Workbook
Name ECONACIONAL: 'Nomina Econacional'!$A$4:$AB$153
Name Excel_BuiltIn__FilterDatabase: 'boleto de ornato'!#REF!
Name Excel_BuiltIn__FilterDatabase: distribucion!$P$6:$P$341
Name Excel_BuiltIn__FilterDatabase: 'INCREMENTO SALARIO MINIMO '!#REF!
Name Excel_BuiltIn__FilterDatabase: 'RECIBO E IGSS ECONACIONAL'!$B$1:$AB$2
Name Excel_BuiltIn__FilterDatabase: 'RECIBO E IGSS PROQUIMA'!$B$2:$AC$4
Name Excel_BuiltIn__FilterDatabase: 'RECIBO E IGSS UNHESA'!$B$2:$AB$4

Sheet boleto de ornato
B1: 1 | C1: 2 | D1: 3 | E1: 4 | F1: 5 | G1: 6 | H1: 6
B2: DISTRIBUCION DE PERSONAL Y COSTO POR EMPRESA
B3: NOMINA MES DE: ENERO 2,022 1a. Quincena)
E5: 5 | F5: 6
D6: DISTRIBUCION DE EMPLEADOS
B7: Nombre | C7: Puesto | D7: Empresa Real | E7: Salario Ordinario | F7: Bono Decreto | G7: Total | H7: MONTO BOLETO
B8: AREA ADMINISTRATIVA
B9: PRESIDENCIA
A10: 1 | B10: Flores Ruano Yandira Beatriz | C10: Asistente de Gerencia General | D10: UNHESA | E10: 3750 | F10: =2000+250 -> 2250 | G10: =+E10+F10 -> 6000 | H10: 50
A11: =+A10+1 -> 2 | B11: Veliz Carias Elder Danilo | C11: Piloto | D11: UNHESA | E11: 2959.24 | F11: 250 | G11: =+E11+F11 -> 3209.24 | H11: 50
A12: =+A11+1 -> 3 | B12: Pirir Toj Luis Alberto | C12: Piloto | D12: PROQUIMA | E12: 3250 | F12: 250 | G12: =+E12+F12 -> 3500 | H12: 50
C13: Total Presidencia | E13: =SUM(E10:E12) -> 9959.24 | F13: =SUM(F10:F12) -> 2750 | G13: =SUM(G10:G12) -> 12709.24 | H13: =SUM(H10:H12) -> 150
B15: ADMINISTRATIVO
A16: =A12+1 -> 4 | B16: Gaitan Hernandez Luis Daniel | C16: Piloto de Presidencia | D16: PROQUIMA | E16: 3262.5 | F16: 2250 | G16: =+E16+F16 -> 5512.5 | H16: 50
A17: =+A16+1 -> 5 | B17: Alvarez Caceros Genesis Arleth | C17: Recepcionista | D17: PROQUIMA | E17: 2959.24 | F17: 725 | G17: =+E17+F17 -> 3684.24 | H17: 50
A18: =+A17+1 -> 6 | B18: Pu Canto Domingo | C18: Conserje | D18: PROQUIMA | E18: 2959.24 | F18: 250 | G18: =+E18+F18 -> 3209.24 | H18: 50
A19: =+A18+1 -> 7 | B19: Chamay Gomez Susana Noemi | C19: conserje | D19: UNHESA | E19: 2959.24 | F19: 250 | G19: =+E19+F19 -> 3209.24 | H19: 50
A20: =+A19+1 -> 8 | B20: Cruz Juarez Santos Ernesto | C20: Mensajero | D20: PROQUIMA | E20: 2959.24 | F20: =250+120 -> 370 | G20: =+E20+F20 -> 3329.24 | H20: 50
A21: =+A20+1 -> 9 | B21: Alpuaque Aragon Sergio Antonio | C21: Mensajero | D21: PROQUIMA | E21: 2959.24 | F21: 370 | G21: =+E21+F21 -> 3329.24 | H21: 50
C22: Total Administrativo | E22: =SUM(E16:E21) -> 18058.7 | F22: =SUM(F16:F21) -> 4215 | G22: =SUM(G16:G21) -> 22273.7 | H22: =SUM(H16:H21) -> 300
B24: CONTABILIDAD Y FINANZAS
A25: =A21+1 -> 10 | B25: Patzan Quib Lucrecia | C25: Contador General | D25: UNHESA | E25: 2959.24 | F25: 250 | G25: =+E25+F25 -> 3209.24 | H25: 50
A26: =A25+1 -> 11 | B26: Sical Cruz Manuel Estuardo | C26: Supervisor Contable | D26: UNHESA | E26: 4200 | F26: 2800 | G26: =+E26+F26 -> 7000 | H26: 75
A27: =A26+1 -> 12 | B27: Mendez Flores Juan Andres | C27: Gerente Financiero | D27: PROQUIMA | E27: 13000 | F27: 7000 | G27: =+E27+F27 -> 20000 | H27: 150
A28: =A27+1 -> 13 | B28: Castañeda Osorio Estela Angelina | C28: Tesorera-Contador | D28: UNHESA | E28: 3250 | F28: 750 | G28: =+E28+F28 -> 4000 | H28: 50
A29: =A28+1 -> 14 | B29: Lopez Vasquez Flor de Maria | C29: Asistente Juridico | D29: PROQUIMA | E29: 3500 | F29: 500 | G29: =+E29+F29 -> 4000 | H29: 50
A30: =A29+1 -> 15 | B30: Gómez Laparra Glenda Esmeralda | C30: Auxiliar Contable | D30: PROQUIMA | E30: 3500 | F30: =1000 -> 1000 | G30: =+E30+F30 -> 4500 | H30: 50
A31: =A30+1 -> 16 | B31: Chavez Garcia Benner Amilcar | C31: Auxiliar Contable | D31: UNHESA | E31: 2959.24 | F31: 250 | G31: =+E31+F31 -> 3209.24 | H31: 50
A32: =A31+1 -> 17 | B32: Mendez Cruz Walter Emilio | C32: Auditor interno | D32: PROQUIMA | E32: 5055 | F32: 3045 | G32: =+E32+F32 -> 8100 | H32: 75
A33: =A32+1 -> 18 | B33: Ramos Caracun Jose Ottoniel | C33: Auxiliar Contable | D33: UNHESA | E33: 3250 | F33: 750 | G33: =+E33+F33 -> 4000 | H33: 50
C34: Total Contabilidad y Finanzas | E34: =SUM(E25:E33) -> 41673.48 | F34: =SUM(F25:F33) -> 16345 | G34: =SUM(G25:G33) -> 58018.48 | H34: =SUM(H25:H33) -> 600
B36: INVESTIGACION Y DESARROLLO
A37: =A33+1 -> 19 | B37: De Floran Rodas Luis Arnau Estanislao | C37: Jefe I & D | D37: PROQUIMA | E37: 5000 | F37: =250+750 -> 1000 | G37: =+E37+F37 -> 6000 | H37: 50
A38: =+A37+1 -> 20 | B38: Orozco Tzic Yenifer Jimena | C38: Asistente de Investigacion y Desarrollo | D38: PROQUIMA | E38: 4000 | F38: 500 | G38: =+E38+F38 -> 4500 | H38: 50
A39: =+A38+1 -> 21 | B39: Castro Aceituno Rodrigo Jose | C39: Auxiliar de Investigacion y Desarrollo | D39: PROQUIMA | E39: 2959.24 | F39: 250 | G39: =+E39+F39 -> 3209.24 | H39: 50
C40: TotaL Investigacion y desarrollo | E40: =SUM(E37:E39) -> 11959.24 | F40: =SUM(F37:F39) -> 1750 | G40: =SUM(G37:G39) -> 13709.24 | H40: =SUM(H37:H39) -> 150
B42: CONTROL DE CALIDAD
A43: 22 | B43: Melgar Najera Alfredo Emilio | C43: Jefe de Gestion de calidad | D43: PROQUIMA | E43: =4250+500 -> 4750 | F43: =250+2000 -> 2250 | G43: =+E43+F43 -> 7000 | H43: 75
A44: =+A43+1 -> 23 | B44: Muñoz Laparra Orly Gabriela | C44: Asistente de Control de Calidad | D44: PROQUIMA | E44: =4250+250 -> 4500 | F44: =250+250 -> 500 | G44: =+E44+F44 -> 5000 | H44: 50
A45: =+A44+1 -> 24 | B45: Lopez Orellana Genesis Alejandra | C45: Asistente de Control de Calidad | D45: UNHESA | E45: 4250 | F45: 750 | G45: =+E45+F45 -> 5000 | H45: 50
...

Sheet INCREMENTO SALARIO MINIMO 
B1: 1 | C1: 2 | D1: 3 | E1: 4 | F1: 5 | G1: 6 | H1: 8 | I1: 9 | J1: 10 | K1: 13 | M1: 1 | N1: 2 | O1: 3 | P1: 4 | Q1: 5 | R1: 6 | S1: 8 | T1: 9 | U1: 10 | V1: 13
B2: DISTRIBUCION DE PERSONAL Y COSTO POR EMPRESA | M2: DISTRIBUCION DE PERSONAL Y COSTO POR EMPRESA
B3: NOMINA MES DE: ENERO 2,022 1a. Quincena) | M3: NOMINA MES DE: ENERO 2,022 1a. Quincena)
E5: 5 | F5: 6 | P5: 5 | Q5: 6
D6: DISTRIBUCION DE EMPLEADOS | O6: DISTRIBUCION DE EMPLEADOS
B7: Nombre | C7: Puesto | D7: Empresa Real | E7: Salario Ordinario | F7: Bono Decreto | G7: Total | H7: % Proquima | I7: % Unhesa | J7: % Unhesa Liq. | K7: Total % Distribución | M7: Nombre | N7: Puesto | O7: Empresa Real | P7: Salario Ordinario | Q7: Bono Decreto | R7: Total | S7: % Proquima | T7: % Unhesa | U7: % Unhesa Liq. | V7: Total % Distribución
B8: AREA ADMINISTRATIVA | M8: AREA ADMINISTRATIVA
B9: PRESIDENCIA | M9: PRESIDENCIA
A10: 2 | B10: Estrada Robles Victor Gerardo 1 | C10: Asesor | D10: PROQUIMA | E10: 2825.1 | F10: 250 | G10: =+E10+F10 -> 3075.1 | H10: 1 | I10: 0 | J10: 0 | K10: =SUM(H10:J10) -> 1 | M10: Estrada Robles Victor Gerardo 1 | N10: Asesor | O10: PROQUIMA | P10: 2959.24 | Q10: 250 | R10: =+P10+Q10 -> 3209.24 | S10: 1 | T10: 0 | U10: 0 | V10: =SUM(S10:U10) -> 1
B11: Estrada Robles Juan Pablo | C11: Asesor | D11: PROQUIMA | E11: 2825.1 | F11: 250 | G11: =+E11+F11 -> 3075.1 | H11: 1 | I11: 0 | J11: 0 | K11: =SUM(H11:J11) -> 1 | M11: Estrada Robles Juan Pablo | N11: Asesor | O11: PROQUIMA | P11: 2959.24 | Q11: 250 | R11: =+P11+Q11 -> 3209.24 | S11: 1 | T11: 0 | U11: 0 | V11: =SUM(S11:U11) -> 1
A12: 5 | B12: Veliz Carias Elder Danilo | C12: Piloto | D12: UNHESA | E12: 2825.1 | F12: 250 | G12: =+E12+F12 -> 3075.1 | H12: 0 | I12: 1 | J12: 0 | K12: =SUM(H12:J12) -> 1 | M12: Veliz Carias Elder Danilo | N12: Piloto | O12: UNHESA | P12: 2959.24 | Q12: 250 | R12: =+P12+Q12 -> 3209.24 | S12: 0 | T12: 1 | U12: 0 | V12: =SUM(S12:U12) -> 1
C13: Total Presidencia | E13: =SUM(E10:E12) -> 8475.3 | F13: =SUM(F10:F12) -> 750 | G13: =SUM(G10:G12) -> 9225.3 | N13: Total Presidencia | P13: =SUM(P10:P12) -> 8877.72 | Q13: =SUM(Q10:Q12) -> 750 | R13: =SUM(R10:R12) -> 9627.72
B17: ADMINISTRATIVO | M17: ADMINISTRATIVO
A18: 8 | B18: Alvarez Caceros Genesis Arleth | C18: Recepcionista | D18: PROQUIMA | E18: 2825.1 | F18: 725 | G18: =+E18+F18 -> 3550.1 | H18: 0.5 | I18: 0.5 | J18: 0 | K18: =SUM(H18:J18) -> 1 | M18: Alvarez Caceros Genesis Arleth | N18: Recepcionista | O18: PROQUIMA | P18: 2959.24 | Q18: 725 | R18: =+P18+Q18 -> 3684.24 | S18: 0.5 | T18: 0.5 | U18: 0 | V18: =SUM(S18:U18) -> 1
A19: 9 | B19: Pu Canto Domingo | C19: Conserje | D19: PROQUIMA | E19: 2825.1 | F19: 250 | G19: =+E19+F19 -> 3075.1 | H19: 0.5 | I19: 0.5 | J19: 0 | K19: =SUM(H19:J19) -> 1 | M19: Pu Canto Domingo | N19: Conserje | O19: PROQUIMA | P19: 2959.24 | Q19: 250 | R19: =+P19+Q19 -> 3209.24 | S19: 0.5 | T19: 0.5 | U19: 0 | V19: =SUM(S19:U19) -> 1
A20: 10 | B20: Chamay Gomez Susana Noemi | C20: conserje | D20: UNHESA | E20: 2825.1 | F20: 250 | G20: =+E20+F20 -> 3075.1 | H20: 0 | I20: 1 | J20: 0 | K20: =SUM(H20:J20) -> 1 | M20: Chamay Gomez Susana Noemi | N20: conserje | O20: UNHESA | P20: 2959.24 | Q20: 250 | R20: =+P20+Q20 -> 3209.24 | S20: 0 | T20: 1 | U20: 0 | V20: =SUM(S20:U20) -> 1
A21: 11 | B21: Cruz Juarez Santos Ernesto | C21: Mensajero | D21: PROQUIMA | E21: 2825.1 | F21: =250+120 -> 370 | G21: =+E21+F21 -> 3195.1 | H21: 1 | I21: 0 | J21: 0 | K21: =SUM(H21:J21) -> 1 | M21: Cruz Juarez Santos Ernesto | N21: Mensajero | O21: PROQUIMA | P21: 2959.24 | Q21: =250+120 -> 370 | R21: =+P21+Q21 -> 3329.24 | S21: 1 | T21: 0 | U21: 0 | V21: =SUM(S21:U21) -> 1
A22: 12 | B22: Alpuaque Aragon Sergio Antonio | C22: Mensajero | D22: PROQUIMA | E22: 2825.1 | F22: 370 | G22: =+E22+F22 -> 3195.1 | H22: 1 | I22: 0 | J22: 0 | K22: =SUM(H22:J22) -> 1 | M22: Alpuaque Aragon Sergio Antonio | N22: Mensajero | O22: PROQUIMA | P22: 2959.24 | Q22: 370 | R22: =+P22+Q22 -> 3329.24 | S22: 1 | T22: 0 | U22: 0 | V22: =SUM(S22:U22) -> 1
C23: Total Administrativo | E23: =SUM(E18:E22) -> 14125.5 | F23: =SUM(F18:F22) -> 1965 | G23: =SUM(G18:G22) -> 16090.5 | N23: Total Administrativo | P23: =SUM(P18:P22) -> 14796.2 | Q23: =SUM(Q18:Q22) -> 1965 | R23: =SUM(R18:R22) -> 16761.2
B25: CONTABILIDAD Y FINANZAS | M25: CONTABILIDAD Y FINANZAS
A26: =A22+1 -> 13 | B26: Patzan Quib Lucrecia | C26: Contador General | D26: UNHESA | E26: 2825.1 | F26: 250 | G26: =+E26+F26 -> 3075.1 | H26: 0.65 | I26: 0.35 | J26: 0 | K26: =SUM(H26:J26) -> 1 | M26: Patzan Quib Lucrecia | N26: Contador General | O26: UNHESA | P26: 2959.24 | Q26: 250 | R26: =+P26+Q26 -> 3209.24 | S26: 0.65 | T26: 0.35 | U26: 0 | V26: =SUM(S26:U26) -> 1
A27: =#REF!+1 -> #REF! | B27: Chavez Garcia Benner Amilcar | C27: Auxiliar Contable | D27: UNHESA | E27: 2825.1 | F27: 250 | G27: =+E27+F27 -> 3075.1 | H27: 0.5 | I27: 0.5 | J27: 0 | K27: =SUM(H27:J27) -> 1 | M27: Chavez Garcia Benner Amilcar | N27: Auxiliar Contable | O27: UNHESA | P27: 2959.24 | Q27: 250 | R27: =+P27+Q27 -> 3209.24 | S27: 0.5 | T27: 0.5 | U27: 0 | V27: =SUM(S27:U27) -> 1
C28: Total Contabilidad y Finanzas | E28: =SUM(E26:E27) -> 5650.2 | F28: =SUM(F26:F27) -> 500 | G28: =SUM(G26:G27) -> 6150.2 | N28: Total Contabilidad y Finanzas | P28: =SUM(P26:P27) -> 5918.48 | Q28: =SUM(Q26:Q27) -> 500 | R28: =SUM(R26:R27) -> 6418.48
B30: INVESTIGACION Y DESARROLLO | M30: INVESTIGACION Y DESARROLLO
A31: =+#REF!+1 -> #REF! | B31: Castro Aceituno Rodrigo Jose | C31: Auxiliar de Investigacion y Desarrollo | D31: PROQUIMA | E31: 2825.1 | F31: 250 | G31: =+E31+F31 -> 3075.1 | H31: 1 | I31: 0 | J31: 0 | K31: =SUM(H31:J31) -> 1 | M31: Castro Aceituno Rodrigo Jose | N31: Auxiliar de Investigacion y Desarrollo | O31: PROQUIMA | P31: 2959.24 | Q31: 250 | R31: =+P31+Q31 -> 3209.24 | S31: 1 | T31: 0 | U31: 0 | V31: =SUM(S31:U31) -> 1
C32: TotaL Investigacion y desarrollo | E32: =SUM(E31:E31) -> 2825.1 | F32: =SUM(F31:F31) -> 250 | G32: =SUM(G31:G31) -> 3075.1 | N32: TotaL Investigacion y desarrollo | P32: =SUM(P31:P31) -> 2959.24 | Q32: =SUM(Q31:Q31) -> 250 | R32: =SUM(R31:R31) -> 3209.24
B34: CONTROL DE CALIDAD | M34: CONTROL DE CALIDAD
A35: =+#REF!+1 -> #REF! | B35: Guzman Hernandez Edgar Geovanni | C35: Auxiliar de control de calidad | D35: PROQUIMA | E35: 2825.1 | F35: 400 | G35: =+E35+F35 -> 3225.1 | H35: 0.6 | I35: 0.4 | J35: 0 | K35: =SUM(H35:J35) -> 1 | M35: Guzman Hernandez Edgar Geovanni | N35: Auxiliar de control de calidad | O35: PROQUIMA | P35: 2959.24 | Q35: 400 | R35: =+P35+Q35 -> 3359.24 | S35: 0.6 | T35: 0.4 | U35: 0 | V35: =SUM(S35:U35) -> 1
A36: =+A35+1 -> #REF! | B36: Martinez Garcia Erick Rolando | C36: Auxiliar de control de calidad | D36: PROQUIMA | E36: 2825.1 | F36: 250 | G36: =+E36+F36 -> 3075.1 | H36: 0.6 | I36: 0.4 | J36: 0 | K36: =SUM(H36:J36) -> 1 | M36: Martinez Garcia Erick Rolando | N36: Auxiliar de control de calidad | O36: PROQUIMA | P36: 2959.24 | Q36: 250 | R36: =+P36+Q36 -> 3209.24 | S36: 0.6 | T36: 0.4 | U36: 0 | V36: =SUM(S36:U36) -> 1
C37: TotaL Control de Calidad | E37: =SUM(E35:E36) -> 5650.2 | F37: =SUM(F35:F36) -> 650 | G37: =SUM(G35:G36) -> 6300.2 | N37: TotaL Control de Calidad | P37: =SUM(P35:P36) -> 5918.48 | Q37: =SUM(Q35:Q36) -> 650 | R37: =SUM(R35:R36) -> 6568.48
B39: INFORMATICA | M39: INFORMATICA
A40: =+#REF!+1 -> #REF! | B40: Lopez Calderon Cesar Anibal | C40: Analista Programador | D40: UNHESA | E40: 2825.1 | F40: 250 | G40: =+E40+F40 -> 3075.1 | H40: 0.5 | I40: 0.5 | J40: 0 | K40: =SUM(H40:J40) -> 1 | M40: Lopez Calderon Cesar Anibal | N40: Analista Programador | O40: UNHESA | P40: 2959.24 | Q40: 250 | R40: =+P40+Q40 -> 3209.24 | S40: 0.5 | T40: 0.5 | U40: 0 | V40: =SUM(S40:U40) -> 1
A41: =+A40+1 -> #REF! | B41: Cabrera Guzman Javier Antonio | C41: Analista Programador | D41: UNHESA | E41: 2825.1 | F41: 250 | G41: =+E41+F41 -> 3075.1 | H41: 0.5 | I41: 0.5 | J41: 0 | K41: =SUM(H41:J41) -> 1 | M41: Cabrera Guzman Javier Antonio | N41: Analista Programador | O41: UNHESA | P41: 2959.24 | Q41: 250 | R41: =+P41+Q41 -> 3209.24 | S41: 0.5 | T41: 0.5 | U41: 0 | V41: =SUM(S41:U41) -> 1
A42: =+A41+1 -> #REF! | B42: Figueros Cardona Gabriel | C42: Analista Programador | D42: UNHESA | E42: 2825.1 | F42: 250 | G42: =+E42+F42 -> 3075.1 | H42: 0.5 | I42: 0.5 | J42: 0 | K42: =SUM(H42:J42) -> 1 | M42: Figueros Cardona Gabriel | N42: Analista Programador | O42: UNHESA | P42: 2959.24 | Q42: 250 | R42: =+P42+Q42 -> 3209.24 | S42: 0.5 | T42: 0.5 | U42: 0 | V42: =SUM(S42:U42) -> 1
A43: =+A42+1 -> #REF! | B43: Guerra Lopez Jonathan Otoniel | C43: Analista Programador | D43: PROQUIMA | E43: 2825.1 | F43: 250 | G43: =+E43+F43 -> 3075.1 | H43: 0.5 | I43: 0.5 | J43: 0 | K43: =SUM(H43:J43) -> 1 | M43: Guerra Lopez Jonathan Otoniel | N43: Analista Programador | O43: PROQUIMA | P43: 2959.24 | Q43: 250 | R43: =+P43+Q43 -> 3209.24 | S43: 0.5 | T43: 0.5 | U43: 0 | V43: =SUM(S43:U43) -> 1
C44: Total Informatica | E44: =+SUM(E40:E43) -> 11300.4 | F44: =+SUM(F40:F43) -> 1000 | G44: =+SUM(G40:G43) -> 12300.4 | N44: Total Informatica | P44: =+SUM(P40:P43) -> 11836.96 | Q44: =+SUM(Q40:Q43) -> 1000 | R44: =+SUM(R40:R43) -> 12836.96
B45: AREA DE OPERACIONES | M45: AREA DE OPERACIONES
B46: PRODUCCION | M46: PRODUCCION
B47: DIRECCION | M47: DIRECCION
A48: =+#REF!+1 -> #REF! | B48: Hernandez Contreras Kewin Josue | C48: Supervisor | D48: PROQUIMA | E48: 2825.1 | F48: 250 | G48: =+E48+F48 -> 3075.1 | H48: 1 | I48: 0 | J48: 0 | K48: =SUM(H48:J48) -> 1 | M48: Hernandez Contreras Kewin Josue | N48: Supervisor | O48: PROQUIMA | P48: 2959.24 | Q48: 250 | R48: =+P48+Q48 -> 3209.24 | S48: 1 | T48: 0 | U48: 0 | V48: =SUM(S48:U48) -> 1
...

Sheet Hoja2
A2: PARQUEOS | E2: Nombre | F2: Puesto | G2: Empresa Real | H2: Renovación Examenes | I2: Tarjetas de Salud
A3: YANDIRA | B3: 120 | E3: Lopez Orellana Genesis Alejandra | F3: Asistente de Control de Calidad | G3: UNHESA | I3: 175
A4: RONY | B4: 240 | E4: Lopez Rivera Lourdes Janeth | F4: Asistente de Control de Calidad | G4: UNHESA | I4: 87.5
A5: GABRIELA | B5: 240 | E5: Garrido Aguilar Maria Elena | F5: Empacadora de Sobres | G5: UNHESA | H5: 150
B6: =SUM(B3:B5) -> 600 | E6: Boche Mendez Olga Veronica | F6: Empacadora de Sobres | G6: UNHESA | H6: 150
E7: Sontay Cifuentes Leydi Rosivel | F7: Linea de Botes | G7: UNHESA | H7: 150
E8: Samora Sacul Yocelin Paola | F8: Linea de Botes | G8: UNHESA | I8: 175
A9: SEGUROS | E9: Cisneros Lopez Marvin Daniel | F9: Operario Sobres | G9: UNHESA | H9: 150
A10: RUTH | B10: 60 | E10: Guerra Tobar Melvin Esleiter | F10: Operario Sobres | G10: UNHESA | I10: 175
A11: SERGIO HUERTAS | B11: 125 | E11: Vasquez Bamaca Walter Leonidas | F11: Operario Sobres | G11: UNHESA | I11: 175
A12: RONY | B12: 120 | E12: Gomez Martinez Sandor Felipe | F12: Operador | G12: UNHESA | I12: 175
A13: MARVIN CISNEROS | B13: 55 | E13: Ramirez Vasquez Audelio | F13: Operario | G13: UNHESA | I13: 175
B14: =+B10+B11+B12+B13 -> 360 | E14: Garcia Sarceño Mayvin Armando | F14: Operario | G14: UNHESA | I14: 175
E15: Salvatierra de Leon Jakeline Marisela | F15: Empacadora | G15: UNHESA | I15: 175
E16: Hernandez Aquino Wendy Lizbeth | F16: Empacadora | G16: UNHESA | I16: 175
A17: ERROR OTONIEL | B17: 39.29 | E17: Morales Hernandez Joselyn Arceli | F17: Empacadora | G17: UNHESA | I17: 175
E18: Ruche Bor José Antonio | F18: Auxiliar de Carga | G18: UNHESA | I18: 175
E19: Aragón Coronado Guillermo Giovanni | F19: Auxiliar de Limpieza | G19: UNHESA | H19: 150
E20: Rodas Morales Rony Alfonso | F20: Coordinador bodegas | G20: UNHESA | H20: 150
A21: DEUDA RONY | B21: 500 | E21: Chacón Morales Katheryne Mariannela | F21: Encargada de Bodega PT | G21: UNHESA | H21: 150
E22: Solis Dominguez Angel Gabriel | F22: Facturador | G22: UNHESA | I22: 175
A23: DESCUENTOS JURIDICOS | E23: Paz Pacheco Otoniel Adonias | F23: Auxiliar de Bodega | G23: UNHESA | H23: 150
A24: JOSE RUCHE | B24: 1076.28 | E24: Morales Hernandez Ausencio | F24: Auxiliar de Mantenimiento | G24: UNHESA | H24: 150
A25: WENDY CHAVEZ | B25: 1076.29 | E25: Si Mes Pablo | F25: Operario Liquidos | G25: UNHESA | H25: 150
B26: =SUM(B24:B25) -> 2152.57 | E26: Tot Paau David Antonio | F26: Operario Liquidos | G26: UNHESA | H26: 150
E27: Xol Botzoc Hermelindo | F27: Operario Liquidos | G27: UNHESA | H27: 150
E28: Chávez Velásquez Wendy Lorena | F28: Empacadora Liquidos | G28: UNHESA | I28: 175
A29: TARJETAS DE SALUD | B29: =+J33 -> 4812.5 | E29: Gregorio Rodríguez Sulma Maribel | F29: Empacadora Liquidos | G29: UNHESA | I29: 175
E30: Velásquez López Claudia Carolina | F30: Empacadora Liquidos | G30: UNHESA | I30: 175
E31: Ixcoy de Quevedo Blanca Francisca | F31: Empacadora Liquidos | G31: UNHESA | H31: 150
A32: PRODUCTO | B32: 82.5 | E32: Toz Putul Martin | F32: Operario Liquidos | G32: UNHESA | H32: 150
H33: =SUM(H3:H32) -> 2100 | I33: =SUM(I3:I32) -> 2712.5 | J33: =+H33+I33 -> 4812.5
A34: TOTAL INTEGRACION COLUMNA | B34: =+B6+B14+B17+B21+B26+B29+J39+B32 -> 8546.86
B37: 8546.86 | C37: =+B37-B34 -> 0

Sheet distribucion
C1: 1 | D1: 2 | E1: 3 | F1: 4 | G1: 5 | H1: 6 | I1: 7 | J1: 8 | K1: 9 | L1: 10 | M1: 11 | N1: 12 | O1: 13 | P1: 14 | Q1: 15 | R1: 16 | S1: 17 | T1: 18 | U1: 19 | V1: 20 | W1: 21 | X1: 22 | Y1: 23 | Z1: 24 | AA1: 25 | AB1: 26 | AC1: 27 | AD1: 28 | AE1: 29 | AF1: 30 | AG1: 31 | AH1: 32 | AI1: 33 | AJ1: 34 | AK1: 35 | AL1: 36 | AM1: 37 | AN1: 38 | AO1: 39 | AP1: 40 | AQ1: 41 | AR1: 42 | AS1: 43 | AT1: 44 | AU1: 45 | AV1: 46 | AW1: 47 | AX1: 48 | AY1: 49 | AZ1: 50 | BA1: 51 | BB1: 52 | BC1: 53 | BD1: 54 | BE1: 55 | BF1: 56 | BG1: 57 | BH1: 58 | BI1: 59 | BJ1: 60 | BK1: 61 | BL1: 62 | BM1: 63 | BN1: 64 | BO1: 65 | BP1: 66 | BQ1: 67 | BR1: 68 | BS1: 69 | BT1: 70 | BU1: 71 | BV1: 72 | BW1: 73 | BX1: 74 | BY1: 75 | BZ1: 76 | CA1: 77 | CB1: 78 | CC1: 79 | CD1: 80 | CE1: 81 | CF1: 82 | CG1: 83 | CH1: 84 | CI1: 85 | CJ1: 86 | CK1: 87 | CL1: 88 | CM1: 89 | CN1: 90 | CO1: 91 | CP1: 92 | CQ1: 93 | CR1: 94 | CS1: 95 | CT1: 96 | CU1: 97 | CV1: 98 | CW1: 99 | CX1: 100 | CY1: 101 | CZ1: 102 | DA1: 103 | DB1: 104 | DC1: 105 | DD1: 106 | DE1: 107 | DF1: 108 | DG1: 109 | DH1: 110 | DI1: 111 | DJ1: 112 | DK1: 113 | DL1: 114 | DM1: 115 | DN1: 116 | DO1: 117 | DP1: 118 | DQ1: 119 | DR1: 120 | DS1: 121 | DT1: 122 | DU1: 123 | DV1: 124 | DW1: 125 | DX1: 126 | DY1: 127 | DZ1: 128 | EA1: 129 | EB1: 130 | EC1: 131 | ED1: 132 | EE1: 133 | EF1: 134 | EG1: 135 | EH1: 136 | EI1: 137 | EJ1: 138 | EK1: 139 | EL1: 140 | EM1: 141 | EN1: 142 | EO1: 143 | EP1: 144 | EQ1: 145 | ER1: 146 | ES1: 147 | ET1: 148 | EU1: 149 | EV1: 150 | EW1: 151 | EX1: 152 | EY1: 153 | EZ1: 154 | FA1: 155 | FB1: 156 | FC1: 157 | FD1: 158 | FE1: 159 | FF1: 160
C2: DISTRIBUCION DE PERSONAL Y COSTO POR EMPRESA
C3: NOMINA MES DE: MAYO 2026 1ERA QUINCENA | N3: .
AW4: NOMINAS SEGÚN DISTRIBUCION REAL | CR4: NOMINAS SEGÚN DISTRIBUCION CONTABILIDAD | FR4: QUINCENA: 2 MES: 1
F5: 5 | G5: 6 | Q5: HORAS EXTRAS PROQUIMA | U5: HORAS EXTRAS UNHESA | Y5: HORAS EXTRAS UNHESA LIQUIDOS | AC5: HORAS EXTRAS ECONACIONAL | AG5: HORAS EXTRAS PROQUIMA MAQUILA | AK5: Otros Ingresos | AP5: Comisiones | AW5: PROQUIMA | BF5: UNHESA | BO5: UNHESA LIQUIDOS | BX5: ECONACIONAL | CG5: ECOMEZCLAS | CR5: PROQUIMA | DA5: UNHESA | DJ5: UNHESA LIQUIDOS | DS5: ECONACIONAL | EB5: ECOMEZCLAS | FG5: DISTRIBUCION REAL | FR5: 1
E6: DISTRIBUCION DE EMPLEADOS | Q6: H.E. Simples | R6: H.E. Simples | S6: H.E. Dobles | T6: H.E. Dobles | U6: H.E. Simples | V6: H.E. Simples | W6: H.E. Dobles | X6: H.E. Dobles | Y6: H.E. Simples | Z6: H.E. Simples | AA6: H.E. Dobles | AB6: H.E. Dobles | AC6: H.E. Simples | AD6: H.E. Simples | AE6: H.E. Dobles | AF6: H.E. Dobles | AG6: H.E. Simples | AH6: H.E. Simples | AI6: H.E. Dobles | AJ6: H.E. Dobles | AK6: Proquima | AL6: Unhesa | AM6: Calidul | AN6: Econacional | AO6: Cleartec | AP6: Proquima | AQ6: Unhesa | AR6: Calidul | AS6: Econacional | AT6: Cleartec | AU6: Otrros ingresos | AV6: 0 | AW6: Salario | AX6: Bono | AY6: cantidad | AZ6: Hrs. Extra | BA6: cantidad | BB6: Hrs. Extra | BC6: Comis / | BD6: Cuota | BE6: Total | BF6: Salario | BG6: Bono | BH6: cantidad | BI6: Hrs. Extra | BJ6: cantidad | BK6: Hrs. Extra | BL6: Comis / | BM6: Cuota | BN6: Total | BO6: Salario | BP6: Bono | BQ6: cantidad | BR6: Hrs. Extra | BS6: cantidad | BT6: Hrs. Extra | BU6: Comis / | BV6: Cuota | BW6: Total | BX6: Salario | BY6: Bono | BZ6: cantidad | CA6: Hrs. Extra | CB6: cantidad | CC6: Hrs. Extra | CD6: Comis / | CE6: Cuota | CF6: Total | CG6: Salario | CH6: Bono | CI6: cantidad | CJ6: Hrs. Extra | CK6: cantidad | CL6: Hrs. Extra | CM6: Comis / | CN6: Cuota | CO6: Total | CQ6: Nueva | CR6: Salario | CS6: Bono | CT6: cantidad | CU6: Hrs. Extra | CV6: cantidad | CW6: Hrs. Extra | CX6: Comis / | CY6: Cuota | CZ6: Total | DA6: Salario | DB6: Bono | DC6: cantidad | DD6: Hrs. Extra | DE6: cantidad | DF6: Hrs. Extra | DG6: Comis / | DH6: Cuota | DI6: Total | DJ6: Salario | DK6: Bono | DL6: cantidad | DM6: Hrs. Extra | DN6: cantidad | DO6: Hrs. Extra | DP6: Comis / | DQ6: Cuota | DR6: Total | DS6: Salario | DT6: Bono | DU6: cantidad | DV6: Hrs. Extra | DW6: cantidad | DX6: Hrs. Extra | DY6: Comis / | DZ6: Cuota | EA6: Total | EB6: Salario | EC6: Bono | ED6: cantidad | EE6: Hrs. Extra | EF6: cantidad | EG6: Hrs. Extra | EH6: Comis / | EI6: Cuota | EJ6: Total | EL6: EGRESOS MENSUALES | EW6: EGRESOS | FG6: % | FH6: % | FI6: % | FJ6: % | FK6: % | FL6: %
A7: Código División | C7: Nombre | D7: Puesto | E7: Empresa Real | F7: Salario Ordinario | G7: Bono Decreto | H7: Total | I7: Días Laborados | J7: % Proquima | K7: % Unhesa | L7: % Unhesa Liq. | M7: % Econacional | N7: % Ecomezclas | O7: Total % Distribución | P7: Observaciones | Q7: Cantidad | R7: Valor | S7: Cantidad | T7: Valor | U7: Cantidad | V7: Valor | W7: Cantidad | X7: Valor | Y7: Cantidad | Z7: Valor | AA7: Cantidad | AB7: Valor | AC7: Cantidad | AD7: Valor | AE7: Cantidad | AF7: Valor | AG7: Cantidad | AH7: Valor | AI7: Cantidad | AJ7: Valor | AW7: Ordinario | AX7: Decreto | AY7: simples | AZ7: simples | BA7: dobles | BB7: dobles | BC7: Otros | BD7: Patronal | BF7: Ordinario | BG7: Decreto | BH7: simples | BI7: simples | BJ7: dobles | BK7: dobles | BL7: Otros | BM7: Patronal | BO7: Ordinario | BP7: Decreto | BQ7: simples | BR7: simples | BS7: dobles | BT7: dobles | BU7: Otros | BV7: Patronal | BX7: Ordinario | BY7: Decreto | BZ7: simples | CA7: simples | CB7: dobles | CC7: dobles | CD7: Otros | CE7: Patronal | CG7: Ordinario | CH7: Decreto | CI7: simples | CJ7: simples | CK7: dobles | CL7: dobles | CM7: Otros | CN7: Patronal | CQ7: Empresa | CR7: Ordinario | CS7: Decreto | CT7: simples | CU7: simples | CV7: dobles | CW7: dobles | CX7: Otros | CY7: Patronal | DA7: Ordinario | DB7: Decreto | DC7: simples | DD7: simples | DE7: dobles | DF7: dobles | DG7: Otros | DH7: Patronal | DJ7: Ordinario | DK7: Decreto | DL7: simples | DM7: simples | DN7: dobles | DO7: dobles | DP7: Otros | DQ7: Patronal | DS7: Ordinario | DT7: Decreto | DU7: simples | DV7: simples | DW7: dobles | DX7: dobles | DY7: Otros | DZ7: Patronal | EB7: Ordinario | EC7: Decreto | ED7: simples | EE7: simples | EF7: dobles | EG7: dobles | EH7: Otros | EI7: Patronal | EL7: ISR | EM7: BANCOS | EN7: CELULAR | EO7: CAFETERIA | EP7: DESCUENTO producto | EQ7: SEGURO/ tarjeta de salud/boleto de ornato | ER7: Otros Descuentos | ES7: CALZADO | ET7: UNIFORME | EU7: TOTAL EGRESOS Bol Ornato, Seguro, Otros | EW7: ISR | EX7: BANCOS | EY7: CELULAR | EZ7: CAFETERIA | FA7: DESCUENTO PRODUCTO | FB7: SEGURO/BOLETO DE ORNATO | FC7: Otros Descuentos | FD7: CALZADO | FE7: UNIFORME | FF7: OTROS EGRESOS | FG7: % Proquima | FH7: % Unhesa | FI7: % Unhesa Liq. | FJ7: % Econacional | FK7: % Ecomezclas | FL7: Total % Distribución
C8: AREA ADMINISTRATIVA | FJ8: cional
C9: PRESIDENCIA
A10: 101020 | B10: 1 | C10: Estrada Robles Victor Gerardo | D10: Presidente | E10: UNHESA | F10: 5000 | G10: =15000+1505.89 -> 16505.89 | H10: =+F10+G10 -> 21505.89 | I10: 15 | J10: 0 | K10: 1 | L10: 0 | M10: 0 | N10: 0 | O10: =SUM(J10:N10) -> 1 | R10: =($F10/30/8*1.5)*Q10 -> 0 | T10: 0 | V10: =($F10/30/8*1.5)*U10 -> 0 | X10: =($F10/30/8*2)*W10 -> 0 | Z10: =(($F10/30/8)*1.5)*Y10 -> 0 | AB10: =(($F10/30/8)*2)*AA10 -> 0 | AD10: =(($F10/30/8)*1.5)*AC10 -> 0 | AF10: =(($F10/30/8)*2)*AE10 -> 0 | AH10: =(($F10/30/8)*1.5)*AG10 -> 0 | AJ10: =(($F10/30/8)*2)*AI10 -> 0 | AW10: =(($F10/30)*$I10)*$J10 -> 0 | AX10: =((G10/30)*I10)*$J10 -> 0 | AY10: =Q10 -> 0 | AZ10: =R10 -> 0 | BA10: =S10 -> 0 | BB10: =T10 -> 0 | BC10: =AK10+AP10 -> 0 | BD10: =(AW10+AZ10+BB10+BC10)*0.1267 -> 0 | BE10: =SUM(AW10:BD10)-AY10-BA10 -> 0 | BF10: =(($F10/30)*$I10)*$K10 -> 2500 | BG10: =(($G10/30)*$I10)*$K10 -> 8252.945 | BH10: =U10 -> 0 | BI10: =V10 -> 0 | BJ10: =W10 -> 0 | BK10: =X10 -> 0 | BL10: =AL10+AQ10 -> 0 | BM10: =(+BF10+BI10+BK10+BL10)*0.1267 -> 316.75 | BN10: =SUM(BF10:BM10)-BH10-BJ10 -> 11069.695 | BO10: =(($F10/30)*$I10)*$L10 -> 0 | BP10: =(($G10/30)*$I10)*$L10 -> 0 | BQ10: =Y10 -> 0 | BR10: =Z10 -> 0 | BS10: =AA10 -> 0 | BT10: =AB10 -> 0 | BU10: =AM10+AR10 -> 0 | BV10: =(BO10+BR10+BT10+BU10)*0.1267 -> 0 | BW10: =SUM(BO10:BV10)-BQ10-BS10 -> 0 | BX10: =(($F10/30)*$I10)*$M10 -> 0 | BY10: =(($G10/30)*$I10)*$M10 -> 0 | BZ10: =AC10 -> 0 | CA10: =AD10 -> 0 | CB10: =AE10 -> 0 | CC10: =AF10 -> 0 | CD10: =AN10+AS10 -> 0 | CE10: =(BX10+CA10+CC10)*0.1267 -> 0 | CF10: =SUM(BX10:CE10)-BZ10-CB10 -> 0 | CG10: =(($F10/30)*$I10)*N10 -> 0 | CH10: =(($G10/30)*$I10)*$N10 -> 0 | CI10: =+AG10 -> 0 | CJ10: =AH10 -> 0 | CK10: =AI10 -> 0 | CL10: =AJ10 -> 0 | CM10: =AO10+AT10 -> 0 | CN10: =(CG10+CJ10+CL10)*0.1267 -> 0 | CO10: =SUM(CG10:CN10)-CI10-CK10 -> 0 | CQ10: UNHESA | CR10: =IF($CQ10="PROQUIMA",$AW10+$BF10+$BO10+$BX10+$CG10,0) -> 0 | CS10: =IF($CQ10="PROQUIMA",$AX10+$BG10+$BP10+$BY10+$CH10,0) -> 0 | CT10: =IF($CQ10="PROQUIMA",$AY10+$BH10+$BQ10+$BZ10+$CI10,0) -> 0 | CU10: =IF($CQ10="PROQUIMA",$AZ10+$BI10+$BR10+$CA10+$CJ10,0) -> 0 | CV10: =IF($CQ10="PROQUIMA",$BA10+$BJ10+$BS10+$CB10+$CK10,0) -> 0 | CW10: =IF($CQ10="PROQUIMA",$BB10+$BK10+$BT10+$CC10+$CL10,0) -> 0 | CX10: =IF($CQ10="PROQUIMA",$BC10+$BL10+$BU10+$CD10+$CM10,0) -> 0 | CY10: =IF($CQ10="PROQUIMA",$BD10+$BM10+$BV10+$CE10+CN10,0) -> 0 | CZ10: =SUM(CR10:CY10)-CT10-CV10 -> 0 | DA10: =IF($CQ10="UNHESA",$AW10+$BF10+$BO10+$BX10+$CG10,0) -> 2500 | DB10: =IF($CQ10="UNHESA",$AX10+$BG10+$BP10+$BY10+$CH10,0) -> 8252.945 | DC10: =IF($CQ10="UNHESA",$AY10+$BH10+$BQ10+$BZ10+$CI10,0) -> 0 | DD10: =IF($CQ10="UNHESA",$AZ10+$BI10+$BR10+$CA10+$CJ10,0) -> 0 | DE10: =IF($CQ10="UNHESA",$BA10+$BJ10+$BS10+$CB10+$CK10,0) -> 0 | DF10: =IF($CQ10="UNHESA",$BB10+$BK10+$BT10+$CC10+$CL10,0) -> 0 | DG10: =IF($CQ10="UNHESA",$BC10+$BL10+$BU10+$CD10+$CM10,0) -> 0 | DH10: =IF($CQ10="UNHESA",$BD10+$BM10+$BV10+$CE10+$CN10,0) -> 316.75 | DI10: =SUM(DA10:DH10)-DC10-DE10 -> 11069.695 | EL10: 1776.01 | EM10: 3232.32 | EU10: =+EP10+EQ10+ER10 -> 0 | EW10: =IF($I10<=15,EL10/2,EL10) -> 888.005 | EX10: =IF($I10<=15,EM10/2,EM10) -> 1616.16 | EY10: =IF($I10<=15,EN10/2,EN10) -> 0 | EZ10: =IF($I10<=15,EO10/2,EO10) -> 0 | FA10: =IF($I10<=15,EP10/2,EP10) -> 0 | FB10: =IF($I10<=15,EQ10/2,EQ10) -> 0 | FC10: =IF($I10<=15,ER10/2,ER10) -> 0 | FD10: =IF($I10<=15,ES10/2,ES10) -> 0 | ... FF10: =IF($I10<=15,EU10/2,EU10) -> 0 | FG10: 0 | FH10: 1 | FI10: 0 | FJ10: 0 | FK10: 0 | FL10: 1 | FN10: =(((F10/30/8)*1.5)*(Q10+U10+Y10))-(AZ10+BI10+BR10) -> 0 | FO10: =(((F10/30/8)*2)*(S10+W10+AA10))-(BB10+BK10+BT10) -> 0 | FP10: =(SUM(AW10:CF10))-(SUM(CR10:DR10)) -> 0 | FQ10: =(F10/30*I10)-(CR10+DA10+DJ10) -> 0 | FR10: =(SUM(EL10:EU10))-((SUM(EW10:FF10))*$FR$5) -> 2504.165
A11: 101020 | D11: Total presidencia | F11: =+F10 -> 5000 | G11: =+G10 -> 16505.89 | H11: =+H10 -> 21505.89 | Q11: =+Q10 -> 0 | R11: =+R10 -> 0 | S11: =+S10 -> 0 | T11: =+T10 -> 0 | U11: =+U10 -> 0 | V11: =+V10 -> 0 | W11: =+W10 -> 0 | X11: =+X10 -> 0 | ... FF11: =+FF10 -> 0
A13: 101010 | B13: 2 | C13: Estrada Robles Victor Gerardo1 | D13: Gerente General | E13: PROQUIMA | F13: 5000 | G13: 10000 | H13: =+F13+G13 -> 15000 | I13: 0 | J13: 1 | K13: 0 | L13: 0 | M13: 0 | N13: 0 | O13: =SUM(J13:N13) -> 1 | R13: =($F13/30/8*1.5)*Q13 -> 0 | T13: =($F13/30/8*2)*S13 -> 0 | V13: =($F13/30/8*1.5)*U13 -> 0 | X13: =($F13/30/8*2)*W13 -> 0 | Z13: =(($F13/30/8)*1.5)*Y13 -> 0 | AB13: =(($F13/30/8)*2)*AA13 -> 0 | AD13: =(($F13/30/8)*1.5)*AC13 -> 0 | AF13: =(($F13/30/8)*2)*AE13 -> 0 | AH13: =(($F13/30/8)*1.5)*AG13 -> 0 | AJ13: =(($F13/30/8)*2)*AI13 -> 0 | AW13: =(($F13/30)*$I13)*$J13 -> 0 | AX13: =(($G13/30)*$I13)*$J13 -> 0 | AY13: =Q13 -> 0 | AZ13: =R13 -> 0 | BA13: =S13 -> 0 | BB13: =T13 -> 0 | BC13: =AK13+AP13 -> 0 | BD13: =(AW13+AZ13+BB13+BC13)*0.1267 -> 0 | BE13: =SUM(AW13:BD13)-AY13-BA13 -> 0 | BF13: =(($F13/30)*$I13)*$K13 -> 0 | BG13: =(($G13/30)*$I13)*$K13 -> 0 | BH13: =U13 -> 0 | BI13: =V13 -> 0 | BJ13: =W13 -> 0 | BK13: =X13 -> 0 | BL13: =AL13+AQ13 -> 0 | BM13: =(+BF13+BI13+BK13+BL13)*0.1267 -> 0 | BN13: =SUM(BF13:BM13)-BH13-BJ13 -> 0 | BO13: =(($F13/30)*$I13)*$L13 -> 0 | BP13: =(($G13/30)*$I13)*$L13 -> 0 | BQ13: =Y13 -> 0 | BR13: =Z13 -> 0 | BS13: =AA13 -> 0 | BT13: =AB13 -> 0 | BU13: =AM13+AR13 -> 0 | BV13: =(BO13+BR13+BT13+BU13)*0.1267 -> 0 | BW13: =SUM(BO13:BV13)-BQ13-BS13 -> 0 | BX13: =(($F13/30)*$I13)*$M13 -> 0 | BY13: =(($G13/30)*$I13)*$M13 -> 0 | BZ13: =AC13 -> 0 | CA13: =AD13 -> 0 | CB13: =AE13 -> 0 | CC13: =AF13 -> 0 | CD13: =AN13+AS13 -> 0 | CE13: =(BX13+CA13+CC13)*0.1267 -> 0 | CF13: =SUM(BX13:CE13)-BZ13-CB13 -> 0 | CG13: =(($F13/30)*$I13)*N13 -> 0 | CH13: =(($G13/30)*$I13)*$N13 -> 0 | CI13: =+AG13 -> 0 | CJ13: =AH13 -> 0 | CK13: =AI13 -> 0 | CL13: =AJ13 -> 0 | CM13: =AO13+AT13 -> 0 | CN13: =(CG13+CJ13+CL13)*0.1267 -> 0 | CO13: =SUM(CG13:CN13)-CI13-CK13 -> 0 | CQ13: PROQUIMA | CR13: =IF($CQ13="PROQUIMA",$AW13+$BF13+$BO13+$BX13+$CG13,0) -> 0 | CS13: =IF($CQ13="PROQUIMA",$AX13+$BG13+$BP13+$BY13+$CH13,0) -> 0 | CT13: =IF($CQ13="PROQUIMA",$AY13+$BH13+$BQ13+$BZ13+$CI13,0) -> 0 | CU13: =IF($CQ13="PROQUIMA",$AZ13+$BI13+$BR13+$CA13+$CJ13,0) -> 0 | CV13: =IF($CQ13="PROQUIMA",$BA13+$BJ13+$BS13+$CB13+$CK13,0) -> 0 | CW13: =IF($CQ13="PROQUIMA",$BB13+$BK13+$BT13+$CC13+$CL13,0) -> 0 | CX13: =IF($CQ13="PROQUIMA",$BC13+$BL13+$BU13+$CD13+$CM13,0) -> 0 | CY13: =IF($CQ13="PROQUIMA",$BD13+$BM13+$BV13+$CE13+CN13,0) -> 0 | CZ13: =SUM(CR13:CY13)-CT13-CV13 -> 0 | DA13: =IF($CQ13="UNHESA",$AW13+$BF13+$BO13+$BX13+$CG13,0) -> 0 | DB13: =IF($CQ13="UNHESA",$AX13+$BG13+$BP13+$BY13+$CH13,0) -> 0 | DC13: =IF($CQ13="UNHESA",$AY13+$BH13+$BQ13+$BZ13+$CI13,0) -> 0 | DD13: =IF($CQ13="UNHESA",$AZ13+$BI13+$BR13+$CA13+$CJ13,0) -> 0 | DE13: =IF($CQ13="UNHESA",$BA13+$BJ13+$BS13+$CB13+$CK13,0) -> 0 | DF13: =IF($CQ13="UNHESA",$BB13+$BK13+$BT13+$CC13+$CL13,0) -> 0 | DG13: =IF($CQ13="UNHESA",$BC13+$BL13+$BU13+$CD13+$CM13,0) -> 0 | DH13: =IF($CQ13="UNHESA",$BD13+$BM13+$BV13+$CE13+$CN13,0) -> 0 | DI13: =SUM(DA13:DH13)-DC13-DE13 -> 0 | EU13: =+EP13+EQ13+ER13 -> 0 | EW13: =IF($I13<=15,EL13/2,EL13) -> 0 | EX13: =IF($I13<=15,EM13/2,EM13) -> 0 | EY13: =IF($I13<=15,EN13/2,EN13) -> 0 | EZ13: =IF($I13<=15,EO13/2,EO13) -> 0 | FA13: =IF($I13<=15,EP13/2,EP13) -> 0 | FB13: =IF($I13<=15,EQ13/2,EQ13) -> 0 | FC13: =IF($I13<=15,ER13/2,ER13) -> 0 | FD13: =IF($I13<=15,ES13/2,ES13) -> 0 | ... FF13: =IF($I13<=15,EU13/2,EU13) -> 0 | FN13: =(((F13/30/8)*1.5)*(Q13+U13+Y13))-(AZ13+BI13+BR13) -> 0 | FO13: =(((F13/30/8)*2)*(S13+W13+AA13))-(BB13+BK13+BT13) -> 0 | FP13: =(SUM(AW13:CF13))-(SUM(CR13:DR13)) -> 0 | FQ13: =(F13/30*I13)-(CR13+DA13+DJ13) -> 0 | FR13: =(SUM(EL13:EU13))-((SUM(EW13:FF13))*$FR$5) -> 0
A14: 101010 | D14: total Gerencia General | F14: =+F13 -> 5000 | G14: =+G13 -> 10000 | H14: =+H13 -> 15000 | Q14: =+Q13 -> 0 | R14: =+R13 -> 0 | S14: =+S13 -> 0 | T14: =+T13 -> 0 | U14: =+U13 -> 0 | V14: =+V13 -> 0 | W14: =+W13 -> 0 | X14: =+X13 -> 0 | ... FF14: =+FF13 -> 0
A15: 101030 | C15: Asesoria
A16: 101030 | B16: 3 | C16: Estrada Robles Juan Pablo | D16: Asesor | E16: PROQUIMA | F16: 5000 | G16: 10000 | H16: =+F16+G16 -> 15000 | I16: 15 | J16: 1 | K16: 0 | L16: 0 | M16: 0 | N16: 0 | O16: =SUM(J16:N16) -> 1 | R16: =($F16/30/8*1.5)*Q16 -> 0 | T16: =($F16/30/8*2)*S16 -> 0 | V16: =($F16/30/8*1.5)*U16 -> 0 | X16: =($F16/30/8*2)*W16 -> 0 | Z16: =(($F16/30/8)*1.5)*Y16 -> 0 | AB16: =(($F16/30/8)*2)*AA16 -> 0 | AD16: =(($F16/30/8)*1.5)*AC16 -> 0 | AF16: =(($F16/30/8)*2)*AE16 -> 0 | AH16: =(($F16/30/8)*1.5)*AG16 -> 0 | AJ16: =(($F16/30/8)*2)*AI16 -> 0 | AW16: =(($F16/30)*$I16)*$J16 -> 2500 | AX16: =(($G16/30)*$I16)*$J16 -> 5000 | AY16: =Q16 -> 0 | AZ16: =R16 -> 0 | BA16: =S16 -> 0 | BB16: =T16 -> 0 | BC16: =AK16+AP16 -> 0 | BD16: =(AW16+AZ16+BB16+BC16)*0.1267 -> 316.75 | BE16: =SUM(AW16:BD16)-AY16-BA16 -> 7816.75 | BF16: =(($F16/30)*$I16)*$K16 -> 0 | BG16: =(($G16/30)*$I16)*$K16 -> 0 | BH16: =U16 -> 0 | BI16: =V16 -> 0 | BJ16: =W16 -> 0 | BK16: =X16 -> 0 | BL16: =AL16+AQ16 -> 0 | BM16: =(+BF16+BI16+BK16+BL16)*0.1267 -> 0 | BN16: =SUM(BF16:BM16)-BH16-BJ16 -> 0 | BO16: =(($F16/30)*$I16)*$L16 -> 0 | BP16: =(($G16/30)*$I16)*$L16 -> 0 | BQ16: =Y16 -> 0 | BR16: =Z16 -> 0 | BS16: =AA16 -> 0 | BT16: =AB16 -> 0 | BU16: =AM16+AR16 -> 0 | BV16: =(BO16+BR16+BT16+BU16)*0.1267 -> 0 | BW16: =SUM(BO16:BV16)-BQ16-BS16 -> 0 | BX16: =(($F16/30)*$I16)*$M16 -> 0 | BY16: =(($G16/30)*$I16)*$M16 -> 0 | BZ16: =AC16 -> 0 | CA16: =AD16 -> 0 | CB16: =AE16 -> 0 | CC16: =AF16 -> 0 | CD16: =AN16+AS16 -> 0 | CE16: =(BX16+CA16+CC16)*0.1267 -> 0 | CF16: =SUM(BX16:CE16)-BZ16-CB16 -> 0 | CG16: =(($F16/30)*$I16)*N16 -> 0 | CH16: =(($G16/30)*$I16)*$N16 -> 0 | CI16: =+AG16 -> 0 | CJ16: =AH16 -> 0 | CK16: =AI16 -> 0 | CL16: =AJ16 -> 0 | CM16: =AO16+AT16 -> 0 | CN16: =(CG16+CJ16+CL16)*0.1267 -> 0 | CO16: =SUM(CG16:CN16)-CI16-CK16 -> 0 | CQ16: PROQUIMA | CR16: =IF($CQ16="PROQUIMA",$AW16+$BF16+$BO16+$BX16+$CG16,0) -> 2500 | CS16: =IF($CQ16="PROQUIMA",$AX16+$BG16+$BP16+$BY16+$CH16,0) -> 5000 | CT16: =IF($CQ16="PROQUIMA",$AY16+$BH16+$BQ16+$BZ16+$CI16,0) -> 0 | CU16: =IF($CQ16="PROQUIMA",$AZ16+$BI16+$BR16+$CA16+$CJ16,0) -> 0 | CV16: =IF($CQ16="PROQUIMA",$BA16+$BJ16+$BS16+$CB16+$CK16,0) -> 0 | CW16: =IF($CQ16="PROQUIMA",$BB16+$BK16+$BT16+$CC16+$CL16,0) -> 0 | CX16: =IF($CQ16="PROQUIMA",$BC16+$BL16+$BU16+$CD16+$CM16,0) -> 0 | CY16: =IF($CQ16="PROQUIMA",$BD16+$BM16+$BV16+$CE16+CN16,0) -> 316.75 | CZ16: =SUM(CR16:CY16)-CT16-CV16 -> 7816.75 | DA16: =IF($CQ16="UNHESA",$AW16+$BF16+$BO16+$BX16+$CG16,0) -> 0 | DB16: =IF($CQ16="UNHESA",$AX16+$BG16+$BP16+$BY16+$CH16,0) -> 0 | DC16: =IF($CQ16="UNHESA",$AY16+$BH16+$BQ16+$BZ16+$CI16,0) -> 0 | DD16: =IF($CQ16="UNHESA",$AZ16+$BI16+$BR16+$CA16+$CJ16,0) -> 0 | DE16: =IF($CQ16="UNHESA",$BA16+$BJ16+$BS16+$CB16+$CK16,0) -> 0 | DF16: =IF($CQ16="UNHESA",$BB16+$BK16+$BT16+$CC16+$CL16,0) -> 0 | DG16: =IF($CQ16="UNHESA",$BC16+$BL16+$BU16+$CD16+$CM16,0) -> 0 | DH16: =IF($CQ16="UNHESA",$BD16+$BM16+$BV16+$CE16+$CN16,0) -> 0 | DI16: =SUM(DA16:DH16)-DC16-DE16 -> 0 | EL16: 620.12 | EU16: =+EP16+EQ16+ER16 -> 0 | EW16: =IF($I16<=15,EL16/2,EL16) -> 310.06 | EX16: =IF($I16<=15,EM16/2,EM16) -> 0 | EY16: =IF($I16<=15,EN16/2,EN16) -> 0 | EZ16: =IF($I16<=15,EO16/2,EO16) -> 0 | FA16: =IF($I16<=15,EP16/2,EP16) -> 0 | FB16: =IF($I16<=15,EQ16/2,EQ16) -> 0 | FC16: =IF($I16<=15,ER16/2,ER16) -> 0 | FD16: =IF($I16<=15,ES16/2,ES16) -> 0 | ... FF16: =IF($I16<=15,EU16/2,EU16) -> 0 | FN16: =(((F16/30/8)*1.5)*(Q16+U16+Y16))-(AZ16+BI16+BR16) -> 0 | FO16: =(((F16/30/8)*2)*(S16+W16+AA16))-(BB16+BK16+BT16) -> 0 | FP16: =(SUM(AW16:CF16))-(SUM(CR16:DR16)) -> 0 | FQ16: =(F16/30*I16)-(CR16+DA16+DJ16) -> 0 | FR16: =(SUM(EL16:EU16))-((SUM(EW16:FF16))*$FR$5) -> 310.06
A17: 101030 | D17: Total Asesoria | F17: =+F16 -> 5000 | G17: =+G16 -> 10000 | H17: =+H16 -> 15000 | Q17: =+Q16 -> 0 | R17: =+R16 -> 0 | S17: =+S16 -> 0 | T17: =+T16 -> 0 | U17: =+U16 -> 0 | V17: =+V16 -> 0 | W17: =+W16 -> 0 | X17: =+X16 -> 0 | ... FF17: =+FF16 -> 0
A19: 101040 | C19: Pilotos
A20: 101040 | B20: 4 | C20: Chavez Najera Fredy Amilcar | D20: Piloto | E20: UNHESA | F20: 4002.28 | G20: 1500 | H20: =+F20+G20 -> 5502.28 | I20: 15 | J20: 0 | K20: 1 | L20: 0 | M20: 0 | N20: 0 | O20: =SUM(J20:N20) -> 1 | R20: =($F20/30/8*1.5)*Q20 -> 0 | T20: =($F20/30/8*2)*S20 -> 0 | V20: =($F20/30/8*1.5)*U20 -> 0 | X20: =($F20/30/8*2)*W20 -> 0 | Z20: =(($F20/30/8)*1.5)*Y20 -> 0 | AB20: =(($F20/30/8)*2)*AA20 -> 0 | AD20: =(($F20/30/8)*1.5)*AC20 -> 0 | AF20: =(($F20/30/8)*2)*AE20 -> 0 | AH20: =(($F20/30/8)*1.5)*AG20 -> 0 | AJ20: =(($F20/30/8)*2)*AI20 -> 0 | AW20: =(($F20/30)*$I20)*$J20 -> 0 | AX20: =(($G20/30)*$I20)*$J20 -> 0 | AY20: =Q20 -> 0 | AZ20: =R20 -> 0 | BA20: =S20 -> 0 | BB20: =T20 -> 0 | BC20: =AK20+AP20 -> 0 | BD20: =(AW20+AZ20+BB20+BC20)*0.1267 -> 0 | BE20: =SUM(AW20:BD20)-AY20-BA20 -> 0 | BF20: =(($F20/30)*$I20)*$K20 -> 2001.14 | BG20: =(($G20/30)*$I20)*$K20 -> 750 | BH20: =U20 -> 0 | BI20: =V20 -> 0 | BJ20: =W20 -> 0 | BK20: =X20 -> 0 | BL20: =AL20+AQ20 -> 0 | BM20: =(+BF20+BI20+BK20+BL20)*0.1267 -> 253.54444 | BN20: =SUM(BF20:BM20)-BH20-BJ20 -> 3004.6844 | BO20: =(($F20/30)*$I20)*$L20 -> 0 | BP20: =(($G20/30)*$I20)*$L20 -> 0 | BQ20: =Y20 -> 0 | BR20: =Z20 -> 0 | BS20: =AA20 -> 0 | BT20: =AB20 -> 0 | BU20: =AM20+AR20 -> 0 | BV20: =(BO20+BR20+BT20+BU20)*0.1267 -> 0 | BW20: =SUM(BO20:BV20)-BQ20-BS20 -> 0 | BX20: =(($F20/30)*$I20)*$M20 -> 0 | BY20: =(($G20/30)*$I20)*$M20 -> 0 | BZ20: =AC20 -> 0 | CA20: =AD20 -> 0 | CB20: =AE20 -> 0 | CC20: =AF20 -> 0 | CD20: =AN20+AS20 -> 0 | CE20: =(BX20+CA20+CC20)*0.1267 -> 0 | CF20: =SUM(BX20:CE20)-BZ20-CB20 -> 0 | CG20: =(($F20/30)*$I20)*N20 -> 0 | CH20: =(($G20/30)*$I20)*$N20 -> 0 | CI20: =+AG20 -> 0 | CJ20: =AH20 -> 0 | CK20: =AI20 -> 0 | CL20: =AJ20 -> 0 | CM20: =AO20+AT20 -> 0 | CN20: =(CG20+CJ20+CL20)*0.1267 -> 0 | CO20: =SUM(CG20:CN20)-CI20-CK20 -> 0 | CQ20: UNHESA | CR20: =IF($CQ20="PROQUIMA",$AW20+$BF20+$BO20+$BX20+$CG20,0) -> 0 | CS20: =IF($CQ20="PROQUIMA",$AX20+$BG20+$BP20+$BY20+$CH20,0) -> 0 | CT20: =IF($CQ20="PROQUIMA",$AY20+$BH20+$BQ20+$BZ20+$CI20,0) -> 0 | CU20: =IF($CQ20="PROQUIMA",$AZ20+$BI20+$BR20+$CA20+$CJ20,0) -> 0 | CV20: =IF($CQ20="PROQUIMA",$BA20+$BJ20+$BS20+$CB20+$CK20,0) -> 0 | CW20: =IF($CQ20="PROQUIMA",$BB20+$BK20+$BT20+$CC20+$CL20,0) -> 0 | CX20: =IF($CQ20="PROQUIMA",$BC20+$BL20+$BU20+$CD20+$CM20,0) -> 0 | CY20: =IF($CQ20="PROQUIMA",$BD20+$BM20+$BV20+$CE20+CN20,0) -> 0 | CZ20: =SUM(CR20:CY20)-CT20-CV20 -> 0 | DA20: =IF($CQ20="UNHESA",$AW20+$BF20+$BO20+$BX20+$CG20,0) -> 2001.14 | DB20: =IF($CQ20="UNHESA",$AX20+$BG20+$BP20+$BY20+$CH20,0) -> 750 | DC20: =IF($CQ20="UNHESA",$AY20+$BH20+$BQ20+$BZ20+$CI20,0) -> 0 | DD20: =IF($CQ20="UNHESA",$AZ20+$BI20+$BR20+$CA20+$CJ20,0) -> 0 | DE20: =IF($CQ20="UNHESA",$BA20+$BJ20+$BS20+$CB20+$CK20,0) -> 0 | DF20: =IF($CQ20="UNHESA",$BB20+$BK20+$BT20+$CC20+$CL20,0) -> 0 | DG20: =IF($CQ20="UNHESA",$BC20+$BL20+$BU20+$CD20+$CM20,0) -> 0 | DH20: =IF($CQ20="UNHESA",$BD20+$BM20+$BV20+$CE20+$CN20,0) -> 253.54444 | DI20: =SUM(DA20:DH20)-DC20-DE20 -> 3004.6844 | EL20: 65.45 | EU20: =+EP20+EQ20+ER20 -> 0 | EW20: =IF($I20<=15,EL20/2,EL20) -> 32.725 | EX20: =IF($I20<=15,EM20/2,EM20) -> 0 | EY20: =IF($I20<=15,EN20/2,EN20) -> 0 | EZ20: =IF($I20<=15,EO20/2,EO20) -> 0 | FA20: =IF($I20<=15,EP20/2,EP20) -> 0 | FB20: =IF($I20<=15,EQ20/2,EQ20) -> 0 | FC20: =IF($I20<=15,ER20/2,ER20) -> 0 | FD20: =IF($I20<=15,ES20/2,ES20) -> 0 | ... FF20: =IF($I20<=15,EU20/2,EU20) -> 0 | FN20: =(((F20/30/8)*1.5)*(Q20+U20+Y20))-(AZ20+BI20+BR20) -> 0 | FO20: =(((F20/30/8)*2)*(S20+W20+AA20))-(BB20+BK20+BT20) -> 0 | FP20: =(SUM(AW20:CF20))-(SUM(CR20:DR20)) -> 0 | FQ20: =(F20/30*I20)-(CR20+DA20+DJ20) -> 0 | FR20: =(SUM(EL20:EU20))-((SUM(EW20:FF20))*$FR$5) -> 32.725
A21: 101040 | C21: Gaitan Hernandez Luis Daniel | D21: Piloto | E21: PROQUIMA | F21: 6000 | G21: 1500 | H21: =+F21+G21 -> 7500 | I21: 15 | J21: 1 | K21: 0 | L21: 0 | M21: 0 | N21: 0 | O21: =SUM(J21:N21) -> 1 | R21: =($F21/30/8*1.5)*Q21 -> 0 | T21: =($F21/30/8*2)*S21 -> 0 | V21: =($F21/30/8*1.5)*U21 -> 0 | X21: =($F21/30/8*2)*W21 -> 0 | Z21: =(($F21/30/8)*1.5)*Y21 -> 0 | AB21: =(($F21/30/8)*2)*AA21 -> 0 | AD21: =(($F21/30/8)*1.5)*AC21 -> 0 | AF21: =(($F21/30/8)*2)*AE21 -> 0 | AH21: =(($F21/30/8)*1.5)*AG21 -> 0 | AJ21: =(($F21/30/8)*2)*AI21 -> 0 | AW21: =(($F21/30)*$I21)*$J21 -> 3000 | AX21: =(($G21/30)*$I21)*$J21 -> 750 | AY21: =Q21 -> 0 | AZ21: =R21 -> 0 | BA21: =S21 -> 0 | BB21: =T21 -> 0 | BC21: =AK21+AP21 -> 0 | BD21: =(AW21+AZ21+BB21+BC21)*0.1267 -> 380.1 | BE21: =SUM(AW21:BD21)-AY21-BA21 -> 4130.1 | BF21: =(($F21/30)*$I21)*$K21 -> 0 | BG21: =(($G21/30)*$I21)*$K21 -> 0 | BH21: =U21 -> 0 | BI21: =V21 -> 0 | BJ21: =W21 -> 0 | BK21: =X21 -> 0 | BL21: =AL21+AQ21 -> 0 | BM21: =(+BF21+BI21+BK21+BL21)*0.1267 -> 0 | BN21: =SUM(BF21:BM21)-BH21-BJ21 -> 0 | BO21: =(($F21/30)*$I21)*$L21 -> 0 | BP21: =(($G21/30)*$I21)*$L21 -> 0 | BQ21: =Y21 -> 0 | BR21: =Z21 -> 0 | BS21: =AA21 -> 0 | BT21: =AB21 -> 0 | BU21: =AM21+AR21 -> 0 | BV21: =(BO21+BR21+BT21+BU21)*0.1267 -> 0 | BW21: =SUM(BO21:BV21)-BQ21-BS21 -> 0 | BX21: =(($F21/30)*$I21)*$M21 -> 0 | BY21: =(($G21/30)*$I21)*$M21 -> 0 | BZ21: =AC21 -> 0 | CA21: =AD21 -> 0 | CB21: =AE21 -> 0 | CC21: =AF21 -> 0 | CD21: =AN21+AS21 -> 0 | CE21: =(BX21+CA21+CC21)*0.1267 -> 0 | CF21: =SUM(BX21:CE21)-BZ21-CB21 -> 0 | CG21: =(($F21/30)*$I21)*N21 -> 0 | CH21: =(($G21/30)*$I21)*$N21 -> 0 | CI21: =+AG21 -> 0 | CJ21: =AH21 -> 0 | CK21: =AI21 -> 0 | CL21: =AJ21 -> 0 | CM21: =AO21+AT21 -> 0 | CN21: =(CG21+CJ21+CL21)*0.1267 -> 0 | CO21: =SUM(CG21:CN21)-CI21-CK21 -> 0 | CQ21: PROQUIMA | CR21: =IF($CQ21="PROQUIMA",$AW21+$BF21+$BO21+$BX21+$CG21,0) -> 3000 | CS21: =IF($CQ21="PROQUIMA",$AX21+$BG21+$BP21+$BY21+$CH21,0) -> 750 | CT21: =IF($CQ21="PROQUIMA",$AY21+$BH21+$BQ21+$BZ21+$CI21,0) -> 0 | CU21: =IF($CQ21="PROQUIMA",$AZ21+$BI21+$BR21+$CA21+$CJ21,0) -> 0 | CV21: =IF($CQ21="PROQUIMA",$BA21+$BJ21+$BS21+$CB21+$CK21,0) -> 0 | CW21: =IF($CQ21="PROQUIMA",$BB21+$BK21+$BT21+$CC21+$CL21,0) -> 0 | CX21: =IF($CQ21="PROQUIMA",$BC21+$BL21+$BU21+$CD21+$CM21,0) -> 0 | CY21: =IF($CQ21="PROQUIMA",$BD21+$BM21+$BV21+$CE21+CN21,0) -> 380.1 | CZ21: =SUM(CR21:CY21)-CT21-CV21 -> 4130.1 | DA21: =IF($CQ21="UNHESA",$AW21+$BF21+$BO21+$BX21+$CG21,0) -> 0 | DB21: =IF($CQ21="UNHESA",$AX21+$BG21+$BP21+$BY21+$CH21,0) -> 0 | DC21: =IF($CQ21="UNHESA",$AY21+$BH21+$BQ21+$BZ21+$CI21,0) -> 0 | DD21: =IF($CQ21="UNHESA",$AZ21+$BI21+$BR21+$CA21+$CJ21,0) -> 0 | DE21: =IF($CQ21="UNHESA",$BA21+$BJ21+$BS21+$CB21+$CK21,0) -> 0 | DF21: =IF($CQ21="UNHESA",$BB21+$BK21+$BT21+$CC21+$CL21,0) -> 0 | DG21: =IF($CQ21="UNHESA",$BC21+$BL21+$BU21+$CD21+$CM21,0) -> 0 | DH21: =IF($CQ21="UNHESA",$BD21+$BM21+$BV21+$CE21+$CN21,0) -> 0 | DI21: =SUM(DA21:DH21)-DC21-DE21 -> 0 | EL21: 160.51 | EU21: =+EP21+EQ21+ER21 -> 0 | EW21: =IF($I21<=15,EL21/2,EL21) -> 80.255 | EX21: =IF($I21<=15,EM21/2,EM21) -> 0 | EY21: =IF($I21<=15,EN21/2,EN21) -> 0 | EZ21: =IF($I21<=15,EO21/2,EO21) -> 0 | FA21: =IF($I21<=15,EP21/2,EP21) -> 0 | FB21: =IF($I21<=15,EQ21/2,EQ21) -> 0 | FC21: =IF($I21<=15,ER21/2,ER21) -> 0 | FD21: =IF($I21<=15,ES21/2,ES21) -> 0 | ... FF21: =IF($I21<=15,EU21/2,EU21) -> 0
F23: =SUM(F20:F22) -> 10002.28 | G23: =SUM(G20:G22) -> 3000 | H23: =SUM(H20:H22) -> 13002.28 | Q23: =SUM(Q20:Q22) -> 0 | R23: =SUM(R20:R22) -> 0 | S23: =SUM(S20:S22) -> 0 | T23: =SUM(T20:T22) -> 0 | U23: =SUM(U20:U22) -> 0 | V23: =SUM(V20:V22) -> 0 | W23: =SUM(W20:W22) -> 0 | X23: =SUM(X20:X22) -> 0 | ... FF23: =SUM(FF20:FF22) -> 0
D24: Total Presidencia | Q24: =+Q10+Q13+Q17+Q23 -> 0 | R24: =+R10+R13+R17+R23 -> 0 | S24: =+S10+S13+S17+S23 -> 0 | T24: =+T10+T13+T17+T23 -> 0 | U24: =+U10+U13+U17+U23 -> 0 | V24: =+V10+V13+V17+V23 -> 0 | W24: =+W10+W13+W17+W23 -> 0 | X24: =+X10+X13+X17+X23 -> 0 | ... FF24: =+FF10+FF13+FF17+FF23 -> 0
A26: 102010 | C26: Administrativo
A29: 102050 | B29: 7 | C29: Quevedo Lopez Ingrid Aracely | D29: Conserje | E29: UNHESA | F29: 4002.28 | G29: 250 | H29: =+F29+G29 -> 4252.28 | I29: 15 | J29: 0 | K29: 1 | L29: 0 | M29: 0 | N29: 0 | O29: =SUM(J29:N29) -> 1 | R29: =($F29/30/8*1.5)*Q29 -> 0 | T29: =($F29/30/8*2)*S29 -> 0 | V29: =($F29/30/8*1.5)*U29 -> 0 | X29: =($F29/30/8*2)*W29 -> 0 | Z29: =(($F29/30/8)*1.5)*Y29 -> 0 | AB29: =(($F29/30/8)*2)*AA29 -> 0 | AD29: =(($F29/30/8)*1.5)*AC29 -> 0 | AF29: =(($F29/30/8)*2)*AE29 -> 0 | AH29: =(($F29/30/8)*1.5)*AG29 -> 0 | AJ29: =(($F29/30/8)*2)*AI29 -> 0 | AW29: =((F29/30)*I29)*$J29 -> 0 | AX29: =((G29/30)*I29)*$J29 -> 0 | AY29: =Q29 -> 0 | AZ29: =R29 -> 0 | BA29: =S29 -> 0 | BB29: =T29 -> 0 | BC29: =AK29+AP29 -> 0 | BD29: =(AW29+AZ29+BB29+BC29)*0.1267 -> 0 | BE29: =SUM(AW29:BD29)-AY29-BA29 -> 0 | BF29: =(($F29/30)*$I29)*$K29 -> 2001.14 | BG29: =(($G29/30)*$I29)*$K29 -> 125 | BH29: =U29 -> 0 | BI29: =V29 -> 0 | BJ29: =W29 -> 0 | BK29: =X29 -> 0 | BL29: =AL29+AQ29 -> 0 | BM29: =(+BF29+BI29+BK29+BL29)*0.1267 -> 253.54444 | BN29: =SUM(BF29:BM29)-BH29-BJ29 -> 2379.6844 | BO29: =(($F29/30)*$I29)*$L29 -> 0 | BP29: =(($G29/30)*$I29)*$L29 -> 0 | BQ29: =Y29 -> 0 | BR29: =Z29 -> 0 | BS29: =AA29 -> 0 | BT29: =AB29 -> 0 | BU29: =AM29+AR29 -> 0 | BV29: =(BO29+BR29+BT29+BU29)*0.1267 -> 0 | BW29: =SUM(BO29:BV29)-BQ29-BS29 -> 0 | BX29: =(($F29/30)*$I29)*$M29 -> 0 | BY29: =(($G29/30)*$I29)*$M29 -> 0 | BZ29: =AC29 -> 0 | CA29: =AD29 -> 0 | CB29: =AE29 -> 0 | CC29: =AF29 -> 0 | CD29: =AN29+AS29 -> 0 | CE29: =(BX29+CA29+CC29)*0.1267 -> 0 | CF29: =SUM(BX29:CE29)-BZ29-CB29 -> 0 | CG29: =(($F29/30)*$I29)*N29 -> 0 | CH29: =(($G29/30)*$I29)*$N29 -> 0 | CI29: =+AG29 -> 0 | CJ29: =AH29 -> 0 | CK29: =AI29 -> 0 | CL29: =AJ29 -> 0 | CM29: =AO29+AT29 -> 0 | CN29: =(CG29+CJ29+CL29)*0.1267 -> 0 | CO29: =SUM(CG29:CN29)-CI29-CK29 -> 0 | CQ29: UNHESA | CR29: =IF($CQ29="PROQUIMA",$AW29+$BF29+$BO29+$BX29+$CG29,0) -> 0 | CS29: =IF($CQ29="PROQUIMA",$AX29+$BG29+$BP29+$BY29+$CH29,0) -> 0 | CT29: =IF($CQ29="PROQUIMA",$AY29+$BH29+$BQ29+$BZ29+$CI29,0) -> 0 | CU29: =IF($CQ29="PROQUIMA",$AZ29+$BI29+$BR29+$CA29+$CJ29,0) -> 0 | CV29: =IF($CQ29="PROQUIMA",$BA29+$BJ29+$BS29+$CB29+$CK29,0) -> 0 | CW29: =IF($CQ29="PROQUIMA",$BB29+$BK29+$BT29+$CC29+$CL29,0) -> 0 | CX29: =IF($CQ29="PROQUIMA",$BC29+$BL29+$BU29+$CD29+$CM29,0) -> 0 | CY29: =IF($CQ29="PROQUIMA",$BD29+$BM29+$BV29+$CE29+CN29,0) -> 0 | CZ29: =SUM(CR29:CY29)-CT29-CV29 -> 0 | DA29: =IF($CQ29="UNHESA",$AW29+$BF29+$BO29+$BX29+$CG29,0) -> 2001.14 | DB29: =IF($CQ29="UNHESA",$AX29+$BG29+$BP29+$BY29+$CH29,0) -> 125 | DC29: =IF($CQ29="UNHESA",$AY29+$BH29+$BQ29+$BZ29+$CI29,0) -> 0 | DD29: =IF($CQ29="UNHESA",$AZ29+$BI29+$BR29+$CA29+$CJ29,0) -> 0 | DE29: =IF($CQ29="UNHESA",$BA29+$BJ29+$BS29+$CB29+$CK29,0) -> 0 | DF29: =IF($CQ29="UNHESA",$BB29+$BK29+$BT29+$CC29+$CL29,0) -> 0 | DG29: =IF($CQ29="UNHESA",$BC29+$BL29+$BU29+$CD29+$CM29,0) -> 0 | DH29: =IF($CQ29="UNHESA",$BD29+$BM29+$BV29+$CE29+$CN29,0) -> 253.54444 | DI29: =SUM(DA29:DH29)-DC29-DE29 -> 2379.6844 | DJ29: =IF($CQ29="UNHESA LIQUIDOS",$AW29+$BF29+$BO29+$BX29+$CG29,0) -> 0 | DK29: =IF($CQ29="CALIDUL",$AX29+$BG29+$BP29+$BY29+$CH29,0) -> 0 | DL29: =IF($CQ29="CALIDUL",$AY29+$BH29+$BQ29+$BZ29+$CI29,0) -> 0 | DM29: =IF($CQ29="CALIDUL",$AZ29+$BI29+$BR29+$CA29+$CJ29,0) -> 0 | DN29: =IF($CQ29="CALIDUL",$BA29+$BJ29+$BS29+$CB29+$CK29,0) -> 0 | DO29: =IF($CQ29="CALIDUL",$BB29+$BK29+$BT29+$CC29+$CL29,0) -> 0 | DP29: =IF($CQ29="CALIDUL",$BC29+$BL29+$BU29+$CD29+$CM29,0) -> 0 | DQ29: =IF($CQ29="CALIDUL",$BD29+$BM29+$BV29+$CE29+$CN29,0) -> 0 | DR29: =SUM(DJ29:DQ29)-DL29-DN29 -> 0 | DS29: =IF($CQ29="ECONACIONAL",$AW29+$BF29+$BO29+$BX29+$CG29,0) -> 0 | DT29: =IF($CQ29="ECONACIONAL",$AX29+$BG29+$BP29+$BY29+$CH29,0) -> 0 | DU29: =IF($CQ29="ECONACIONAL",$AY29+$BH29+$BQ29+$BZ29+$CI29,0) -> 0 | DV29: =IF($CQ29="ECONACIONAL",$AZ29+$BI29+$BR29+$CA29+$CJ29,0) -> 0 | DW29: =IF($CQ29="ECONACIONAL",$BA29+$BJ29+$BS29+$CB29+$CK29,0) -> 0 | DX29: =IF($CQ29="ECONACIONAL",$BB29+$BK29+$BT29+$CC29+$CL29,0) -> 0 | DY29: =IF($CQ29="ECONACIONAL",$BC29+$BL29+$BU29+$CD29+$CM29,0) -> 0 | DZ29: =IF($CQ29="ECONACIONAL",$BD29+$BM29+$BV29+$CE29+$CN29,0) -> 0 | EA29: =SUM(DS29:DZ29)-DU29-DW29 -> 0 | EB29: =IF($CQ29="CLEARTEC",$AW29+$BF29+$BO29+$BX29+$CG29,0) -> 0 | EC29: =IF($CQ29="CLEARTEC",$AX29+$BG29+$BP29+$BY29+$CH29,0) -> 0 | ED29: =IF($CQ29="CLEARTEC",$AY29+$BH29+$BQ29+$BZ29+$CI29,0) -> 0 | EE29: =IF($CQ29="CLEARTEC",$AZ29+$BI29+$BR29+$CA29+$CJ29,0) -> 0 | EF29: =IF($CQ29="CLEARTEC",$BA29+$BJ29+$BS29+$CB29+$CK29,0) -> 0 | EG29: =IF($CQ29="CLEARTEC",$BB29+$BK29+$BT29+$CC29+$CL29,0) -> 0 | EH29: =IF($CQ29="CLEARTEC",$BC29+$BL29+$BU29+$CD29+$CM29,0) -> 0 | EI29: =IF($CQ29="CLEARTEC",$BD29+$BM29+$BV29+$CE29+$CN29,0) -> 0 | EJ29: =SUM(EB29:EI29)-ED29-EF29 -> 0 | EL29: 2.95 | EM29: 1951.06 | EU29: =+EP29+EQ29+ER29 -> 0 | EW29: =IF($I29<=15,EL29/2,EL29) -> 1.475 | EX29: =IF($I29<=15,EM29/2,EM29) -> 975.53 | EY29: =IF($I29<=15,EN29/2,EN29) -> 0 | EZ29: =IF($I29<=15,EO29/2,EO29) -> 0 | FA29: =IF($I29<=15,EP29/2,EP29) -> 0 | FB29: =IF($I29<=15,EQ29/2,EQ29) -> 0 | FC29: =IF($I29<=15,ER29/2,ER29) -> 0 | FD29: =IF($I29<=15,ES29/2,ES29) -> 0 | ... FF29: =IF($I29<=15,EU29/2,EU29) -> 0 | FN29: =(((F29/30/8)*1.5)*(Q29+U29+Y29))-(AZ29+BI29+BR29) -> 0 | FO29: =(((F29/30/8)*2)*(S29+W29+AA29))-(BB29+BK29+BT29) -> 0 | FP29: =(SUM(AW29:CF29))-(SUM(CR29:DR29)) -> 0 | FQ29: =(F29/30*I29)-(CR29+DA29+DJ29) -> 0 | FR29: =(SUM(EL29:EU29))-((SUM(EW29:FF29))*$FR$5) -> 977.005
A30: 102050 | B30: 8 | C30: Morales Alvarez Yony | D30: Conserje | E30: UNHESA | F30: 4002.28 | G30: 250 | H30: =+F30+G30 -> 4252.28 | I30: 15 | J30: 0 | K30: 1 | L30: 0 | M30: 0 | N30: 0 | O30: =SUM(J30:N30) -> 1 | R30: =($F30/30/8*1.5)*Q30 -> 0 | T30: =($F30/30/8*2)*S30 -> 0 | V30: =($F30/30/8*1.5)*U30 -> 0 | X30: =($F30/30/8*2)*W30 -> 0 | Z30: =(($F30/30/8)*1.5)*Y30 -> 0 | AB30: =(($F30/30/8)*2)*AA30 -> 0 | AD30: =(($F30/30/8)*1.5)*AC30 -> 0 | AF30: =(($F30/30/8)*2)*AE30 -> 0 | AH30: =(($F30/30/8)*1.5)*AG30 -> 0 | AJ30: =(($F30/30/8)*2)*AI30 -> 0 | AW30: =((F30/30)*I30)*$J30 -> 0 | AX30: =((G30/30)*I30)*$J30 -> 0 | AY30: =Q30 -> 0 | AZ30: =R30 -> 0 | BA30: =S30 -> 0 | BB30: =T30 -> 0 | BC30: =AK30+AP30 -> 0 | BD30: =(AW30+AZ30+BB30+BC30)*0.1267 -> 0 | BE30: =SUM(AW30:BD30)-AY30-BA30 -> 0 | BF30: =(($F30/30)*$I30)*$K30 -> 2001.14 | BG30: =(($G30/30)*$I30)*$K30 -> 125 | BH30: =U30 -> 0 | BI30: =V30 -> 0 | BJ30: =W30 -> 0 | BK30: =X30 -> 0 | BL30: =AL30+AQ30 -> 0 | BM30: =(+BF30+BI30+BK30+BL30)*0.1267 -> 253.54444 | BN30: =SUM(BF30:BM30)-BH30-BJ30 -> 2379.6844 | BO30: =(($F30/30)*$I30)*$L30 -> 0 | BP30: =(($G30/30)*$I30)*$L30 -> 0 | BQ30: =Y30 -> 0 | BR30: =Z30 -> 0 | BS30: =AA30 -> 0 | BT30: =AB30 -> 0 | BU30: =AM30+AR30 -> 0 | BV30: =(BO30+BR30+BT30+BU30)*0.1267 -> 0 | BW30: =SUM(BO30:BV30)-BQ30-BS30 -> 0 | BX30: =(($F30/30)*$I30)*$M30 -> 0 | BY30: =(($G30/30)*$I30)*$M30 -> 0 | BZ30: =AC30 -> 0 | CA30: =AD30 -> 0 | CB30: =AE30 -> 0 | CC30: =AF30 -> 0 | CD30: =AN30+AS30 -> 0 | CE30: =(BX30+CA30+CC30)*0.1267 -> 0 | CF30: =SUM(BX30:CE30)-BZ30-CB30 -> 0 | CG30: =(($F30/30)*$I30)*N30 -> 0 | CH30: =(($G30/30)*$I30)*$N30 -> 0 | CI30: =+AG30 -> 0 | CJ30: =AH30 -> 0 | CK30: =AI30 -> 0 | CL30: =AJ30 -> 0 | CM30: =AO30+AT30 -> 0 | CN30: =(CG30+CJ30+CL30)*0.1267 -> 0 | CO30: =SUM(CG30:CN30)-CI30-CK30 -> 0 | CQ30: UNHESA | CR30: =IF($CQ30="PROQUIMA",$AW30+$BF30+$BO30+$BX30+$CG30,0) -> 0 | CS30: =IF($CQ30="PROQUIMA",$AX30+$BG30+$BP30+$BY30+$CH30,0) -> 0 | CT30: =IF($CQ30="PROQUIMA",$AY30+$BH30+$BQ30+$BZ30+$CI30,0) -> 0 | CU30: =IF($CQ30="PROQUIMA",$AZ30+$BI30+$BR30+$CA30+$CJ30,0) -> 0 | CV30: =IF($CQ30="PROQUIMA",$BA30+$BJ30+$BS30+$CB30+$CK30,0) -> 0 | CW30: =IF($CQ30="PROQUIMA",$BB30+$BK30+$BT30+$CC30+$CL30,0) -> 0 | CX30: =IF($CQ30="PROQUIMA",$BC30+$BL30+$BU30+$CD30+$CM30,0) -> 0 | CY30: =IF($CQ30="PROQUIMA",$BD30+$BM30+$BV30+$CE30+CN30,0) -> 0 | CZ30: =SUM(CR30:CY30)-CT30-CV30 -> 0 | DA30: =IF($CQ30="UNHESA",$AW30+$BF30+$BO30+$BX30+$CG30,0) -> 2001.14 | DB30: =IF($CQ30="UNHESA",$AX30+$BG30+$BP30+$BY30+$CH30,0) -> 125 | DC30: =IF($CQ30="UNHESA",$AY30+$BH30+$BQ30+$BZ30+$CI30,0) -> 0 | DD30: =IF($CQ30="UNHESA",$AZ30+$BI30+$BR30+$CA30+$CJ30,0) -> 0 | DE30: =IF($CQ30="UNHESA",$BA30+$BJ30+$BS30+$CB30+$CK30,0) -> 0 | DF30: =IF($CQ30="UNHESA",$BB30+$BK30+$BT30+$CC30+$CL30,0) -> 0 | DG30: =IF($CQ30="UNHESA",$BC30+$BL30+$BU30+$CD30+$CM30,0) -> 0 | DH30: =IF($CQ30="UNHESA",$BD30+$BM30+$BV30+$CE30+$CN30,0) -> 253.54444 | DI30: =SUM(DA30:DH30)-DC30-DE30 -> 2379.6844 | DJ30: =IF($CQ30="UNHESA LIQUIDOS",$AW30+$BF30+$BO30+$BX30+$CG30,0) -> 0 | DK30: =IF($CQ30="CALIDUL",$AX30+$BG30+$BP30+$BY30+$CH30,0) -> 0 | DL30: =IF($CQ30="CALIDUL",$AY30+$BH30+$BQ30+$BZ30+$CI30,0) -> 0 | DM30: =IF($CQ30="CALIDUL",$AZ30+$BI30+$BR30+$CA30+$CJ30,0) -> 0 | DN30: =IF($CQ30="CALIDUL",$BA30+$BJ30+$BS30+$CB30+$CK30,0) -> 0 | DO30: =IF($CQ30="CALIDUL",$BB30+$BK30+$BT30+$CC30+$CL30,0) -> 0 | DP30: =IF($CQ30="CALIDUL",$BC30+$BL30+$BU30+$CD30+$CM30,0) -> 0 | DQ30: =IF($CQ30="CALIDUL",$BD30+$BM30+$BV30+$CE30+$CN30,0) -> 0 | DR30: =SUM(DJ30:DQ30)-DL30-DN30 -> 0 | DS30: =IF($CQ30="ECONACIONAL",$AW30+$BF30+$BO30+$BX30+$CG30,0) -> 0 | DT30: =IF($CQ30="ECONACIONAL",$AX30+$BG30+$BP30+$BY30+$CH30,0) -> 0 | DU30: =IF($CQ30="ECONACIONAL",$AY30+$BH30+$BQ30+$BZ30+$CI30,0) -> 0 | DV30: =IF($CQ30="ECONACIONAL",$AZ30+$BI30+$BR30+$CA30+$CJ30,0) -> 0 | DW30: =IF($CQ30="ECONACIONAL",$BA30+$BJ30+$BS30+$CB30+$CK30,0) -> 0 | DX30: =IF($CQ30="ECONACIONAL",$BB30+$BK30+$BT30+$CC30+$CL30,0) -> 0 | DY30: =IF($CQ30="ECONACIONAL",$BC30+$BL30+$BU30+$CD30+$CM30,0) -> 0 | DZ30: =IF($CQ30="ECONACIONAL",$BD30+$BM30+$BV30+$CE30+$CN30,0) -> 0 | EA30: =SUM(DS30:DZ30)-DU30-DW30 -> 0 | EB30: =IF($CQ30="CLEARTEC",$AW30+$BF30+$BO30+$BX30+$CG30,0) -> 0 | EC30: =IF($CQ30="CLEARTEC",$AX30+$BG30+$BP30+$BY30+$CH30,0) -> 0 | ED30: =IF($CQ30="CLEARTEC",$AY30+$BH30+$BQ30+$BZ30+$CI30,0) -> 0 | EE30: =IF($CQ30="CLEARTEC",$AZ30+$BI30+$BR30+$CA30+$CJ30,0) -> 0 | EF30: =IF($CQ30="CLEARTEC",$BA30+$BJ30+$BS30+$CB30+$CK30,0) -> 0 | EG30: =IF($CQ30="CLEARTEC",$BB30+$BK30+$BT30+$CC30+$CL30,0) -> 0 | EH30: =IF($CQ30="CLEARTEC",$BC30+$BL30+$BU30+$CD30+$CM30,0) -> 0 | EI30: =IF($CQ30="CLEARTEC",$BD30+$BM30+$BV30+$CE30+$CN30,0) -> 0 | EJ30: =SUM(EB30:EI30)-ED30-EF30 -> 0 | EL30: 2.95 | EU30: =+EP30+EQ30+ER30 -> 0 | EW30: =IF($I30<=15,EL30/2,EL30) -> 1.475 | EX30: =IF($I30<=15,EM30/2,EM30) -> 0 | EY30: =IF($I30<=15,EN30/2,EN30) -> 0 | EZ30: =IF($I30<=15,EO30/2,EO30) -> 0 | FA30: =IF($I30<=15,EP30/2,EP30) -> 0 | FB30: =IF($I30<=15,EQ30/2,EQ30) -> 0 | FC30: =IF($I30<=15,ER30/2,ER30) -> 0 | FD30: =IF($I30<=15,ES30/2,ES30) -> 0 | ... FF30: =IF($I30<=15,EU30/2,EU30) -> 0 | FN30: =(((F30/30/8)*1.5)*(Q30+U30+Y30))-(AZ30+BI30+BR30) -> 0 | FO30: =(((F30/30/8)*2)*(S30+W30+AA30))-(BB30+BK30+BT30) -> 0 | FP30: =(SUM(AW30:CF30))-(SUM(CR30:DR30)) -> 0 | FQ30: =(F30/30*I30)-(CR30+DA30+DJ30) -> 0 | FR30: =(SUM(EL30:EU30))-((SUM(EW30:FF30))*$FR$5) -> 1.475
D31: Total Administrativo | F31: =SUM(F27:F30) -> 8004.56 | G31: =SUM(G27:G30) -> 500 | H31: =SUM(H27:H30) -> 8504.56 | Q31: =SUM(Q27:Q30) -> 0 | R31: =SUM(R27:R30) -> 0 | S31: =SUM(S27:S30) -> 0 | T31: =SUM(T27:T30) -> 0 | U31: =SUM(U27:U30) -> 0 | V31: =SUM(V27:V30) -> 0 | W31: =SUM(W27:W30) -> 0 | X31: =SUM(X27:X30) -> 0 | ... FF31: =SUM(FF27:FF30) -> 0
A33: 102050 | C33: Conserjería Presidencia | FN33: =(((F33/30/8)*1.5)*(Q33+U33+Y33))-(AZ33+BI33+BR33) -> 0 | FO33: =(((F33/30/8)*2)*(S33+W33+AA33))-(BB33+BK33+BT33) -> 0 | FP33: =(SUM(AW33:CF33))-(SUM(CR33:DR33)) -> 0 | FQ33: =(F33/30*I33)-(CR33+DA33+DJ33) -> 0 | FR33: =(SUM(EL33:EU33))-((SUM(EW33:FF33))*$FR$5) -> 0
