Workbook
Name ECONACIONAL: 'Nomina Econacional'!$A$4:$AB$153
Name Excel_BuiltIn__FilterDatabase: 'boleto de ornato'!#REF!
Name Excel_BuiltIn__FilterDatabase: distribucion!$T$6:$T$153
Name Excel_BuiltIn__FilterDatabase: 'IGSS ECONACIONAL'!$B$5:$AB$6
Name Excel_BuiltIn__FilterDatabase: 'INCREMENTO SALARIO MINIMO '!#REF!
Name Excel_BuiltIn__FilterDatabase: 'RECIBO E IGSS ECONACIONAL'!$B$1:$AB$2

Sheet distribucion
G1: 1 | H1: 2 | I1: 3 | J1: 4 | K1: 5 | L1: 6 | M1: 7 | N1: 8 | O1: 9 | P1: 10 | Q1: 11 | R1: 12 | S1: 13 | T1: 14 | U1: 15 | V1: 16 | W1: 17 | X1: 18 | Y1: 19 | Z1: 20 | AA1: 21 | AB1: 22 | AC1: 23 | AD1: 24 | AE1: 25 | AF1: 26 | AG1: 27 | AH1: 28 | AI1: 29 | AJ1: 30 | AK1: 31 | AL1: 32 | AM1: 33 | AN1: 34 | AO1: 35 | AP1: 36 | AQ1: 37 | AR1: 38 | AS1: 39 | AT1: 40 | AU1: 41 | AV1: 42 | AW1: 43 | AX1: 44 | AY1: 45 | AZ1: 46 | BA1: 47 | BB1: 48 | BC1: 49 | BD1: 50 | BE1: 51 | BF1: 52 | BG1: 53 | BH1: 54 | BI1: 55 | BJ1: 56 | BK1: 57 | BL1: 58 | BM1: 59 | BN1: 60 | BO1: 61 | BP1: 62 | BQ1: 63 | BR1: 64 | BS1: 65 | BT1: 66 | BU1: 67 | BV1: 68 | BW1: 69 | BX1: 70 | BY1: 71 | BZ1: 72 | CA1: 73 | CB1: 74 | CC1: 75 | CD1: 76 | CE1: 77 | CF1: 78 | CG1: 79 | CH1: 80 | CI1: 81 | CJ1: 82 | CK1: 83 | CL1: 84 | CM1: 85 | CN1: 86 | CO1: 87 | CP1: 88 | CQ1: 89 | CR1: 90 | CS1: 91 | CT1: 92 | CU1: 93 | CV1: 94 | CW1: 95 | CX1: 96 | CY1: 97 | CZ1: 98 | DA1: 99 | DB1: 100 | DC1: 101 | DD1: 102 | DE1: 103 | DF1: 104 | DG1: 105 | DH1: 106 | DI1: 107 | DJ1: 108 | DK1: 109 | DL1: 110 | DM1: 111 | DN1: 112 | DO1: 113 | DP1: 114 | DQ1: 115 | DR1: 116 | DS1: 117 | DT1: 118 | DU1: 119 | DV1: 120 | DW1: 121 | DX1: 122 | DY1: 123 | DZ1: 124 | EA1: 125 | EB1: 126 | EC1: 127 | ED1: 128 | EE1: 129 | EF1: 130 | EG1: 131 | EH1: 132 | EI1: 133 | EJ1: 134 | EK1: 135 | EL1: 136 | EM1: 137 | EN1: 138 | EO1: 139 | EP1: 140 | EQ1: 141 | ER1: 142 | ES1: 143 | ET1: 144 | EU1: 145 | EV1: 146 | EW1: 147 | EX1: 148 | EY1: 149 | EZ1: 150 | FA1: 151 | FB1: 152 | FC1: 153 | FD1: 154 | FE1: 155 | FF1: 156 | FG1: 157 | FH1: 158 | FI1: 159 | FJ1: 160
G3: NOMINA ECONACIONAL, S. A. | R3: .
G4: JUNIO 2026 2da QUINCENA | BA4: NOMINAS SEGÚN DISTRIBUCION REAL | CV4: NOMINAS SEGÚN DISTRIBUCION CONTABILIDAD | FV4: QUINCENA: 2 MES: 1
G5: 2026 | J5: 5 | K5: 6 | U5: HORAS EXTRAS PROQUIMA | Y5: HORAS EXTRAS UNHESA | AC5: HORAS EXTRAS HIDROXON | AG5: HORAS EXTRAS CLEARTEC | AK5: HORAS EXTRAS PROQUIMA MAQUILA | AO5: Otros Ingresos | AT5: Comisiones | BA5: PROQUIMA | BJ5: UNHESA | BS5: HIDROXON | CB5: CLEARTEC | CV5: PROQUIMA | DE5: UNHESA | DN5: UNHESA LIQUIDOS | DW5: CLEARTEC | EF5: ECONACIONAL | FK5: DISTRIBUCION REAL | FV5: 2
I6: DISTRIBUCION DE EMPLEADOS | U6: H.E. Simples | V6: H.E. Simples | W6: H.E. Dobles | X6: H.E. Dobles | Y6: H.E. Simples | Z6: H.E. Simples | AA6: H.E. Dobles | AB6: H.E. Dobles | AC6: H.E. Simples | AD6: H.E. Simples | AE6: H.E. Dobles | AF6: H.E. Dobles | AG6: H.E. Simples | AH6: H.E. Simples | AI6: H.E. Dobles | AJ6: H.E. Dobles | AK6: H.E. Simples | AL6: H.E. Simples | AM6: H.E. Dobles | AN6: H.E. Dobles | AO6: Proquima | AP6: Unhesa | AQ6: Calidul | AR6: Econacional | AS6: Cleartec | AT6: Proquima | AU6: Unhesa | AV6: Calidul | AW6: Econacional | AX6: Cleartec | AY6: Otrros ingresos | AZ6: 0 | BA6: Salario | BB6: Bono | BC6: cantidad | BD6: Hrs. Extra | BE6: cantidad | BF6: Hrs. Extra | BG6: Comis / | BH6: Cuota | BI6: Total | BJ6: Salario | BK6: Bono | BL6: cantidad | BM6: Hrs. Extra | BN6: cantidad | BO6: Hrs. Extra | BP6: Comis / | BQ6: Cuota | BR6: Total | BS6: Salario | BT6: Bono | BU6: cantidad | BV6: Hrs. Extra | BW6: cantidad | BX6: Hrs. Extra | BY6: Comis / | BZ6: Cuota | CA6: Total | CB6: Salario | CC6: Bono | CD6: cantidad | CE6: Hrs. Extra | CF6: cantidad | CG6: Hrs. Extra | CH6: Comis / | CI6: Cuota | CJ6: Total | CK6: Salario | CL6: Bono | CM6: cantidad | CN6: Hrs. Extra | CO6: cantidad | CP6: Hrs. Extra | CQ6: Comis / | CR6: Cuota | CS6: Total | CU6: Nueva | CV6: Salario | CW6: Bono | CX6: cantidad | CY6: Hrs. Extra | CZ6: cantidad | DA6: Hrs. Extra | DB6: Comis / | DC6: Cuota | DD6: Total | DE6: Salario | DF6: Bono | DG6: cantidad | DH6: Hrs. Extra | DI6: cantidad | DJ6: Hrs. Extra | DK6: Comis / | DL6: Cuota | DM6: Total | DN6: Salario | DO6: Bono | DP6: cantidad | DQ6: Hrs. Extra | DR6: cantidad | DS6: Hrs. Extra | DT6: Comis / | DU6: Cuota | DV6: Total | DW6: Salario | DX6: Bono | DY6: cantidad | DZ6: Hrs. Extra | EA6: cantidad | EB6: Hrs. Extra | EC6: Comis / | ED6: Cuota | EE6: Total | EF6: Salario | EG6: Bono | EH6: cantidad | EI6: Hrs. Extra | EJ6: cantidad | EK6: Hrs. Extra | EL6: Comis / | EM6: Cuota | EN6: Total | EP6: EGRESOS MENSUALES | FA6: EGRESOS | FK6: % | FL6: % | FM6: % | FN6: % | FO6: % | FP6: %
A7: MES | B7: AÑO | C7: MES/AÑO | D7: CC | E7: Código División | G7: Nombre | H7: Puesto | I7: Empresa Real | J7: Salario Ordinario | K7: Bono Decreto | L7: Total | M7: Días Laborados | N7: % Proquima | O7: % Unhesa | P7: HIDROXON | Q7: % Cleartec | S7: Total % Distribución | T7: Observaciones | U7: Cantidad | V7: Valor | W7: Cantidad | X7: Valor | Y7: Cantidad | Z7: Valor | AA7: Cantidad | AB7: Valor | AC7: Cantidad | AD7: Valor | AE7: Cantidad | AF7: Valor | AG7: Cantidad | AH7: Valor | AI7: Cantidad | AJ7: Valor | AK7: Cantidad | AL7: Valor | AM7: Cantidad | AN7: Valor | BA7: Ordinario | BB7: Decreto | BC7: simples | BD7: simples | BE7: dobles | BF7: dobles | BG7: Otros | BH7: Patronal | BJ7: Ordinario | BK7: Decreto | BL7: simples | BM7: simples | BN7: dobles | BO7: dobles | BP7: Otros | BQ7: Patronal | BS7: Ordinario | BT7: Decreto | BU7: simples | BV7: simples | BW7: dobles | BX7: dobles | BY7: Otros | BZ7: Patronal | CB7: Ordinario | CC7: Decreto | CD7: simples | CE7: simples | CF7: dobles | CG7: dobles | CH7: Otros | CI7: Patronal | CK7: Ordinario | CL7: Decreto | CM7: simples | CN7: simples | CO7: dobles | CP7: dobles | CQ7: Otros | CR7: Patronal | CU7: Empresa | CV7: Ordinario | CW7: Decreto | CX7: simples | CY7: simples | CZ7: dobles | DA7: dobles | DB7: Otros | DC7: Patronal | DE7: Ordinario | DF7: Decreto | DG7: simples | DH7: simples | DI7: dobles | DJ7: dobles | DK7: Otros | DL7: Patronal | DN7: Ordinario | DO7: Decreto | DP7: simples | DQ7: simples | DR7: dobles | DS7: dobles | DT7: Otros | DU7: Patronal | DW7: Ordinario | DX7: Decreto | DY7: simples | DZ7: simples | EA7: dobles | EB7: dobles | EC7: Otros | ED7: Patronal | EF7: Ordinario | EG7: Decreto | EH7: simples | EI7: simples | EJ7: dobles | EK7: dobles | EL7: Otros | EM7: Patronal | EP7: ISR | EQ7: BANCOS | ER7: CELULAR | ES7: CAFETERIA | ET7: DESCUENTO producto | EU7: SEGURO/ tarjeta de salud/boleto de ornato | EV7: Otros Descuentos | EW7: CALZADO | EX7: UNIFORME | EY7: TOTAL EGRESOS Bol Ornato, Seguro, Otros | FA7: ISR | FB7: BANCOS | FC7: CELULAR | FD7: CAFETERIA | FE7: DESCUENTO PRODUCTO | FF7: SEGURO | FG7: Otros Descuentos | FH7: CALZADO | FI7: UNIFORME | FJ7: OTROS EGRESOS | FK7: % Proquima | FL7: % Unhesa | FM7: % Unhesa Liq. | FN7: % Econacional | FO7: % Ecomezclas | FP7: Total % Distribución
A8: =+$G$4 -> JUNIO 2026 2da QUINCENA | B8: =+$G$5 -> 2026 | C8: =A8 & B8 -> JUNIO 2026 2da QUINCENA2026 | D8: =+$G$8 -> ADMINISTRATIVO | E8: 102010 | G8: ADMINISTRATIVO
E9: 102010 | F9: 1 | G9: Hernandez Maria Andrea | H9: Asistente de Gerencia General | I9: ECONACIONAL | J9: 5000 | K9: 1000 | L9: =+J9+K9 -> 6000 | M9: 30 | N9: 0.5 | O9: 0.4 | P9: 0.1 | Q9: 0 | R9: 0 | S9: =SUM(N9:R9) -> 1 | V9: =($J9/30/8*1.5)*U9 -> 0 | X9: =($J9/30/8*2)*W9 -> 0 | Z9: =($J9/30/8*1.5)*Y9 -> 0 | AB9: =($J9/30/8*2)*AA9 -> 0 | AD9: =(($J9/30/8)*1.5)*AC9 -> 0 | AF9: =(($J9/30/8)*2)*AE9 -> 0 | AH9: =(($J9/30/8)*1.5)*AG9 -> 0 | AI9: 0 | AJ9: =(($J9/30/8)*2)*AI9 -> 0 | AL9: =(($J9/30/8)*1.5)*AK9 -> 0 | AN9: =(($J9/30/8)*2)*AM9 -> 0 | BA9: =(($J9/30)*$M9)*$N9 -> 2500 | BB9: =((K9/30)*M9)*$N9 -> 500 | BC9: =U9 -> 0 | BD9: =V9 -> 0 | BE9: =W9 -> 0 | BF9: =X9 -> 0 | BG9: =AO9+AT9 -> 0 | BH9: =(BA9+BD9+BF9+BG9)*0.1267 -> 316.75 | BI9: =SUM(BA9:BH9)-BC9-BE9 -> 3316.75 | BJ9: =(($J9/30)*$M9)*$O9 -> 2000 | BK9: =(($K9/30)*$M9)*$O9 -> 400 | BL9: =Y9 -> 0 | BM9: =Z9 -> 0 | BN9: =AA9 -> 0 | BO9: =AB9 -> 0 | BP9: =AP9+AU9 -> 0 | BQ9: =(+BJ9+BM9+BO9+BP9)*0.1267 -> 253.4 | BR9: =SUM(BJ9:BQ9)-BL9-BN9 -> 2653.4 | BS9: =(($J9/30)*$M9)*$P9 -> 500 | BT9: =(($K9/30)*$M9)*$P9 -> 100 | BU9: =AC9 -> 0 | BV9: =AD9 -> 0 | BW9: =AE9 -> 0 | BX9: =AF9 -> 0 | BY9: =AQ9+AV9 -> 0 | BZ9: =(BS9+BV9+BX9+BY9)*0.1267 -> 63.35 | CA9: =SUM(BS9:BZ9)-BU9-BW9 -> 663.35 | CB9: =(($J9/30)*$M9)*$Q9 -> 0 | CC9: =(($K9/30)*$M9)*$Q9 -> 0 | CD9: =AG9 -> 0 | CE9: =AH9 -> 0 | CF9: =AI9 -> 0 | CG9: =AJ9 -> 0 | CH9: =AR9+AW9 -> 0 | CI9: =(CB9+CE9+CG9+CH9)*0.1267 -> 0 | CJ9: =SUM(CB9:CI9)-CD9-CF9 -> 0 | CK9: =(($J9/30)*$M9)*R9 -> 0 | CL9: =(($K9/30)*$M9)*$R9 -> 0 | CM9: =+AK9 -> 0 | CN9: =AL9 -> 0 | CO9: =AM9 -> 0 | CP9: =AN9 -> 0 | CQ9: =AS9+AX9 -> 0 | CR9: =(CK9+CN9+CP9)*0.1267 -> 0 | CS9: =SUM(CK9:CR9)-CM9-CO9 -> 0 | CU9: ECONACIONAL | CV9: =IF($CU9="PROQUIMA",$BA9+$BJ9+$BS9+$CB9+$CK9,0) -> 0 | CW9: =IF($CU9="PROQUIMA",$BB9+$BK9+$BT9+$CC9+$CL9,0) -> 0 | CX9: =IF($CU9="PROQUIMA",$BC9+$BL9+$BU9+$CD9+$CM9,0) -> 0 | CY9: =IF($CU9="PROQUIMA",$BD9+$BM9+$BV9+$CE9+$CN9,0) -> 0 | CZ9: =IF($CU9="PROQUIMA",$BE9+$BN9+$BW9+$CF9+$CO9,0) -> 0 | DA9: =IF($CU9="PROQUIMA",$BF9+$BO9+$BX9+$CG9+$CP9,0) -> 0 | DB9: =IF($CU9="PROQUIMA",$BG9+$BP9+$BY9+$CH9+$CQ9,0) -> 0 | DC9: =IF($CU9="PROQUIMA",$BH9+$BQ9+$BZ9+$CI9+CR9,0) -> 0 | DD9: =SUM(CV9:DC9)-CX9-CZ9 -> 0 | DE9: =IF($CU9="UNHESA",$BA9+$BJ9+$BS9+$CB9+$CK9,0) -> 0 | DF9: =IF($CU9="UNHESA",$BB9+$BK9+$BT9+$CC9+$CL9,0) -> 0 | DG9: =IF($CU9="UNHESA",$BC9+$BL9+$BU9+$CD9+$CM9,0) -> 0 | DH9: =IF($CU9="UNHESA",$BD9+$BM9+$BV9+$CE9+$CN9,0) -> 0 | DI9: =IF($CU9="UNHESA",$BE9+$BN9+$BW9+$CF9+$CO9,0) -> 0 | DJ9: =IF($CU9="UNHESA",$BF9+$BO9+$BX9+$CG9+$CP9,0) -> 0 | DK9: =IF($CU9="UNHESA",$BG9+$BP9+$BY9+$CH9+$CQ9,0) -> 0 | DL9: =IF($CU9="UNHESA",$BH9+$BQ9+$BZ9+$CI9+$CR9,0) -> 0 | DM9: =SUM(DE9:DL9)-DG9-DI9 -> 0 | DN9: =SUM(DF9:DM9)-DH9-DJ9 -> 0 | DO9: =SUM(DG9:DN9)-DI9-DK9 -> 0 | DP9: =SUM(DH9:DO9)-DJ9-DL9 -> 0 | DQ9: =SUM(DI9:DP9)-DK9-DM9 -> 0 | DR9: =SUM(DJ9:DQ9)-DL9-DN9 -> 0 | DS9: =SUM(DK9:DR9)-DM9-DO9 -> 0 | DT9: =SUM(DL9:DS9)-DN9-DP9 -> 0 | ... DV9: =SUM(DN9:DU9)-DP9-DR9 -> 0 | DW9: =IF($CU9="CLEARTEC",$BA9+$BJ9+$BS9+$CB9+$CK9,0) -> 0 | DX9: =IF($CU9="CLEARTEC",$BA9+$BJ9+$BS9+$CB9+$CK9,0) -> 0 | DY9: =IF($CU9="CLEARTEC",$BA9+$BJ9+$BS9+$CB9+$CK9,0) -> 0 | DZ9: =IF($CU9="CLEARTEC",$BA9+$BJ9+$BS9+$CB9+$CK9,0) -> 0 | EA9: =IF($CU9="CLEARTEC",$BA9+$BJ9+$BS9+$CB9+$CK9,0) -> 0 | EB9: =IF($CU9="CLEARTEC",$BA9+$BJ9+$BS9+$CB9+$CK9,0) -> 0 | EC9: =IF($CU9="CLEARTEC",$BA9+$BJ9+$BS9+$CB9+$CK9,0) -> 0 | ED9: =IF($CU9="CLEARTEC",$BA9+$BJ9+$BS9+$CB9+$CK9,0) -> 0 | EE9: =IF($CU9="CLEARTEC",$BA9+$BJ9+$BS9+$CB9+$CK9,0) -> 0 | EF9: =IF(CU9="ECONACIONAL",$BA9+$BJ9+$BS9+$CB9+$CK9) -> 5000 | EG9: =IF($CU9="ECONACIONAL",$BB9+$BK9+$BT9+$CC9+$CL9,0) -> 1000 | EH9: =IF(CU9="ECONACIONAL",$BC9+$BL9+$BU9+$CD9+$CM9) -> 0 | EI9: =IF(CU9="ECONACIONAL",$BD9+$DH9+$DQ9+$DZ9+BM9+BV9+CE9+CN9) -> 0 | EJ9: =IF($CU9="CLEARTEC",$BE9+$BN9+$BW9+$CF9+$CO9,0) -> 0 | EK9: =IF(CU9="ECONACIONAL",$BF9+$BO9+$BX9+$CG9+$CP9) -> 0 | EL9: =IF(CU9="ECONACIONAL",$BG9+$BP9+$BY9+$CH9+$CQ9) -> 0 | EM9: =IF(CU9="ECONACIONAL",BH9+BQ9+BZ9+CI9+CR9) -> 633.5 | EN9: =SUM(EF9:EM9)-EH9-EJ9 -> 6633.5 | EP9: 87.92 | ES9: =165+60 -> 225 | EV9: 350 | EY9: =+ET9+EU9+EV9 -> 350 | FA9: =IF($M9<=15,EP9/2,EP9) -> 87.92 | FB9: =IF($M9<=15,EQ9/2,EQ9) -> 0 | FC9: =IF($M9<=15,ER9/2,ER9) -> 0 | FD9: =IF($M9<=15,ES9/2,ES9) -> 225 | FE9: =IF($M9<=15,ET9/2,ET9) -> 0 | FF9: =IF($M9<=15,EU9/2,EU9) -> 0 | FG9: =IF($M9<=15,EV9/2,EV9) -> 350 | FH9: =IF($M9<=15,EW9/2,EW9) -> 0 | ... FJ9: =IF($M9<=15,EY9/2,EY9) -> 350 | FR9: =(((J9/30/8)*1.5)*(U9+Y9+AC9))-(BD9+BM9+BV9) -> 0 | FS9: =(((J9/30/8)*2)*(W9+AA9+AE9))-(BF9+BO9+BX9) -> 0 | FT9: =(SUM(BA9:CJ9))-(SUM(EF9:EN9)) -> 0 | FU9: =(J9/30*M9)-(EF9) -> 0 | FV9: =(SUM(EP9:EY9))-((SUM(FA9:FJ9))*$FV$5) -> -1012.92
A10: =$G$4 -> JUNIO 2026 2da QUINCENA | B10: =+$G$5 -> 2026 | C10: =A10 & B10 -> JUNIO 2026 2da QUINCENA2026 | D10: =+$G$8 -> ADMINISTRATIVO | E10: 102050 | F10: 2 | G10: Pu Canto Domingo | H10: Conserje | I10: ECONACIONAL | J10: 4002.28 | K10: 250 | L10: =+J10+K10 -> 4252.28 | M10: 30 | N10: 0.5 | O10: 0.5 | P10: 0 | Q10: 0 | R10: 0 | S10: =SUM(N10:R10) -> 1 | V10: =($J10/30/8*1.5)*U10 -> 0 | X10: =($J10/30/8*2)*W10 -> 0 | Z10: =($J10/30/8*1.5)*Y10 -> 0 | AB10: =($J10/30/8*2)*AA10 -> 0 | AD10: =(($J10/30/8)*1.5)*AC10 -> 0 | AF10: =(($J10/30/8)*2)*AE10 -> 0 | AH10: =(($J10/30/8)*1.5)*AG10 -> 0 | AJ10: =(($J10/30/8)*2)*AI10 -> 0 | AL10: =(($J10/30/8)*1.5)*AK10 -> 0 | AN10: =(($J10/30/8)*2)*AM10 -> 0 | BA10: =((J10/30)*M10)*$N10 -> 2001.14 | BB10: =((K10/30)*M10)*$N10 -> 125 | BC10: =U10 -> 0 | BD10: =V10 -> 0 | BE10: =W10 -> 0 | BF10: =X10 -> 0 | BG10: =AO10+AT10 -> 0 | BH10: =(BA10+BD10+BF10+BG10)*0.1267 -> 253.54444 | BI10: =SUM(BA10:BH10)-BC10-BE10 -> 2379.6844 | BJ10: =(($J10/30)*$M10)*$O10 -> 2001.14 | BK10: =(($K10/30)*$M10)*$O10 -> 125 | BL10: =Y10 -> 0 | BM10: =Z10 -> 0 | BN10: =AA10 -> 0 | BO10: =AB10 -> 0 | BP10: =AP10+AU10 -> 0 | BQ10: =(+BJ10+BM10+BO10+BP10)*0.1267 -> 253.54444 | BR10: =SUM(BJ10:BQ10)-BL10-BN10 -> 2379.6844 | BS10: =(($J10/30)*$M10)*$P10 -> 0 | BT10: =(($K10/30)*$M10)*$P10 -> 0 | BU10: =AC10 -> 0 | BV10: =AD10 -> 0 | BW10: =AE10 -> 0 | BX10: =AF10 -> 0 | BY10: =AQ10+AV10 -> 0 | BZ10: =(BS10+BV10+BX10)*0.09 -> 0 | CA10: =SUM(BS10:BZ10)-BU10-BW10 -> 0 | CB10: =(($J10/30)*$M10)*$Q10 -> 0 | CC10: =(($K10/30)*$M10)*$Q10 -> 0 | CD10: =AG10 -> 0 | CE10: =AH10 -> 0 | CF10: =AI10 -> 0 | CG10: =AJ10 -> 0 | CH10: =AR10+AW10 -> 0 | CI10: =(CB10+CE10+CG10)*0.09 -> 0 | CJ10: =SUM(CB10:CI10)-CD10-CF10 -> 0 | CK10: =(($J10/30)*$M10)*R10 -> 0 | CL10: =(($K10/30)*$M10)*$R10 -> 0 | CM10: =+AK10 -> 0 | CN10: =AL10 -> 0 | CO10: =AM10 -> 0 | CP10: =AN10 -> 0 | CQ10: =AS10+AX10 -> 0 | CR10: =(CK10+CN10+CP10)*0.09 -> 0 | CS10: =SUM(CK10:CR10)-CM10-CO10 -> 0 | CU10: ECONACIONAL | CV10: =IF($CU10="PROQUIMA",$BA10+$BJ10+$BS10+$CB10+$CK10,0) -> 0 | CW10: =IF($CU10="PROQUIMA",$BB10+$BK10+$BT10+$CC10+$CL10,0) -> 0 | CX10: =IF($CU10="PROQUIMA",$BC10+$BL10+$BU10+$CD10+$CM10,0) -> 0 | CY10: =IF($CU10="PROQUIMA",$BD10+$BM10+$BV10+$CE10+$CN10,0) -> 0 | CZ10: =IF($CU10="PROQUIMA",$BE10+$BN10+$BW10+$CF10+$CO10,0) -> 0 | DA10: =IF($CU10="PROQUIMA",$BF10+$BO10+$BX10+$CG10+$CP10,0) -> 0 | DB10: =IF($CU10="PROQUIMA",$BG10+$BP10+$BY10+$CH10+$CQ10,0) -> 0 | DC10: =IF($CU10="PROQUIMA",$BH10+$BQ10+$BZ10+$CI10+CR10,0) -> 0 | DD10: =SUM(CV10:DC10)-CX10-CZ10 -> 0 | DE10: =IF($CU10="UNHESA",$BA10+$BJ10+$BS10+$CB10+$CK10,0) -> 0 | DF10: =IF($CU10="UNHESA",$BB10+$BK10+$BT10+$CC10+$CL10,0) -> 0 | DG10: =IF($CU10="UNHESA",$BC10+$BL10+$BU10+$CD10+$CM10,0) -> 0 | DH10: =IF($CU10="UNHESA",$BD10+$BM10+$BV10+$CE10+$CN10,0) -> 0 | DI10: =IF($CU10="UNHESA",$BE10+$BN10+$BW10+$CF10+$CO10,0) -> 0 | DJ10: =IF($CU10="UNHESA",$BF10+$BO10+$BX10+$CG10+$CP10,0) -> 0 | DK10: =IF($CU10="UNHESA",$BG10+$BP10+$BY10+$CH10+$CQ10,0) -> 0 | DL10: =IF($CU10="UNHESA",$BH10+$BQ10+$BZ10+$CI10+$CR10,0) -> 0 | DM10: =SUM(DE10:DL10)-DG10-DI10 -> 0 | DN10: =IF($CU10="UNHESA LIQUIDOS",$BA10+$BJ10+$BS10+$CB10+$CK10,0) -> 0 | DO10: =IF($CU10="CALIDUL",$BB10+$BK10+$BT10+$CC10+$CL10,0) -> 0 | DP10: =IF($CU10="CALIDUL",$BC10+$BL10+$BU10+$CD10+$CM10,0) -> 0 | DQ10: =IF($CU10="CALIDUL",$BD10+$BM10+$BV10+$CE10+$CN10,0) -> 0 | DR10: =IF($CU10="CALIDUL",$BE10+$BN10+$BW10+$CF10+$CO10,0) -> 0 | DS10: =IF($CU10="CALIDUL",$BF10+$BO10+$BX10+$CG10+$CP10,0) -> 0 | DT10: =IF($CU10="CALIDUL",$BG10+$BP10+$BY10+$CH10+$CQ10,0) -> 0 | DU10: =IF($CU10="CALIDUL",$BH10+$BQ10+$BZ10+$CI10+$CR10,0) -> 0 | DV10: =SUM(DN10:DU10)-DP10-DR10 -> 0 | DW10: =IF($CU10="CLEARTEC",$BA10+$BJ10+$BS10+$CB10+$CK10,0) -> 0 | DX10: =IF($CU10="CLEARTEC",$BA10+$BJ10+$BS10+$CB10+$CK10,0) -> 0 | DY10: =IF($CU10="CLEARTEC",$BA10+$BJ10+$BS10+$CB10+$CK10,0) -> 0 | DZ10: =IF($CU10="CLEARTEC",$BA10+$BJ10+$BS10+$CB10+$CK10,0) -> 0 | EA10: =IF($CU10="CLEARTEC",$BA10+$BJ10+$BS10+$CB10+$CK10,0) -> 0 | EB10: =IF($CU10="CLEARTEC",$BA10+$BJ10+$BS10+$CB10+$CK10,0) -> 0 | EC10: =IF($CU10="CLEARTEC",$BA10+$BJ10+$BS10+$CB10+$CK10,0) -> 0 | ED10: =IF($CU10="CLEARTEC",$BA10+$BJ10+$BS10+$CB10+$CK10,0) -> 0 | EE10: =IF($CU10="CLEARTEC",$BA10+$BJ10+$BS10+$CB10+$CK10,0) -> 0 | EF10: =IF(CU10="ECONACIONAL",$BA10+$BJ10+$BS10+$CB10+$CK10) -> 4002.28 | EG10: =IF($CU10="ECONACIONAL",$BB10+$BK10+$BT10+$CC10+$CL10,0) -> 250 | EH10: =IF(CU10="ECONACIONAL",$BC10+$BL10+$BU10+$CD10+$CM10) -> 0 | EI10: =IF(CU10="ECONACIONAL",$BD10+$DH10+$DQ10+$DZ10+BM10+BV10+CE10+CN10) -> 0 | EJ10: =IF($CU10="CLEARTEC",$BE10+$BN10+$BW10+$CF10+$CO10,0) -> 0 | EK10: =IF(CU10="ECONACIONAL",$BF10+$BO10+$BX10+$CG10+$CP10) -> 0 | EL10: =IF(CU10="ECONACIONAL",$BG10+$BP10+$BY10+$CH10+$CQ10) -> 0 | EM10: =IF(CU10="ECONACIONAL",BH10+BQ10+BZ10+CI10+CR10) -> 507.08888 | EN10: =SUM(EF10:EM10)-EH10-EJ10 -> 4759.3689 | EY10: =+ET10+EU10+EV10 -> 0 | FA10: =IF($M10<=15,EP10/2,EP10) -> 0 | FB10: =IF($M10<=15,EQ10/2,EQ10) -> 0 | FC10: =IF($M10<=15,ER10/2,ER10) -> 0 | FD10: =IF($M10<=15,ES10/2,ES10) -> 0 | FE10: =IF($M10<=15,ET10/2,ET10) -> 0 | FF10: =IF($M10<=15,EU10/2,EU10) -> 0 | FG10: =IF($M10<=15,EV10/2,EV10) -> 0 | FH10: =IF($M10<=15,EW10/2,EW10) -> 0 | ... FJ10: =IF($M10<=15,EY10/2,EY10) -> 0 | FK10: 0.5 | FL10: 0.5 | FM10: 0 | FN10: 0 | FO10: 0 | FP10: 1 | FR10: =(((J10/30/8)*1.5)*(U10+Y10+AC10))-(BD10+BM10+BV10) -> 0 | FS10: =(((J10/30/8)*2)*(W10+AA10+AE10))-(BF10+BO10+BX10) -> 0 | FT10: =(SUM(BA10:CJ10))-(SUM(EF10:EN10)) -> 0 | FU10: =(J10/30*M10)-(EF10) -> 0 | FV10: =(SUM(EP10:EY10))-((SUM(FA10:FJ10))*$FV$5) -> 0
E11: 102050 | G11: Choc Abrego Enma Leticia | H11: Conserje | I11: ECONACIONAL | J11: 4002.28 | K11: 250 | L11: =+J11+K11 -> 4252.28 | M11: 30 | N11: 0.5 | O11: 0.4 | P11: 0.1 | Q11: 0 | R11: 0 | S11: =SUM(N11:R11) -> 1 | T11: A.23/3 | V11: =($J11/30/8*1.5)*U11 -> 0 | X11: =($J11/30/8*2)*W11 -> 0 | Z11: =($J11/30/8*1.5)*Y11 -> 0 | AB11: =($J11/30/8*2)*AA11 -> 0 | AD11: =(($J11/30/8)*1.5)*AC11 -> 0 | AF11: =(($J11/30/8)*2)*AE11 -> 0 | AH11: =(($J11/30/8)*1.5)*AG11 -> 0 | AJ11: =(($J11/30/8)*2)*AI11 -> 0 | AL11: =(($J11/30/8)*1.5)*AK11 -> 0 | AN11: =(($J11/30/8)*2)*AM11 -> 0 | BA11: =((J11/30)*M11)*$N11 -> 2001.14 | BB11: =((K11/30)*M11)*$N11 -> 125 | BC11: =U11 -> 0 | BD11: =V11 -> 0 | BE11: =W11 -> 0 | BF11: =X11 -> 0 | BG11: =AO11+AT11 -> 0 | BH11: =(BA11+BD11+BF11+BG11)*0.1267 -> 253.54444 | BI11: =SUM(BA11:BH11)-BC11-BE11 -> 2379.6844 | BJ11: =(($J11/30)*$M11)*$O11 -> 1600.912 | BK11: =(($K11/30)*$M11)*$O11 -> 100 | BL11: =Y11 -> 0 | BM11: =Z11 -> 0 | BN11: =AA11 -> 0 | BO11: =AB11 -> 0 | BP11: =AP11+AU11 -> 0 | BQ11: =(+BJ11+BM11+BO11+BP11)*0.1267 -> 202.83555 | BR11: =SUM(BJ11:BQ11)-BL11-BN11 -> 1903.7476 | BS11: =(($J11/30)*$M11)*$P11 -> 400.228 | BT11: =(($K11/30)*$M11)*$P11 -> 25 | BU11: =AC11 -> 0 | BV11: =AD11 -> 0 | BW11: =AE11 -> 0 | BX11: =AF11 -> 0 | BY11: =AQ11+AV11 -> 0 | BZ11: =(BS11+BV11+BX11)*0.09 -> 36.02052 | CA11: =SUM(BS11:BZ11)-BU11-BW11 -> 461.24852 | CB11: =(($J11/30)*$M11)*$Q11 -> 0 | CC11: =(($K11/30)*$M11)*$Q11 -> 0 | CD11: =AG11 -> 0 | CE11: =AH11 -> 0 | CF11: =AI11 -> 0 | CG11: =AJ11 -> 0 | CH11: =AR11+AW11 -> 0 | CI11: =(CB11+CE11+CG11)*0.09 -> 0 | CJ11: =SUM(CB11:CI11)-CD11-CF11 -> 0 | CK11: =(($J11/30)*$M11)*R11 -> 0 | CL11: =(($K11/30)*$M11)*$R11 -> 0 | CM11: =+AK11 -> 0 | CN11: =AL11 -> 0 | CO11: =AM11 -> 0 | CP11: =AN11 -> 0 | CQ11: =AS11+AX11 -> 0 | CR11: =(CK11+CN11+CP11)*0.09 -> 0 | CS11: =SUM(CK11:CR11)-CM11-CO11 -> 0 | CU11: ECONACIONAL | CV11: =IF($CU11="PROQUIMA",$BA11+$BJ11+$BS11+$CB11+$CK11,0) -> 0 | CW11: =IF($CU11="PROQUIMA",$BB11+$BK11+$BT11+$CC11+$CL11,0) -> 0 | CX11: =IF($CU11="PROQUIMA",$BC11+$BL11+$BU11+$CD11+$CM11,0) -> 0 | CY11: =IF($CU11="PROQUIMA",$BD11+$BM11+$BV11+$CE11+$CN11,0) -> 0 | CZ11: =IF($CU11="PROQUIMA",$BE11+$BN11+$BW11+$CF11+$CO11,0) -> 0 | DA11: =IF($CU11="PROQUIMA",$BF11+$BO11+$BX11+$CG11+$CP11,0) -> 0 | DB11: =IF($CU11="PROQUIMA",$BG11+$BP11+$BY11+$CH11+$CQ11,0) -> 0 | DC11: =IF($CU11="PROQUIMA",$BH11+$BQ11+$BZ11+$CI11+CR11,0) -> 0 | DD11: =SUM(CV11:DC11)-CX11-CZ11 -> 0 | DE11: =IF($CU11="UNHESA",$BA11+$BJ11+$BS11+$CB11+$CK11,0) -> 0 | DF11: =IF($CU11="UNHESA",$BB11+$BK11+$BT11+$CC11+$CL11,0) -> 0 | DG11: =IF($CU11="UNHESA",$BC11+$BL11+$BU11+$CD11+$CM11,0) -> 0 | DH11: =IF($CU11="UNHESA",$BD11+$BM11+$BV11+$CE11+$CN11,0) -> 0 | DI11: =IF($CU11="UNHESA",$BE11+$BN11+$BW11+$CF11+$CO11,0) -> 0 | DJ11: =IF($CU11="UNHESA",$BF11+$BO11+$BX11+$CG11+$CP11,0) -> 0 | DK11: =IF($CU11="UNHESA",$BG11+$BP11+$BY11+$CH11+$CQ11,0) -> 0 | DL11: =IF($CU11="UNHESA",$BH11+$BQ11+$BZ11+$CI11+$CR11,0) -> 0 | DM11: =SUM(DE11:DL11)-DG11-DI11 -> 0 | DN11: =IF($CU11="UNHESA LIQUIDOS",$BA11+$BJ11+$BS11+$CB11+$CK11,0) -> 0 | DO11: =IF($CU11="CALIDUL",$BB11+$BK11+$BT11+$CC11+$CL11,0) -> 0 | DP11: =IF($CU11="CALIDUL",$BC11+$BL11+$BU11+$CD11+$CM11,0) -> 0 | DQ11: =IF($CU11="CALIDUL",$BD11+$BM11+$BV11+$CE11+$CN11,0) -> 0 | DR11: =IF($CU11="CALIDUL",$BE11+$BN11+$BW11+$CF11+$CO11,0) -> 0 | DS11: =IF($CU11="CALIDUL",$BF11+$BO11+$BX11+$CG11+$CP11,0) -> 0 | DT11: =IF($CU11="CALIDUL",$BG11+$BP11+$BY11+$CH11+$CQ11,0) -> 0 | DU11: =IF($CU11="CALIDUL",$BH11+$BQ11+$BZ11+$CI11+$CR11,0) -> 0 | DV11: =SUM(DN11:DU11)-DP11-DR11 -> 0 | DW11: =IF($CU11="CLEARTEC",$BA11+$BJ11+$BS11+$CB11+$CK11,0) -> 0 | DX11: =IF($CU11="CLEARTEC",$BA11+$BJ11+$BS11+$CB11+$CK11,0) -> 0 | DY11: =IF($CU11="CLEARTEC",$BA11+$BJ11+$BS11+$CB11+$CK11,0) -> 0 | DZ11: =IF($CU11="CLEARTEC",$BA11+$BJ11+$BS11+$CB11+$CK11,0) -> 0 | EA11: =IF($CU11="CLEARTEC",$BA11+$BJ11+$BS11+$CB11+$CK11,0) -> 0 | EB11: =IF($CU11="CLEARTEC",$BA11+$BJ11+$BS11+$CB11+$CK11,0) -> 0 | EC11: =IF($CU11="CLEARTEC",$BA11+$BJ11+$BS11+$CB11+$CK11,0) -> 0 | ED11: =IF($CU11="CLEARTEC",$BA11+$BJ11+$BS11+$CB11+$CK11,0) -> 0 | EE11: =IF($CU11="CLEARTEC",$BA11+$BJ11+$BS11+$CB11+$CK11,0) -> 0 | EF11: =IF(CU11="ECONACIONAL",$BA11+$BJ11+$BS11+$CB11+$CK11) -> 4002.28 | EG11: =IF($CU11="ECONACIONAL",$BB11+$BK11+$BT11+$CC11+$CL11,0) -> 250 | EH11: =IF(CU11="ECONACIONAL",$BC11+$BL11+$BU11+$CD11+$CM11) -> 0 | EI11: =IF(CU11="ECONACIONAL",$BD11+$DH11+$DQ11+$DZ11+BM11+BV11+CE11+CN11) -> 0 | EJ11: =IF($CU11="CLEARTEC",$BE11+$BN11+$BW11+$CF11+$CO11,0) -> 0 | EK11: =IF(CU11="ECONACIONAL",$BF11+$BO11+$BX11+$CG11+$CP11) -> 0 | EL11: =IF(CU11="ECONACIONAL",$BG11+$BP11+$BY11+$CH11+$CQ11) -> 0 | EM11: =IF(CU11="ECONACIONAL",BH11+BQ11+BZ11+CI11+CR11) -> 492.40051 | EN11: =SUM(EF11:EM11)-EH11-EJ11 -> 4744.6805 | EY11: =+ET11+EU11+EV11 -> 0 | FA11: =IF($M11<=15,EP11/2,EP11) -> 0 | FB11: =IF($M11<=15,EQ11/2,EQ11) -> 0 | FC11: =IF($M11<=15,ER11/2,ER11) -> 0 | FD11: =IF($M11<=15,ES11/2,ES11) -> 0 | FE11: =IF($M11<=15,ET11/2,ET11) -> 0 | FF11: =IF($M11<=15,EU11/2,EU11) -> 0 | FG11: =IF($M11<=15,EV11/2,EV11) -> 0 | FH11: =IF($M11<=15,EW11/2,EW11) -> 0 | ... FJ11: =IF($M11<=15,EY11/2,EY11) -> 0 | FK11: 0.5 | FL11: 0.5 | FM11: 0 | FN11: 0 | FO11: 0 | FP11: 1 | FR11: =(((J11/30/8)*1.5)*(U11+Y11+AC11))-(BD11+BM11+BV11) -> 0 | FS11: =(((J11/30/8)*2)*(W11+AA11+AE11))-(BF11+BO11+BX11) -> 0 | FT11: =(SUM(BA11:CJ11))-(SUM(EF11:EN11)) -> 0 | FU11: =(J11/30*M11)-(EF11) -> 0 | FV11: =(SUM(EP11:EY11))-((SUM(FA11:FJ11))*$FV$5) -> 0
H12: Administrativo | J12: =SUM(J9:J11) -> 13004.56 | K12: =SUM(K9:K11) -> 1500 | L12: =SUM(L9:L11) -> 14504.56 | T12: =SUM(T9:T11) -> 0 | U12: =SUM(U9:U11) -> 0 | V12: =SUM(V9:V11) -> 0 | W12: =SUM(W9:W11) -> 0 | X12: =SUM(X9:X11) -> 0 | Y12: =SUM(Y9:Y11) -> 0 | Z12: =SUM(Z9:Z11) -> 0 | AA12: =SUM(AA9:AA11) -> 0 | ... EN12: =SUM(EN9:EN11) -> 16137.549 | EP12: =SUM(EP9:EP11) -> 87.92 | EQ12: =SUM(EQ9:EQ11) -> 0 | ER12: =SUM(ER9:ER11) -> 0 | ES12: =SUM(ES9:ES11) -> 225 | ET12: =SUM(ET9:ET11) -> 0 | EU12: =SUM(EU9:EU11) -> 0 | EV12: =SUM(EV9:EV11) -> 350 | EW12: =SUM(EW9:EW11) -> 0 | ... EY12: =SUM(EY9:EY11) -> 350 | FA12: =SUM(FA9:FA11) -> 87.92 | FB12: =SUM(FB9:FB11) -> 0 | FC12: =SUM(FC9:FC11) -> 0 | FD12: =SUM(FD9:FD11) -> 225 | FE12: =SUM(FE9:FE11) -> 0 | FF12: =SUM(FF9:FF11) -> 0 | FG12: =SUM(FG9:FG11) -> 350 | FH12: =SUM(FH9:FH11) -> 0 | ... FP12: =SUM(FP9:FP11) -> 2
A13: =$G$4 -> JUNIO 2026 2da QUINCENA | B13: =+$G$5 -> 2026 | C13: =A13 & B13 -> JUNIO 2026 2da QUINCENA2026 | D13: =+$G$8 -> ADMINISTRATIVO | E13: 102030 | G13: RECEPCION
C15: =A15 & B15 | H15: Recepción | J15: =SUM(J14:J14) -> 0 | K15: =SUM(K14:K14) -> 0 | L15: =SUM(L14:L14) -> 0 | U15: =SUM(U14:U14) -> 0 | V15: =SUM(V14:V14) -> 0 | W15: =SUM(W14:W14) -> 0 | X15: =SUM(X14:X14) -> 0 | Y15: =SUM(Y14:Y14) -> 0 | Z15: =SUM(Z14:Z14) -> 0 | AA15: =SUM(AA14:AA14) -> 0 | AB15: =SUM(AB14:AB14) -> 0 | ... FP15: =SUM(FP14:FP14) -> 0
A16: =$G$4 -> JUNIO 2026 2da QUINCENA | B16: =+$G$5 -> 2026 | C16: =A16 & B16 -> JUNIO 2026 2da QUINCENA2026 | D16: =+G16 -> MENSAJERIA | E16: 102020 | G16: MENSAJERIA
E17: 102020 | G17: Julaj Ixcotoyac Angel Estuardo | H17: Mensajero | I17: ECONACIONAL | J17: 4002.28 | K17: 370 | L17: =+J17+K17 -> 4372.28 | M17: 9 | N17: 0.5 | O17: 0.3 | P17: 0.2 | Q17: 0 | R17: 0 | S17: =SUM(N17:R17) -> 1 | T17: A.23/3 | V17: =($J17/30/8*1.5)*U17 -> 0 | X17: =($J17/30/8*2)*W17 -> 0 | Z17: =($J17/30/8*1.5)*Y17 -> 0 | AB17: =($J17/30/8*2)*AA17 -> 0 | AD17: =(($J17/30/8)*1.5)*AC17 -> 0 | AF17: =(($J17/30/8)*2)*AE17 -> 0 | AH17: =(($J17/30/8)*1.5)*AG17 -> 0 | AJ17: =(($J17/30/8)*2)*AI17 -> 0 | AL17: =(($J17/30/8)*1.5)*AK17 -> 0 | AN17: =(($J17/30/8)*2)*AM17 -> 0 | BA17: =((J17/30)*M17)*$N17 -> 600.342 | BB17: =((K17/30)*M17)*$N17 -> 55.5 | BC17: =U17 -> 0 | BD17: =V17 -> 0 | BE17: =W17 -> 0 | BF17: =X17 -> 0 | BG17: =AO17+AT17 -> 0 | BH17: =(BA17+BD17+BF17+BG17)*0.1267 -> 76.063331 | BI17: =SUM(BA17:BH17)-BC17-BE17 -> 731.90533 | BJ17: =(($J17/30)*$M17)*$O17 -> 360.2052 | BK17: =(($K17/30)*$M17)*$O17 -> 33.3 | BL17: =Y17 -> 0 | BM17: =Z17 -> 0 | BN17: =AA17 -> 0 | BO17: =AB17 -> 0 | BP17: =AP17+AU17 -> 0 | BQ17: =(+BJ17+BM17+BO17+BP17)*0.1267 -> 45.637999 | BR17: =SUM(BJ17:BQ17)-BL17-BN17 -> 439.1432 | BS17: =(($J17/30)*$M17)*$P17 -> 240.1368 | BT17: =(($K17/30)*$M17)*$P17 -> 22.2 | BU17: =AC17 -> 0 | BV17: =AD17 -> 0 | BW17: =AE17 -> 0 | BX17: =AF17 -> 0 | BY17: =AQ17+AV17 -> 0 | BZ17: =(BS17+BV17+BX17)*0.09 -> 21.612312 | CA17: =SUM(BS17:BZ17)-BU17-BW17 -> 283.94911 | CB17: =(($J17/30)*$M17)*$Q17 -> 0 | CC17: =(($K17/30)*$M17)*$Q17 -> 0 | CD17: =AG17 -> 0 | CE17: =AH17 -> 0 | CF17: =AI17 -> 0 | CG17: =AJ17 -> 0 | CH17: =AR17+AW17 -> 0 | CI17: =(CB17+CE17+CG17)*0.09 -> 0 | CJ17: =SUM(CB17:CI17)-CD17-CF17 -> 0 | CK17: =(($J17/30)*$M17)*R17 -> 0 | CL17: =(($K17/30)*$M17)*$R17 -> 0 | CM17: =+AK17 -> 0 | CN17: =AL17 -> 0 | CO17: =AM17 -> 0 | CP17: =AN17 -> 0 | CQ17: =AS17+AX17 -> 0 | CR17: =(CK17+CN17+CP17)*0.09 -> 0 | CS17: =SUM(CK17:CR17)-CM17-CO17 -> 0 | CU17: ECONACIONAL | CV17: =IF($CU17="PROQUIMA",$BA17+$BJ17+$BS17+$CB17+$CK17,0) -> 0 | CW17: =IF($CU17="PROQUIMA",$BB17+$BK17+$BT17+$CC17+$CL17,0) -> 0 | CX17: =IF($CU17="PROQUIMA",$BC17+$BL17+$BU17+$CD17+$CM17,0) -> 0 | CY17: =IF($CU17="PROQUIMA",$BD17+$BM17+$BV17+$CE17+$CN17,0) -> 0 | CZ17: =IF($CU17="PROQUIMA",$BE17+$BN17+$BW17+$CF17+$CO17,0) -> 0 | DA17: =IF($CU17="PROQUIMA",$BF17+$BO17+$BX17+$CG17+$CP17,0) -> 0 | DB17: =IF($CU17="PROQUIMA",$BG17+$BP17+$BY17+$CH17+$CQ17,0) -> 0 | DC17: =IF($CU17="PROQUIMA",$BH17+$BQ17+$BZ17+$CI17+CR17,0) -> 0 | DD17: =SUM(CV17:DC17)-CX17-CZ17 -> 0 | DE17: =IF($CU17="UNHESA",$BA17+$BJ17+$BS17+$CB17+$CK17,0) -> 0 | DF17: =IF($CU17="UNHESA",$BB17+$BK17+$BT17+$CC17+$CL17,0) -> 0 | DG17: =IF($CU17="UNHESA",$BC17+$BL17+$BU17+$CD17+$CM17,0) -> 0 | DH17: =IF($CU17="UNHESA",$BD17+$BM17+$BV17+$CE17+$CN17,0) -> 0 | DI17: =IF($CU17="UNHESA",$BE17+$BN17+$BW17+$CF17+$CO17,0) -> 0 | DJ17: =IF($CU17="UNHESA",$BF17+$BO17+$BX17+$CG17+$CP17,0) -> 0 | DK17: =IF($CU17="UNHESA",$BG17+$BP17+$BY17+$CH17+$CQ17,0) -> 0 | DL17: =IF($CU17="UNHESA",$BH17+$BQ17+$BZ17+$CI17+$CR17,0) -> 0 | DM17: =SUM(DE17:DL17)-DG17-DI17 -> 0 | DN17: =IF($CU17="UNHESA LIQUIDOS",$BA17+$BJ17+$BS17+$CB17+$CK17,0) -> 0 | DO17: =IF($CU17="CALIDUL",$BB17+$BK17+$BT17+$CC17+$CL17,0) -> 0 | DP17: =IF($CU17="CALIDUL",$BC17+$BL17+$BU17+$CD17+$CM17,0) -> 0 | DQ17: =IF($CU17="CALIDUL",$BD17+$BM17+$BV17+$CE17+$CN17,0) -> 0 | DR17: =IF($CU17="CALIDUL",$BE17+$BN17+$BW17+$CF17+$CO17,0) -> 0 | DS17: =IF($CU17="CALIDUL",$BF17+$BO17+$BX17+$CG17+$CP17,0) -> 0 | DT17: =IF($CU17="CALIDUL",$BG17+$BP17+$BY17+$CH17+$CQ17,0) -> 0 | DU17: =IF($CU17="CALIDUL",$BH17+$BQ17+$BZ17+$CI17+$CR17,0) -> 0 | DV17: =SUM(DN17:DU17)-DP17-DR17 -> 0 | DW17: =IF($CU17="CLEARTEC",$BA17+$BJ17+$BS17+$CB17+$CK17,0) -> 0 | DX17: =IF($CU17="CLEARTEC",$BA17+$BJ17+$BS17+$CB17+$CK17,0) -> 0 | DY17: =IF($CU17="CLEARTEC",$BA17+$BJ17+$BS17+$CB17+$CK17,0) -> 0 | DZ17: =IF($CU17="CLEARTEC",$BA17+$BJ17+$BS17+$CB17+$CK17,0) -> 0 | EA17: =IF($CU17="CLEARTEC",$BA17+$BJ17+$BS17+$CB17+$CK17,0) -> 0 | EB17: =IF($CU17="CLEARTEC",$BA17+$BJ17+$BS17+$CB17+$CK17,0) -> 0 | EC17: =IF($CU17="CLEARTEC",$BA17+$BJ17+$BS17+$CB17+$CK17,0) -> 0 | ED17: =IF($CU17="CLEARTEC",$BA17+$BJ17+$BS17+$CB17+$CK17,0) -> 0 | EE17: =IF($CU17="CLEARTEC",$BA17+$BJ17+$BS17+$CB17+$CK17,0) -> 0 | EF17: =IF(CU17="ECONACIONAL",$BA17+$BJ17+$BS17+$CB17+$CK17) -> 1200.684 | EG17: =IF($CU17="ECONACIONAL",$BB17+$BK17+$BT17+$CC17+$CL17,0) -> 111 | EH17: =IF(CU17="ECONACIONAL",$BC17+$BL17+$BU17+$CD17+$CM17) -> 0 | EI17: =IF(CU17="ECONACIONAL",$BD17+$DH17+$DQ17+$DZ17+BM17+BV17+CE17+CN17) -> 0 | EJ17: =IF($CU17="CLEARTEC",$BE17+$BN17+$BW17+$CF17+$CO17,0) -> 0 | EK17: =IF(CU17="ECONACIONAL",$BF17+$BO17+$BX17+$CG17+$CP17) -> 0 | EL17: =IF(CU17="ECONACIONAL",$BG17+$BP17+$BY17+$CH17+$CQ17) -> 0 | EM17: =IF(CU17="ECONACIONAL",BH17+BQ17+BZ17+CI17+CR17) -> 143.31364 | EN17: =SUM(EF17:EM17)-EH17-EJ17 -> 1454.9976 | EY17: =+ET17+EU17+EV17 -> 0 | FA17: =IF($M17<=15,EP17/2,EP17) -> 0 | FB17: =IF($M17<=15,EQ17/2,EQ17) -> 0 | FC17: =IF($M17<=15,ER17/2,ER17) -> 0 | FD17: =IF($M17<=15,ES17/2,ES17) -> 0 | FE17: =IF($M17<=15,ET17/2,ET17) -> 0 | FF17: =IF($M17<=15,EU17/2,EU17) -> 0 | FG17: =IF($M17<=15,EV17/2,EV17) -> 0 | FH17: =IF($M17<=15,EW17/2,EW17) -> 0 | ... FJ17: =IF($M17<=15,EY17/2,EY17) -> 0 | FK17: 0.5 | FL17: 0.5 | FM17: 0 | FN17: 0 | FO17: 0 | FP17: 1 | FR17: =(((J17/30/8)*1.5)*(U17+Y17+AC17))-(BD17+BM17+BV17) -> 0 | FS17: =(((J17/30/8)*2)*(W17+AA17+AE17))-(BF17+BO17+BX17) -> 0 | FT17: =(SUM(BA17:CJ17))-(SUM(EF17:EN17)) -> 0 | FU17: =(J17/30*M17)-(EF17) -> 0 | FV17: =(SUM(EP17:EY17))-((SUM(FA17:FJ17))*$FV$5) -> 0
H18: Total | J18: =+J17 -> 4002.28 | K18: =+K17 -> 370 | L18: =+L17 -> 4372.28 | U18: =+U17 -> 0 | V18: =+V17 -> 0 | W18: =+W17 -> 0 | X18: =+X17 -> 0 | Y18: =+Y17 -> 0 | Z18: =+Z17 -> 0 | AA18: =+AA17 -> 0 | AB18: =+AB17 -> 0 | ... AZ18: =+AZ17 -> 0 | BA18: =SUM(BA17) -> 600.342 | BB18: =SUM(BB17) -> 55.5 | BC18: =SUM(BC17) -> 0 | BD18: =SUM(BD17) -> 0 | BE18: =SUM(BE17) -> 0 | BF18: =SUM(BF17) -> 0 | BG18: =SUM(BG17) -> 0 | BH18: =SUM(BH17) -> 76.063331 | ... CS18: =SUM(CS17) -> 0 | CT18: =+CT17 -> 0 | CU18: =+CU17 -> ECONACIONAL | CV18: =+CV17 -> 0 | CW18: =+CW17 -> 0 | CX18: =+CX17 -> 0 | CY18: =+CY17 -> 0 | CZ18: =+CZ17 -> 0 | DA18: =+DA17 -> 0 | ... EN18: =+EN17 -> 1454.9976 | EP18: =+EP17 -> 0 | EQ18: =+EQ17 -> 0 | ER18: =+ER17 -> 0 | ES18: =+ES17 -> 0 | ET18: =+ET17 -> 0 | EU18: =+EU17 -> 0 | EV18: =+EV17 -> 0 | EW18: =+EW17 -> 0 | ... EY18: =+EY17 -> 0 | FA18: =+FA17 -> 0 | FB18: =+FB17 -> 0 | FC18: =+FC17 -> 0 | FD18: =+FD17 -> 0 | FE18: =+FE17 -> 0 | FF18: =+FF17 -> 0 | FG18: =+FG17 -> 0 | FH18: =+FH17 -> 0 | ... FJ18: =+FJ17 -> 0
H19: Total Administrativo | J19: =+J12+J15+J18 -> 17006.84 | K19: =+K12+K15+K18 -> 1870 | L19: =+L12+L15+L18 -> 18876.84 | U19: =+U12+U15+U18 -> 0 | V19: =+V12+V15+V18 -> 0 | W19: =+W12+W15+W18 -> 0 | X19: =+X12+X15+X18 -> 0 | Y19: =+Y12+Y15+Y18 -> 0 | Z19: =+Z12+Z15+Z18 -> 0 | AA19: =+AA12+AA15+AA18 -> 0 | AB19: =+AB12+AB15+AB18 -> 0 | ... EN19: =+EN12+EN15+EN18 -> 17592.547 | EP19: =+EP12+EP15+EP18 -> 87.92 | EQ19: =+EQ12+EQ15+EQ18 -> 0 | ER19: =+ER12+ER15+ER18 -> 0 | ES19: =+ES12+ES15+ES18 -> 225 | ET19: =+ET12+ET15+ET18 -> 0 | EU19: =+EU12+EU15+EU18 -> 0 | EV19: =+EV12+EV15+EV18 -> 350 | EW19: =+EW12+EW15+EW18 -> 0 | ... EY19: =+EY12+EY15+EY18 -> 350 | FA19: =+FA12+FA15+FA18 -> 87.92 | FB19: =+FB12+FB15+FB18 -> 0 | FC19: =+FC12+FC15+FC18 -> 0 | FD19: =+FD12+FD15+FD18 -> 225 | FE19: =+FE12+FE15+FE18 -> 0 | FF19: =+FF12+FF15+FF18 -> 0 | FG19: =+FG12+FG15+FG18 -> 350 | FH19: =+FH12+FH15+FH18 -> 0 | ... FP19: =+FP12+FP15+FP18 -> 2
E20: 103010 | G20: RECURSOS HUMANOS
A21: =$G$4 -> JUNIO 2026 2da QUINCENA | B21: =+$G$5 -> 2026 | C21: =A21 & B21 -> JUNIO 2026 2da QUINCENA2026 | D21: =+$G$20 -> RECURSOS HUMANOS | E21: 103010 | G21: Administracion
A22: =$G$4 -> JUNIO 2026 2da QUINCENA | B22: =+$G$5 -> 2026 | C22: =A22 & B22 -> JUNIO 2026 2da QUINCENA2026 | D22: =+$G$20 -> RECURSOS HUMANOS | E22: 103010 | F22: =F17+1 -> 1 | G22: Hernandez de Lemus Iris Carolina | H22: Jefe de Recursos Humanos | I22: ECONACIONAL | J22: 9150 | K22: 4500 | L22: =+J22+K22 -> 13650 | M22: 30 | N22: 0.4 | O22: 0.35 | P22: 0.05 | Q22: 0.2 | R22: 0 | S22: =SUM(N22:R22) -> 1 | V22: =($J22/30/8*1.5)*U22 -> 0 | X22: =($J22/30/8*2)*W22 -> 0 | Z22: =($J22/30/8*1.5)*Y22 -> 0 | AB22: =($J22/30/8*2)*AA22 -> 0 | AD22: =(($J22/30/8)*1.5)*AC22 -> 0 | AF22: =(($J22/30/8)*2)*AE22 -> 0 | AH22: =(($J22/30/8)*1.5)*AG22 -> 0 | AJ22: =(($J22/30/8)*2)*AI22 -> 0 | AL22: =(($J22/30/8)*1.5)*AK22 -> 0 | AN22: =(($J22/30/8)*2)*AM22 -> 0 | BA22: =((J22/30)*M22)*$N22 -> 3660 | BB22: =((K22/30)*M22)*$N22 -> 1800 | BC22: =U22 -> 0 | BD22: =V22 -> 0 | BE22: =W22 -> 0 | BF22: =X22 -> 0 | BG22: =AO22+AT22 -> 0 | BH22: =(BA22+BD22+BF22+BG22)*0.1267 -> 463.722 | BI22: =SUM(BA22:BH22)-BC22-BE22 -> 5923.722 | BJ22: =(($J22/30)*$M22)*$O22 -> 3202.5 | BK22: =(($K22/30)*$M22)*$O22 -> 1575 | BL22: =Y22 -> 0 | BM22: =Z22 -> 0 | BN22: =AA22 -> 0 | BO22: =AB22 -> 0 | BP22: =AP22+AU22 -> 0 | BQ22: =(+BJ22+BM22+BO22+BP22)*0.1267 -> 405.75675 | BR22: =SUM(BJ22:BQ22)-BL22-BN22 -> 5183.2568 | BS22: =(($J22/30)*$M22)*$P22 -> 457.5 | BT22: =(($K22/30)*$M22)*$P22 -> 225 | BU22: =AC22 -> 0 | BV22: =AD22 -> 0 | BW22: =AE22 -> 0 | BX22: =AF22 -> 0 | BY22: =AQ22+AV22 -> 0 | BZ22: =(BS22+BV22+BX22+BY22)*0.1267 -> 57.96525 | CA22: =SUM(BS22:BZ22)-BU22-BW22 -> 740.46525 | CB22: =(($J22/30)*$M22)*$Q22 -> 1830 | CC22: =(($K22/30)*$M22)*$Q22 -> 900 | CD22: =AG22 -> 0 | CE22: =AH22 -> 0 | CF22: =AI22 -> 0 | CG22: =AJ22 -> 0 | CH22: =AR22+AW22 -> 0 | CI22: =(CB22+CE22+CG22+CH22)*0.1267 -> 231.861 | CJ22: =SUM(CB22:CI22)-CD22-CF22 -> 2961.861 | CK22: =(($J22/30)*$M22)*R22 -> 0 | CL22: =(($K22/30)*$M22)*$R22 -> 0 | CM22: =+AK22 -> 0 | CN22: =AL22 -> 0 | CO22: =AM22 -> 0 | CP22: =AN22 -> 0 | CQ22: =AS22+AX22 -> 0 | CR22: =(CK22+CN22+CP22)*0.1267 -> 0 | CS22: =SUM(CK22:CR22)-CM22-CO22 -> 0 | CU22: ECONACIONAL | CV22: =IF($CU22="PROQUIMA",$BA22+$BJ22+$BS22+$CB22+$CK22,0) -> 0 | CW22: =IF($CU22="PROQUIMA",$BB22+$BK22+$BT22+$CC22+$CL22,0) -> 0 | CX22: =IF($CU22="PROQUIMA",$BC22+$BL22+$BU22+$CD22+$CM22,0) -> 0 | CY22: =IF($CU22="PROQUIMA",$BD22+$BM22+$BV22+$CE22+$CN22,0) -> 0 | CZ22: =IF($CU22="PROQUIMA",$BE22+$BN22+$BW22+$CF22+$CO22,0) -> 0 | DA22: =IF($CU22="PROQUIMA",$BF22+$BO22+$BX22+$CG22+$CP22,0) -> 0 | DB22: =IF($CU22="PROQUIMA",$BG22+$BP22+$BY22+$CH22+$CQ22,0) -> 0 | DC22: =IF($CU22="PROQUIMA",$BH22+$BQ22+$BZ22+$CI22+CR22,0) -> 0 | DD22: =SUM(CV22:DC22)-CX22-CZ22 -> 0 | DE22: =IF($CU22="UNHESA",$BA22+$BJ22+$BS22+$CB22+$CK22,0) -> 0 | DF22: =IF($CU22="UNHESA",$BB22+$BK22+$BT22+$CC22+$CL22,0) -> 0 | DG22: =IF($CU22="UNHESA",$BC22+$BL22+$BU22+$CD22+$CM22,0) -> 0 | DH22: =IF($CU22="UNHESA",$BD22+$BM22+$BV22+$CE22+$CN22,0) -> 0 | DI22: =IF($CU22="UNHESA",$BE22+$BN22+$BW22+$CF22+$CO22,0) -> 0 | DJ22: =IF($CU22="UNHESA",$BF22+$BO22+$BX22+$CG22+$CP22,0) -> 0 | DK22: =IF($CU22="UNHESA",$BG22+$BP22+$BY22+$CH22+$CQ22,0) -> 0 | DL22: =IF($CU22="UNHESA",$BH22+$BQ22+$BZ22+$CI22+$CR22,0) -> 0 | DM22: =SUM(DE22:DL22)-DG22-DI22 -> 0 | DN22: =IF($CU22="UNHESA LIQUIDOS",$BA22+$BJ22+$BS22+$CB22+$CK22,0) -> 0 | DO22: =IF($CU22="UNHESA LIQUIDOS",$BB22+$BK22+$BT22+$CC22+$CL22,0) -> 0 | DP22: =IF($CU22="UNHESA LIQUIDOS",$BC22+$BL22+$BU22+$CD22+$CM22,0) -> 0 | DQ22: =IF($CU22="UNHESA LIQUIDOS",$BD22+$BM22+$BV22+$CE22+$CN22,0) -> 0 | DR22: =IF($CU22="UNHESA LIQUIDOS",$BE22+$BN22+$BW22+$CF22+$CO22,0) -> 0 | DS22: =IF($CU22="UNHESA LIQUIDOS",$BF22+$BO22+$BX22+$CG22+$CP22,0) -> 0 | DT22: =IF($CU22="UNHESA LIQUIDOS",$BG22+$BP22+$BY22+$CH22+$CQ22,0) -> 0 | DU22: =IF($CU22="UNHESA LIQUIDOS",$BH22+$BQ22+$BZ22+$CI22+$CR22,0) -> 0 | DV22: =SUM(DN22:DU22)-DP22-DR22 -> 0 | DW22: =IF($CU22="CLEARTEC",$BA22+$BJ22+$BS22+$CB22+$CK22,0) -> 0 | DX22: =IF($CU22="CLEARTEC",$BA22+$BJ22+$BS22+$CB22+$CK22,0) -> 0 | DY22: =IF($CU22="CLEARTEC",$BA22+$BJ22+$BS22+$CB22+$CK22,0) -> 0 | DZ22: =IF($CU22="CLEARTEC",$BA22+$BJ22+$BS22+$CB22+$CK22,0) -> 0 | EA22: =IF($CU22="CLEARTEC",$BA22+$BJ22+$BS22+$CB22+$CK22,0) -> 0 | EB22: =IF($CU22="CLEARTEC",$BA22+$BJ22+$BS22+$CB22+$CK22,0) -> 0 | EC22: =IF($CU22="CLEARTEC",$BA22+$BJ22+$BS22+$CB22+$CK22,0) -> 0 | ED22: =IF($CU22="CLEARTEC",$BA22+$BJ22+$BS22+$CB22+$CK22,0) -> 0 | EE22: =IF($CU22="CLEARTEC",$BA22+$BJ22+$BS22+$CB22+$CK22,0) -> 0 | EF22: =IF(CU22="ECONACIONAL",$BA22+$BJ22+$BS22+$CB22+$CK22) -> 9150 | EG22: =IF($CU22="ECONACIONAL",$BB22+$BK22+$BT22+$CC22+$CL22,0) -> 4500 | EH22: =IF(CU22="ECONACIONAL",$BC22+$BL22+$BU22+$CD22+$CM22) -> 0 | EI22: =IF(CU22="ECONACIONAL",$BD22+$DH22+$DQ22+$DZ22+BM22+BV22+CE22+CN22) -> 0 | EJ22: =IF($CU22="CLEARTEC",$BE22+$BN22+$BW22+$CF22+$CO22,0) -> 0 | EK22: =IF(CU22="ECONACIONAL",$BF22+$BO22+$BX22+$CG22+$CP22) -> 0 | EL22: =IF(CU22="ECONACIONAL",$BG22+$BP22+$BY22+$CH22+$CQ22) -> 0 | EM22: =IF(CU22="ECONACIONAL",BH22+BQ22+BZ22+CI22+CR22) -> 1159.305 | EN22: =SUM(EF22:EM22)-EH22-EJ22 -> 14809.305 | EP22: 429.5 | ES22: =300+302 -> 602 | EY22: =+ET22+EU22+EV22 -> 0 | FA22: =IF($M22<=15,EP22/2,EP22) -> 429.5 | FB22: =IF($M22<=15,EQ22/2,EQ22) -> 0 | FC22: =IF($M22<=15,ER22/2,ER22) -> 0 | FD22: =IF($M22<=15,ES22/2,ES22) -> 602 | FE22: =IF($M22<=15,ET22/2,ET22) -> 0 | FF22: =IF($M22<=15,EU22/2,EU22) -> 0 | FG22: =IF($M22<=15,EV22/2,EV22) -> 0 | FH22: =IF($M22<=15,EW22/2,EW22) -> 0 | ... FJ22: =IF($M22<=15,EY22/2,EY22) -> 0 | FK22: 0.5 | FL22: 0.5 | FM22: 0 | FN22: 0 | FO22: 0 | FP22: 1 | FR22: =(((J22/30/8)*1.5)*(U22+Y22+AC22))-(BD22+BM22+BV22) -> 0 | FS22: =(((J22/30/8)*2)*(W22+AA22+AE22))-(BF22+BO22+BX22) -> 0 | FT22: =(SUM(BA22:CJ22))-(SUM(EF22:EN22)) -> 0 | FU22: =(J22/30*M22)-(EF22) -> 0 | FV22: =(SUM(EP22:EY22))-((SUM(FA22:FJ22))*$FV$5) -> -1031.5
A23: =$G$4 -> JUNIO 2026 2da QUINCENA | B23: =+$G$5 -> 2026 | C23: =A23 & B23 -> JUNIO 2026 2da QUINCENA2026 | D23: =+$G$20 -> RECURSOS HUMANOS | E23: 103010 | F23: =+F22+1 -> 2 | G23: Perez Menendez Mayra Alejandra | H23: Asistente de Recursos Humanos | I23: ECONACIONAL | J23: 4850 | K23: 1500 | L23: =+J23+K23 -> 6350 | M23: 30 | N23: 0.4 | O23: 0.35 | P23: 0.05 | Q23: 0.2 | R23: 0 | S23: =SUM(N23:R23) -> 1 | V23: =($J23/30/8*1.5)*U23 -> 0 | X23: =($J23/30/8*2)*W23 -> 0 | Z23: =($J23/30/8*1.5)*Y23 -> 0 | AB23: =($J23/30/8*2)*AA23 -> 0 | AD23: =(($J23/30/8)*1.5)*AC23 -> 0 | AF23: =(($J23/30/8)*2)*AE23 -> 0 | AH23: =(($J23/30/8)*1.5)*AG23 -> 0 | AJ23: =(($J23/30/8)*2)*AI23 -> 0 | AL23: =(($J23/30/8)*1.5)*AK23 -> 0 | AN23: =(($J23/30/8)*2)*AM23 -> 0 | BA23: =((J23/30)*M23)*$N23 -> 1940 | BB23: =((K23/30)*M23)*$N23 -> 600 | BC23: =U23 -> 0 | BD23: =V23 -> 0 | BE23: =W23 -> 0 | BF23: =X23 -> 0 | BG23: =AO23+AT23 -> 0 | BH23: =(BA23+BD23+BF23+BG23)*0.1267 -> 245.798 | BI23: =SUM(BA23:BH23)-BC23-BE23 -> 2785.798 | BJ23: =(($J23/30)*$M23)*$O23 -> 1697.5 | BK23: =(($K23/30)*$M23)*$O23 -> 525 | BL23: =Y23 -> 0 | BM23: =Z23 -> 0 | BN23: =AA23 -> 0 | BO23: =AB23 -> 0 | BP23: =AP23+AU23 -> 0 | BQ23: =(+BJ23+BM23+BO23+BP23)*0.1267 -> 215.07325 | BR23: =SUM(BJ23:BQ23)-BL23-BN23 -> 2437.5732 | BS23: =(($J23/30)*$M23)*$P23 -> 242.5 | BT23: =(($K23/30)*$M23)*$P23 -> 75 | BU23: =AC23 -> 0 | BV23: =AD23 -> 0 | BW23: =AE23 -> 0 | BX23: =AF23 -> 0 | BY23: =AQ23+AV23 -> 0 | BZ23: =(BS23+BV23+BX23+BY23)*0.1267 -> 30.72475 | CA23: =SUM(BS23:BZ23)-BU23-BW23 -> 348.22475 | CB23: =(($J23/30)*$M23)*$Q23 -> 970 | CC23: =(($K23/30)*$M23)*$Q23 -> 300 | CD23: =AG23 -> 0 | CE23: =AH23 -> 0 | CF23: =AI23 -> 0 | CG23: =AJ23 -> 0 | CH23: =AR23+AW23 -> 0 | CI23: =(CB23+CE23+CG23+CH23)*0.1267 -> 122.899 | CJ23: =SUM(CB23:CI23)-CD23-CF23 -> 1392.899 | CK23: =(($J23/30)*$M23)*R23 -> 0 | CL23: =(($K23/30)*$M23)*$R23 -> 0 | CM23: =+AK23 -> 0 | CN23: =AL23 -> 0 | CO23: =AM23 -> 0 | CP23: =AN23 -> 0 | CQ23: =AS23+AX23 -> 0 | CR23: =(CK23+CN23+CP23)*0.1267 -> 0 | CS23: =SUM(CK23:CR23)-CM23-CO23 -> 0 | CU23: ECONACIONAL | CV23: =IF($CU23="PROQUIMA",$BA23+$BJ23+$BS23+$CB23+$CK23,0) -> 0 | CW23: =IF($CU23="PROQUIMA",$BB23+$BK23+$BT23+$CC23+$CL23,0) -> 0 | CX23: =IF($CU23="PROQUIMA",$BC23+$BL23+$BU23+$CD23+$CM23,0) -> 0 | CY23: =IF($CU23="PROQUIMA",$BD23+$BM23+$BV23+$CE23+$CN23,0) -> 0 | CZ23: =IF($CU23="PROQUIMA",$BE23+$BN23+$BW23+$CF23+$CO23,0) -> 0 | DA23: =IF($CU23="PROQUIMA",$BF23+$BO23+$BX23+$CG23+$CP23,0) -> 0 | DB23: =IF($CU23="PROQUIMA",$BG23+$BP23+$BY23+$CH23+$CQ23,0) -> 0 | DC23: =IF($CU23="PROQUIMA",$BH23+$BQ23+$BZ23+$CI23+CR23,0) -> 0 | DD23: =SUM(CV23:DC23)-CX23-CZ23 -> 0 | DE23: =IF($CU23="UNHESA",$BA23+$BJ23+$BS23+$CB23+$CK23,0) -> 0 | DF23: =IF($CU23="UNHESA",$BB23+$BK23+$BT23+$CC23+$CL23,0) -> 0 | DG23: =IF($CU23="UNHESA",$BC23+$BL23+$BU23+$CD23+$CM23,0) -> 0 | DH23: =IF($CU23="UNHESA",$BD23+$BM23+$BV23+$CE23+$CN23,0) -> 0 | DI23: =IF($CU23="UNHESA",$BE23+$BN23+$BW23+$CF23+$CO23,0) -> 0 | DJ23: =IF($CU23="UNHESA",$BF23+$BO23+$BX23+$CG23+$CP23,0) -> 0 | DK23: =IF($CU23="UNHESA",$BG23+$BP23+$BY23+$CH23+$CQ23,0) -> 0 | DL23: =IF($CU23="UNHESA",$BH23+$BQ23+$BZ23+$CI23+$CR23,0) -> 0 | DM23: =SUM(DE23:DL23)-DG23-DI23 -> 0 | DN23: =IF($CU23="UNHESA LIQUIDOS",$BA23+$BJ23+$BS23+$CB23+$CK23,0) -> 0 | DO23: =IF($CU23="UNHESA LIQUIDOS",$BB23+$BK23+$BT23+$CC23+$CL23,0) -> 0 | DP23: =IF($CU23="UNHESA LIQUIDOS",$BC23+$BL23+$BU23+$CD23+$CM23,0) -> 0 | DQ23: =IF($CU23="UNHESA LIQUIDOS",$BD23+$BM23+$BV23+$CE23+$CN23,0) -> 0 | DR23: =IF($CU23="UNHESA LIQUIDOS",$BE23+$BN23+$BW23+$CF23+$CO23,0) -> 0 | DS23: =IF($CU23="UNHESA LIQUIDOS",$BF23+$BO23+$BX23+$CG23+$CP23,0) -> 0 | DT23: =IF($CU23="UNHESA LIQUIDOS",$BG23+$BP23+$BY23+$CH23+$CQ23,0) -> 0 | DU23: =IF($CU23="UNHESA LIQUIDOS",$BH23+$BQ23+$BZ23+$CI23+$CR23,0) -> 0 | DV23: =SUM(DN23:DU23)-DP23-DR23 -> 0 | DW23: =IF($CU23="CLEARTEC",$BA23+$BJ23+$BS23+$CB23+$CK23,0) -> 0 | DX23: =IF($CU23="CLEARTEC",$BA23+$BJ23+$BS23+$CB23+$CK23,0) -> 0 | DY23: =IF($CU23="CLEARTEC",$BA23+$BJ23+$BS23+$CB23+$CK23,0) -> 0 | DZ23: =IF($CU23="CLEARTEC",$BA23+$BJ23+$BS23+$CB23+$CK23,0) -> 0 | EA23: =IF($CU23="CLEARTEC",$BA23+$BJ23+$BS23+$CB23+$CK23,0) -> 0 | EB23: =IF($CU23="CLEARTEC",$BA23+$BJ23+$BS23+$CB23+$CK23,0) -> 0 | EC23: =IF($CU23="CLEARTEC",$BA23+$BJ23+$BS23+$CB23+$CK23,0) -> 0 | ED23: =IF($CU23="CLEARTEC",$BA23+$BJ23+$BS23+$CB23+$CK23,0) -> 0 | EE23: =IF($CU23="CLEARTEC",$BA23+$BJ23+$BS23+$CB23+$CK23,0) -> 0 | EF23: =IF(CU23="ECONACIONAL",$BA23+$BJ23+$BS23+$CB23+$CK23) -> 4850 | EG23: =IF($CU23="ECONACIONAL",$BB23+$BK23+$BT23+$CC23+$CL23,0) -> 1500 | EH23: =IF(CU23="ECONACIONAL",$BC23+$BL23+$BU23+$CD23+$CM23) -> 0 | EI23: =IF(CU23="ECONACIONAL",$BD23+$DH23+$DQ23+$DZ23+BM23+BV23+CE23+CN23) -> 0 | EJ23: =IF($CU23="CLEARTEC",$BE23+$BN23+$BW23+$CF23+$CO23,0) -> 0 | EK23: =IF(CU23="ECONACIONAL",$BF23+$BO23+$BX23+$CG23+$CP23) -> 0 | EL23: =IF(CU23="ECONACIONAL",$BG23+$BP23+$BY23+$CH23+$CQ23) -> 0 | EM23: =IF(CU23="ECONACIONAL",BH23+BQ23+BZ23+CI23+CR23) -> 614.495 | EN23: =SUM(EF23:EM23)-EH23-EJ23 -> 6964.495 | EP23: 115.97 | ES23: =124+81.5 -> 205.5 | EV23: 350 | EX23: 313.43 | EY23: =+ET23+EU23+EV23 -> 350 | FA23: =IF($M23<=15,EP23/2,EP23) -> 115.97 | FB23: =IF($M23<=15,EQ23/2,EQ23) -> 0 | FC23: =IF($M23<=15,ER23/2,ER23) -> 0 | FD23: =IF($M23<=15,ES23/2,ES23) -> 205.5 | FE23: =IF($M23<=15,ET23/2,ET23) -> 0 | FF23: =IF($M23<=15,EU23/2,EU23) -> 0 | FG23: =IF($M23<=15,EV23/2,EV23) -> 350 | FH23: =IF($M23<=15,EW23/2,EW23) -> 0 | ... FJ23: =IF($M23<=15,EY23/2,EY23) -> 350 | FR23: =(((J23/30/8)*1.5)*(U23+Y23+AC23))-(BD23+BM23+BV23) -> 0 | FS23: =(((J23/30/8)*2)*(W23+AA23+AE23))-(BF23+BO23+BX23) -> 0 | FT23: =(SUM(BA23:CJ23))-(SUM(EF23:EN23)) -> 0 | FU23: =(J23/30*M23)-(EF23) -> 0 | FV23: =(SUM(EP23:EY23))-((SUM(FA23:FJ23))*$FV$5) -> -1334.9
A24: =$G$4 -> JUNIO 2026 2da QUINCENA | B24: =+$G$5 -> 2026 | C24: =A24 & B24 -> JUNIO 2026 2da QUINCENA2026 | D24: =+$G$8 -> ADMINISTRATIVO | E24: 103010 | F24: 4 | G24: Saenz Lemus Dulce Maria | H24: Recepcionista | I24: ECONACIONAL | J24: 4250.03 | K24: 250 | L24: =+J24+K24 -> 4500.03 | M24: 30 | N24: 0.5 | O24: 0.45 | P24: 0.05 | Q24: 0 | R24: 0 | S24: =SUM(N24:R24) -> 1 | V24: =($J24/30/8*1.5)*U24 -> 0 | X24: =($J24/30/8*2)*W24 -> 0 | Z24: =($J24/30/8*1.5)*Y24 -> 0 | AB24: =($J24/30/8*2)*AA24 -> 0 | AD24: =(($J24/30/8)*1.5)*AC24 -> 0 | AF24: =(($J24/30/8)*2)*AE24 -> 0 | AH24: =(($J24/30/8)*1.5)*AG24 -> 0 | AJ24: =(($J24/30/8)*2)*AI24 -> 0 | BA24: =((J24/30)*M24)*$N24 -> 2125.015 | BB24: =((K24/30)*M24)*$N24 -> 125 | BC24: =U24 -> 0 | BD24: =V24 -> 0 | BE24: =W24 -> 0 | BF24: =X24 -> 0 | BG24: =AO24+AT24 -> 0 | BH24: =(BA24+BD24+BF24+BG24)*0.1267 -> 269.2394 | BI24: =SUM(BA24:BH24)-BC24-BE24 -> 2519.2544 | BJ24: =(($J24/30)*$M24)*$O24 -> 1912.5135 | BK24: =(($K24/30)*$M24)*$O24 -> 112.5 | BL24: =Y24 -> 0 | BM24: =Z24 -> 0 | BN24: =AA24 -> 0 | BO24: =AB24 -> 0 | BP24: =AP24+AU24 -> 0 | BQ24: =(+BJ24+BM24+BO24+BP24)*0.1267 -> 242.31546 | BR24: =SUM(BJ24:BQ24)-BL24-BN24 -> 2267.329 | BS24: =(($J24/30)*$M24)*$P24 -> 212.5015 | BT24: =(($K24/30)*$M24)*$P24 -> 12.5 | BU24: =AC24 -> 0 | BV24: =AD24 -> 0 | BW24: =AE24 -> 0 | BX24: =AF24 -> 0 | BY24: =AQ24+AV24 -> 0 | BZ24: =(BS24+BV24+BX24+BY24)*0.1267 -> 26.92394 | CA24: =SUM(BS24:BZ24)-BU24-BW24 -> 251.92544 | CB24: =(($J24/30)*$M24)*$Q24 -> 0 | CC24: =(($K24/30)*$M24)*$Q24 -> 0 | CD24: =AG24 -> 0 | CE24: =AH24 -> 0 | CF24: =AI24 -> 0 | CG24: =AJ24 -> 0 | CH24: =AR24+AW24 -> 0 | CI24: =(CB24+CE24+CG24+CH24)*0.1267 -> 0 | CJ24: =SUM(CB24:CI24)-CD24-CF24 -> 0 | CU24: ECONACIONAL | CV24: =IF($CU24="PROQUIMA",$BA24+$BJ24+$BS24+$CB24+$CK24,0) -> 0 | CW24: =IF($CU24="PROQUIMA",$BB24+$BK24+$BT24+$CC24+$CL24,0) -> 0 | CX24: =IF($CU24="PROQUIMA",$BC24+$BL24+$BU24+$CD24+$CM24,0) -> 0 | CY24: =IF($CU24="PROQUIMA",$BD24+$BM24+$BV24+$CE24+$CN24,0) -> 0 | CZ24: =IF($CU24="PROQUIMA",$BE24+$BN24+$BW24+$CF24+$CO24,0) -> 0 | DA24: =IF($CU24="PROQUIMA",$BF24+$BO24+$BX24+$CG24+$CP24,0) -> 0 | DB24: =IF($CU24="PROQUIMA",$BG24+$BP24+$BY24+$CH24+$CQ24,0) -> 0 | DC24: =IF($CU24="PROQUIMA",$BH24+$BQ24+$BZ24+$CI24+CR24,0) -> 0 | DD24: =SUM(CV24:DC24)-CX24-CZ24 -> 0 | DE24: =IF($CU24="UNHESA",$BA24+$BJ24+$BS24+$CB24+$CK24,0) -> 0 | DF24: =IF($CU24="UNHESA",$BB24+$BK24+$BT24+$CC24+$CL24,0) -> 0 | DG24: =IF($CU24="UNHESA",$BC24+$BL24+$BU24+$CD24+$CM24,0) -> 0 | DH24: =IF($CU24="UNHESA",$BD24+$BM24+$BV24+$CE24+$CN24,0) -> 0 | DI24: =IF($CU24="UNHESA",$BE24+$BN24+$BW24+$CF24+$CO24,0) -> 0 | DJ24: =IF($CU24="UNHESA",$BF24+$BO24+$BX24+$CG24+$CP24,0) -> 0 | DK24: =IF($CU24="UNHESA",$BG24+$BP24+$BY24+$CH24+$CQ24,0) -> 0 | DL24: =IF($CU24="UNHESA",$BH24+$BQ24+$BZ24+$CI24+$CR24,0) -> 0 | DM24: =SUM(DE24:DL24)-DG24-DI24 -> 0 | DN24: =IF($CU24="UNHESA LIQUIDOS",$BA24+$BJ24+$BS24+$CB24+$CK24,0) -> 0 | DO24: =IF($CU24="CALIDUL",$BB24+$BK24+$BT24+$CC24+$CL24,0) -> 0 | DP24: =IF($CU24="CALIDUL",$BC24+$BL24+$BU24+$CD24+$CM24,0) -> 0 | DQ24: =IF($CU24="CALIDUL",$BD24+$BM24+$BV24+$CE24+$CN24,0) -> 0 | DR24: =IF($CU24="CALIDUL",$BE24+$BN24+$BW24+$CF24+$CO24,0) -> 0 | DS24: =IF($CU24="CALIDUL",$BF24+$BO24+$BX24+$CG24+$CP24,0) -> 0 | DT24: =IF($CU24="CALIDUL",$BG24+$BP24+$BY24+$CH24+$CQ24,0) -> 0 | DU24: =IF($CU24="CALIDUL",$BH24+$BQ24+$BZ24+$CI24+$CR24,0) -> 0 | DV24: =SUM(DN24:DU24)-DP24-DR24 -> 0 | DW24: =IF($CU24="CLEARTEC",$BA24+$BJ24+$BS24+$CB24+$CK24,0) -> 0 | DX24: =IF($CU24="CLEARTEC",$BA24+$BJ24+$BS24+$CB24+$CK24,0) -> 0 | DY24: =IF($CU24="CLEARTEC",$BA24+$BJ24+$BS24+$CB24+$CK24,0) -> 0 | DZ24: =IF($CU24="CLEARTEC",$BA24+$BJ24+$BS24+$CB24+$CK24,0) -> 0 | EA24: =IF($CU24="CLEARTEC",$BA24+$BJ24+$BS24+$CB24+$CK24,0) -> 0 | EB24: =IF($CU24="CLEARTEC",$BA24+$BJ24+$BS24+$CB24+$CK24,0) -> 0 | EC24: =IF($CU24="CLEARTEC",$BA24+$BJ24+$BS24+$CB24+$CK24,0) -> 0 | ED24: =IF($CU24="CLEARTEC",$BA24+$BJ24+$BS24+$CB24+$CK24,0) -> 0 | EE24: =SUM(DW24:ED24)-DY24-EA24 -> 0 | EF24: =IF(CU24="ECONACIONAL",$BA24+$BJ24+$BS24+$CB24+$CK24) -> 4250.03 | EG24: =IF($CU24="ECONACIONAL",$BB24+$BK24+$BT24+$CC24+$CL24,0) -> 250 | EH24: =IF(CU24="ECONACIONAL",$BC24+$BL24+$BU24+$CD24+$CM24) -> 0 | EI24: =IF(CU24="ECONACIONAL",$BD24+$DH24+$DQ24+$DZ24+BM24+BV24+CE24+CN24) -> 0 | EJ24: =IF($CU24="CLEARTEC",$BE24+$BN24+$BW24+$CF24+$CO24,0) -> 0 | EK24: =IF(CU24="ECONACIONAL",$BF24+$BO24+$BX24+$CG24+$CP24) -> 0 | EL24: =IF(CU24="ECONACIONAL",$BG24+$BP24+$BY24+$CH24+$CQ24) -> 0 | EM24: =IF(CU24="ECONACIONAL",BH24+BQ24+BZ24+CI24+CR24) -> 538.4788 | EN24: =SUM(EF24:EM24)-EH24-EJ24 -> 5038.5088 | EP24: 4.51 | ES24: =135.5+88.5 -> 224 | EY24: =+ET24+EU24+EV24 -> 0 | FA24: =IF($M24<=15,EP24/2,EP24) -> 4.51 | FB24: =IF($M24<=15,EQ24/2,EQ24) -> 0 | FC24: =IF($M24<=15,ER24/2,ER24) -> 0 | FD24: =IF($M24<=15,ES24/2,ES24) -> 224 | FE24: =IF($M24<=15,ET24/2,ET24) -> 0 | FF24: =IF($M24<=15,EU24/2,EU24) -> 0 | FG24: =IF($M24<=15,EV24/2,EV24) -> 0 | FH24: =IF($M24<=15,EW24/2,EW24) -> 0 | ... FJ24: =IF($M24<=15,EY24/2,EY24) -> 0 | FR24: =(((J24/30/8)*1.5)*(U24+Y24+AC24))-(BD24+BM24+BV24) -> 0 | FS24: =(((J24/30/8)*2)*(W24+AA24+AE24))-(BF24+BO24+BX24) -> 0 | FT24: =(SUM(BA24:CJ24))-(SUM(EF24:EN24)) -> 0 | FU24: =(J24/30*M24)-(EF24) -> 0 | FV24: =(SUM(EP24:EY24))-((SUM(FA24:FJ24))*$FV$5) -> -228.51
A25: =$G$4 -> JUNIO 2026 2da QUINCENA | B25: =+$G$5 -> 2026 | C25: =A25 & B25 -> JUNIO 2026 2da QUINCENA2026 | D25: =+$G$20 -> RECURSOS HUMANOS | E25: 103010 | F25: 9 | G25: Marroquin Rueda Jenneffer Ivonne | H25: Asistente de Reclutamiento | I25: ECONACIONAL | J25: 4725 | K25: 1000 | L25: =+J25+K25 -> 5725 | M25: 30 | N25: 0.4 | O25: 0.35 | P25: 0.05 | Q25: 0.2 | R25: 0 | S25: =SUM(N25:R25) -> 1 | V25: =($J25/30/8*1.5)*U25 -> 0 | X25: =($J25/30/8*2)*W25 -> 0 | Z25: =($J25/30/8*1.5)*Y25 -> 0 | AB25: =($J25/30/8*2)*AA25 -> 0 | AD25: =(($J25/30/8)*1.5)*AC25 -> 0 | AF25: =(($J25/30/8)*2)*AE25 -> 0 | AH25: =(($J25/30/8)*1.5)*AG25 -> 0 | AJ25: =(($J25/30/8)*2)*AI25 -> 0 | AL25: =(($J25/30/8)*1.5)*AK25 -> 0 | AN25: =(($J25/30/8)*2)*AM25 -> 0 | BA25: =((J25/30)*M25)*$N25 -> 1890 | BB25: =((K25/30)*M25)*$N25 -> 400 | BC25: =U25 -> 0 | BD25: =V25 -> 0 | BE25: =W25 -> 0 | BF25: =X25 -> 0 | BG25: =AO25+AT25 -> 0 | BH25: =(BA25+BD25+BF25+BG25)*0.1267 -> 239.463 | BI25: =SUM(BA25:BH25)-BC25-BE25 -> 2529.463 | BJ25: =(($J25/30)*$M25)*$O25 -> 1653.75 | BK25: =(($K25/30)*$M25)*$O25 -> 350 | BL25: =Y25 -> 0 | BM25: =Z25 -> 0 | BN25: =AA25 -> 0 | BO25: =AB25 -> 0 | BP25: =AP25+AU25 -> 0 | BQ25: =(+BJ25+BM25+BO25+BP25)*0.1267 -> 209.53012 | BR25: =SUM(BJ25:BQ25)-BL25-BN25 -> 2213.2801 | BS25: =(($J25/30)*$M25)*$P25 -> 236.25 | BT25: =(($K25/30)*$M25)*$P25 -> 50 | BU25: =AC25 -> 0 | BV25: =AD25 -> 0 | BW25: =AE25 -> 0 | BX25: =AF25 -> 0 | BY25: =AQ25+AV25 -> 0 | BZ25: =(BS25+BV25+BX25+BY25)*0.1267 -> 29.932875 | CA25: =SUM(BS25:BZ25)-BU25-BW25 -> 316.18288 | CB25: =(($J25/30)*$M25)*$Q25 -> 945 | CC25: =(($K25/30)*$M25)*$Q25 -> 200 | CD25: =AG25 -> 0 | CE25: =AH25 -> 0 | CF25: =AI25 -> 0 | CG25: =AJ25 -> 0 | CH25: =AR25+AW25 -> 0 | CI25: =(CB25+CE25+CG25+CH25)*0.1267 -> 119.7315 | CJ25: =SUM(CB25:CI25)-CD25-CF25 -> 1264.7315 | CK25: =(($J25/30)*$M25)*R25 -> 0 | CL25: =(($K25/30)*$M25)*$R25 -> 0 | CM25: =+AK25 -> 0 | CN25: =AL25 -> 0 | CO25: =AM25 -> 0 | CP25: =AN25 -> 0 | CQ25: =AS25+AX25 -> 0 | CR25: =(CK25+CN25+CP25)*0.1267 -> 0 | CS25: =SUM(CK25:CR25)-CM25-CO25 -> 0 | CU25: ECONACIONAL | CV25: =IF($CU25="PROQUIMA",$BA25+$BJ25+$BS25+$CB25+$CK25,0) -> 0 | CW25: =IF($CU25="PROQUIMA",$BB25+$BK25+$BT25+$CC25+$CL25,0) -> 0 | CX25: =IF($CU25="PROQUIMA",$BC25+$BL25+$BU25+$CD25+$CM25,0) -> 0 | CY25: =IF($CU25="PROQUIMA",$BD25+$BM25+$BV25+$CE25+$CN25,0) -> 0 | CZ25: =IF($CU25="PROQUIMA",$BE25+$BN25+$BW25+$CF25+$CO25,0) -> 0 | DA25: =IF($CU25="PROQUIMA",$BF25+$BO25+$BX25+$CG25+$CP25,0) -> 0 | DB25: =IF($CU25="PROQUIMA",$BG25+$BP25+$BY25+$CH25+$CQ25,0) -> 0 | DC25: =IF($CU25="PROQUIMA",$BH25+$BQ25+$BZ25+$CI25+CR25,0) -> 0 | DD25: =SUM(CV25:DC25)-CX25-CZ25 -> 0 | DE25: =IF($CU25="UNHESA",$BA25+$BJ25+$BS25+$CB25+$CK25,0) -> 0 | DF25: =IF($CU25="UNHESA",$BB25+$BK25+$BT25+$CC25+$CL25,0) -> 0 | DG25: =IF($CU25="UNHESA",$BC25+$BL25+$BU25+$CD25+$CM25,0) -> 0 | DH25: =IF($CU25="UNHESA",$BD25+$BM25+$BV25+$CE25+$CN25,0) -> 0 | DI25: =IF($CU25="UNHESA",$BE25+$BN25+$BW25+$CF25+$CO25,0) -> 0 | DJ25: =IF($CU25="UNHESA",$BF25+$BO25+$BX25+$CG25+$CP25,0) -> 0 | DK25: =IF($CU25="UNHESA",$BG25+$BP25+$BY25+$CH25+$CQ25,0) -> 0 | DL25: =IF($CU25="UNHESA",$BH25+$BQ25+$BZ25+$CI25+$CR25,0) -> 0 | DM25: =SUM(DE25:DL25)-DG25-DI25 -> 0 | DN25: =IF($CU25="UNHESA LIQUIDOS",$BA25+$BJ25+$BS25+$CB25+$CK25,0) -> 0 | DO25: =IF($CU25="UNHESA LIQUIDOS",$BB25+$BK25+$BT25+$CC25+$CL25,0) -> 0 | DP25: =IF($CU25="UNHESA LIQUIDOS",$BC25+$BL25+$BU25+$CD25+$CM25,0) -> 0 | DQ25: =IF($CU25="UNHESA LIQUIDOS",$BD25+$BM25+$BV25+$CE25+$CN25,0) -> 0 | DR25: =IF($CU25="UNHESA LIQUIDOS",$BE25+$BN25+$BW25+$CF25+$CO25,0) -> 0 | DS25: =IF($CU25="UNHESA LIQUIDOS",$BF25+$BO25+$BX25+$CG25+$CP25,0) -> 0 | DT25: =IF($CU25="UNHESA LIQUIDOS",$BG25+$BP25+$BY25+$CH25+$CQ25,0) -> 0 | DU25: =IF($CU25="UNHESA LIQUIDOS",$BH25+$BQ25+$BZ25+$CI25+$CR25,0) -> 0 | DV25: =SUM(DN25:DU25)-DP25-DR25 -> 0 | DW25: =IF($CU25="CLEARTEC",$BA25+$BJ25+$BS25+$CB25+$CK25,0) -> 0 | DX25: =IF($CU25="CLEARTEC",$BA25+$BJ25+$BS25+$CB25+$CK25,0) -> 0 | DY25: =IF($CU25="CLEARTEC",$BA25+$BJ25+$BS25+$CB25+$CK25,0) -> 0 | DZ25: =IF($CU25="CLEARTEC",$BA25+$BJ25+$BS25+$CB25+$CK25,0) -> 0 | EA25: =IF($CU25="CLEARTEC",$BA25+$BJ25+$BS25+$CB25+$CK25,0) -> 0 | EB25: =IF($CU25="CLEARTEC",$BA25+$BJ25+$BS25+$CB25+$CK25,0) -> 0 | EC25: =IF($CU25="CLEARTEC",$BA25+$BJ25+$BS25+$CB25+$CK25,0) -> 0 | ED25: =IF($CU25="CLEARTEC",$BA25+$BJ25+$BS25+$CB25+$CK25,0) -> 0 | EE25: =IF($CU25="CLEARTEC",$BA25+$BJ25+$BS25+$CB25+$CK25,0) -> 0 | EF25: =IF(CU25="ECONACIONAL",$BA25+$BJ25+$BS25+$CB25+$CK25) -> 4725 | EG25: =IF($CU25="ECONACIONAL",$BB25+$BK25+$BT25+$CC25+$CL25,0) -> 1000 | EH25: =IF(CU25="ECONACIONAL",$BC25+$BL25+$BU25+$CD25+$CM25) -> 0 | EI25: =IF(CU25="ECONACIONAL",$BD25+$DH25+$DQ25+$DZ25+BM25+BV25+CE25+CN25) -> 0 | EJ25: =IF($CU25="CLEARTEC",$BE25+$BN25+$BW25+$CF25+$CO25,0) -> 0 | EK25: =IF(CU25="ECONACIONAL",$BF25+$BO25+$BX25+$CG25+$CP25) -> 0 | EL25: =IF(CU25="ECONACIONAL",$BG25+$BP25+$BY25+$CH25+$CQ25) -> 0 | EM25: =IF(CU25="ECONACIONAL",BH25+BQ25+BZ25+CI25+CR25) -> 598.6575 | EN25: =SUM(EF25:EM25)-EH25-EJ25 -> 6323.6575 | EP25: 61.78 | ES25: =215.5+230 -> 445.5 | ET25: 82.5 | EX25: 313.43 | EY25: =+ET25+EU25+EV25 -> 82.5 | FA25: =IF($M25<=15,EP25/2,EP25) -> 61.78 | FB25: =IF($M25<=15,EQ25/2,EQ25) -> 0 | FC25: =IF($M25<=15,ER25/2,ER25) -> 0 | FD25: =IF($M25<=15,ES25/2,ES25) -> 445.5 | FE25: =IF($M25<=15,ET25/2,ET25) -> 82.5 | FF25: =IF($M25<=15,EU25/2,EU25) -> 0 | FG25: =IF($M25<=15,EV25/2,EV25) -> 0 | FH25: =IF($M25<=15,EW25/2,EW25) -> 0 | ... FJ25: =IF($M25<=15,EY25/2,EY25) -> 82.5 | FR25: =(((J25/30/8)*1.5)*(U25+Y25+AC25))-(BD25+BM25+BV25) -> 0 | FS25: =(((J25/30/8)*2)*(W25+AA25+AE25))-(BF25+BO25+BX25) -> 0 | FT25: =(SUM(BA25:CJ25))-(SUM(EF25:EN25)) -> 0 | FU25: =(J25/30*M25)-(EF25) -> 0 | FV25: =(SUM(EP25:EY25))-((SUM(FA25:FJ25))*$FV$5) -> -985.71
H26: TotaL Recursos Humanos | J26: =SUM(J22:J25) -> 22975.03 | K26: =SUM(K22:K25) -> 7250 | L26: =SUM(L22:L25) -> 30225.03 | U26: =SUM(U22:U25) -> 0 | V26: =SUM(V22:V25) -> 0 | W26: =SUM(W22:W25) -> 0 | X26: =SUM(X22:X25) -> 0 | Y26: =SUM(Y22:Y25) -> 0 | Z26: =SUM(Z22:Z25) -> 0 | AA26: =SUM(AA22:AA25) -> 0 | AB26: =SUM(AB22:AB25) -> 0 | ... EN26: =SUM(EN22:EN25) -> 33135.966 | EP26: =SUM(EP22:EP25) -> 611.76 | EQ26: =SUM(EQ22:EQ25) -> 0 | ER26: =SUM(ER22:ER25) -> 0 | ES26: =SUM(ES22:ES25) -> 1477 | ET26: =SUM(ET22:ET25) -> 82.5 | EU26: =SUM(EU22:EU25) -> 0 | EV26: =SUM(EV22:EV25) -> 350 | EW26: =SUM(EW22:EW25) -> 0 | ... EY26: =SUM(EY22:EY25) -> 432.5 | FA26: =SUM(FA22:FA25) -> 611.76 | FB26: =SUM(FB22:FB25) -> 0 | FC26: =SUM(FC22:FC25) -> 0 | FD26: =SUM(FD22:FD25) -> 1477 | FE26: =SUM(FE22:FE25) -> 82.5 | FF26: =SUM(FF22:FF25) -> 0 | FG26: =SUM(FG22:FG25) -> 350 | FH26: =SUM(FH22:FH25) -> 0 | ... FJ26: =SUM(FJ22:FJ25) -> 432.5
G27: INFORMATICA
A28: =$G$4 -> JUNIO 2026 2da QUINCENA | B28: =+$G$5 -> 2026 | C28: =A28 & B28 -> JUNIO 2026 2da QUINCENA2026 | D28: =+$G$27 -> INFORMATICA | E28: 104010 | G28: Administracion
