Workbook
Name ECONACIONAL: 'Nomina Econacional'!$A$4:$AB$153
Name Excel_BuiltIn__FilterDatabase: 'boleto de ornato'!#REF!
Name Excel_BuiltIn__FilterDatabase: distribucion!$O$6:$O$236
Name Excel_BuiltIn__FilterDatabase: 'INCREMENTO SALARIO MINIMO '!#REF!
Name Excel_BuiltIn__FilterDatabase: 'RECIBO E IGSS ECONACIONAL'!$B$1:$AB$2
Name Excel_BuiltIn__FilterDatabase: 'RECIBO E IGSS PROQUIMA'!$B$2:$AC$10
Name Excel_BuiltIn__FilterDatabase: 'RECIBO E IGSS UNHESA'!$B$2:$AB$4

Sheet distribucion
B1: 1 | C1: 2 | D1: 3 | E1: 4 | F1: 5 | G1: 6 | H1: 7 | I1: 8 | J1: 9 | K1: 10 | L1: 11 | M1: 12 | N1: 13 | O1: 14 | P1: 15 | Q1: 16 | R1: 17 | S1: 18 | T1: 19 | U1: 20 | V1: 21 | W1: 22 | X1: 23 | Y1: 24 | Z1: 25 | AA1: 26 | AB1: 27 | AC1: 28 | AD1: 29 | AE1: 30 | AF1: 31 | AG1: 32 | AH1: 33 | AI1: 34 | AJ1: 35 | AK1: 36 | AL1: 37 | AM1: 38 | AN1: 39 | AO1: 40 | AP1: 41 | AQ1: 42 | AR1: 43 | AS1: 44 | AT1: 45 | AU1: 46 | AV1: 47 | AW1: 48 | AX1: 49 | AY1: 50 | AZ1: 51 | BA1: 52 | BB1: 53 | BC1: 54 | BD1: 55 | BE1: 56 | BF1: 57 | BG1: 58 | BH1: 59 | BI1: 60 | BJ1: 61 | BK1: 62 | BL1: 63 | BM1: 64 | BN1: 65 | BO1: 66 | BP1: 67 | BQ1: 68 | BR1: 69 | BS1: 70 | BT1: 71 | BU1: 72 | BV1: 73 | BW1: 74 | BX1: 75 | BY1: 76 | BZ1: 77 | CA1: 78 | CB1: 79 | CC1: 80 | CD1: 81 | CE1: 82 | CF1: 83 | CG1: 84 | CH1: 85 | CI1: 86 | CJ1: 87 | CK1: 88 | CL1: 89 | CM1: 90 | CN1: 91 | CO1: 92 | CP1: 93 | CQ1: 94 | CR1: 95 | CS1: 96 | CT1: 97 | CU1: 98 | CV1: 99 | CW1: 100 | CX1: 101 | CY1: 102 | CZ1: 103 | DA1: 104 | DB1: 105 | DC1: 106 | DD1: 107 | DE1: 108 | DF1: 109 | DG1: 110 | DH1: 111 | DI1: 112 | DJ1: 113 | DK1: 114 | DL1: 115 | DM1: 116 | DN1: 117 | DO1: 118 | DP1: 119 | DQ1: 120 | DR1: 121 | DS1: 122 | DT1: 123 | DU1: 124 | DV1: 125 | DW1: 126 | DX1: 127 | DY1: 128 | DZ1: 129 | EA1: 130 | EB1: 131 | EC1: 132 | ED1: 133 | EE1: 134 | EF1: 135 | EG1: 136 | EH1: 137 | EI1: 138 | EJ1: 139 | EK1: 140 | EL1: 141 | EM1: 142 | EN1: 143 | EO1: 144 | EP1: 145 | EQ1: 146 | ER1: 147 | ES1: 148 | ET1: 149 | EU1: 150 | EV1: 151 | EW1: 152 | EX1: 153 | EY1: 154 | EZ1: 155 | FA1: 156 | FB1: 157 | FC1: 158 | FD1: 159 | FE1: 160
B2: DISTRIBUCION DE PERSONAL Y COSTO POR EMPRESA
B3: NOMINA MES DE: ENERO 2,023 2da Quincena) | M3: .
AV4: NOMINAS SEGÚN DISTRIBUCION REAL | CQ4: NOMINAS SEGÚN DISTRIBUCION CONTABILIDAD
E5: 5 | F5: 6 | P5: HORAS EXTRAS PROQUIMA | T5: HORAS EXTRAS UNHESA | X5: HORAS EXTRAS UNHESA LIQUIDOS | AB5: HORAS EXTRAS ECONACIONAL | AF5: HORAS EXTRAS PROQUIMA MAQUILA | AJ5: Otros Ingresos | AO5: Comisiones | AV5: PROQUIMA | BE5: UNHESA | BN5: UNHESA LIQUIDOS | BW5: ECONACIONAL | CF5: ECOMEZCLAS | CQ5: PROQUIMA | CZ5: UNHESA | DI5: UNHESA LIQUIDOS | DR5: ECONACIONAL | EA5: ECOMEZCLAS | FF5: DISTRIBUCION REAL
D6: DISTRIBUCION DE EMPLEADOS | P6: H.E. Simples | Q6: H.E. Simples | R6: H.E. Dobles | S6: H.E. Dobles | T6: H.E. Simples | U6: H.E. Simples | V6: H.E. Dobles | W6: H.E. Dobles | X6: H.E. Simples | Y6: H.E. Simples | Z6: H.E. Dobles | AA6: H.E. Dobles | AB6: H.E. Simples | AC6: H.E. Simples | AD6: H.E. Dobles | AE6: H.E. Dobles | AF6: H.E. Simples | AG6: H.E. Simples | AH6: H.E. Dobles | AI6: H.E. Dobles | AJ6: Proquima | AK6: Unhesa | AL6: Calidul | AM6: Econacional | AN6: Cleartec | AO6: Proquima | AP6: Unhesa | AQ6: Calidul | AR6: Econacional | AS6: Cleartec | AT6: Otrros ingresos | AU6: 0 | AV6: Salario | AW6: Bono | AX6: cantidad | AY6: Hrs. Extra | AZ6: cantidad | BA6: Hrs. Extra | BB6: Comis / | BC6: Cuota | BD6: Total | BE6: Salario | BF6: Bono | BG6: cantidad | BH6: Hrs. Extra | BI6: cantidad | BJ6: Hrs. Extra | BK6: Comis / | BL6: Cuota | BM6: Total | BN6: Salario | BO6: Bono | BP6: cantidad | BQ6: Hrs. Extra | BR6: cantidad | BS6: Hrs. Extra | BT6: Comis / | BU6: Cuota | BV6: Total | BW6: Salario | BX6: Bono | BY6: cantidad | BZ6: Hrs. Extra | CA6: cantidad | CB6: Hrs. Extra | CC6: Comis / | CD6: Cuota | CE6: Total | CF6: Salario | CG6: Bono | CH6: cantidad | CI6: Hrs. Extra | CJ6: cantidad | CK6: Hrs. Extra | CL6: Comis / | CM6: Cuota | CN6: Total | CP6: Nueva | CQ6: Salario | CR6: Bono | CS6: cantidad | CT6: Hrs. Extra | CU6: cantidad | CV6: Hrs. Extra | CW6: Comis / | CX6: Cuota | CY6: Total | CZ6: Salario | DA6: Bono | DB6: cantidad | DC6: Hrs. Extra | DD6: cantidad | DE6: Hrs. Extra | DF6: Comis / | DG6: Cuota | DH6: Total | DI6: Salario | DJ6: Bono | DK6: cantidad | DL6: Hrs. Extra | DM6: cantidad | DN6: Hrs. Extra | DO6: Comis / | DP6: Cuota | DQ6: Total | DR6: Salario | DS6: Bono | DT6: cantidad | DU6: Hrs. Extra | DV6: cantidad | DW6: Hrs. Extra | DX6: Comis / | DY6: Cuota | DZ6: Total | EA6: Salario | EB6: Bono | EC6: cantidad | ED6: Hrs. Extra | EE6: cantidad | EF6: Hrs. Extra | EG6: Comis / | EH6: Cuota | EI6: Total | EK6: EGRESOS MENSUALES | EV6: EGRESOS | FF6: % | FG6: % | FH6: % | FI6: % | FJ6: % | FK6: %
B7: Nombre | C7: Puesto | D7: Empresa Real | E7: Salario Ordinario | F7: Bono Decreto | G7: Total | H7: Días Laborados | I7: % Proquima | J7: % Unhesa | K7: % Unhesa Liq. | L7: % Econacional | M7: % Ecomezclas | N7: Total % Distribución | O7: Observaciones | P7: Cantidad | Q7: Valor | R7: Cantidad | S7: Valor | T7: Cantidad | U7: Valor | V7: Cantidad | W7: Valor | X7: Cantidad | Y7: Valor | Z7: Cantidad | AA7: Valor | AB7: Cantidad | AC7: Valor | AD7: Cantidad | AE7: Valor | AF7: Cantidad | AG7: Valor | AH7: Cantidad | AI7: Valor | AV7: Ordinario | AW7: Decreto | AX7: simples | AY7: simples | AZ7: dobles | BA7: dobles | BB7: Otros | BC7: Patronal | BE7: Ordinario | BF7: Decreto | BG7: simples | BH7: simples | BI7: dobles | BJ7: dobles | BK7: Otros | BL7: Patronal | BN7: Ordinario | BO7: Decreto | BP7: simples | BQ7: simples | BR7: dobles | BS7: dobles | BT7: Otros | BU7: Patronal | BW7: Ordinario | BX7: Decreto | BY7: simples | BZ7: simples | CA7: dobles | CB7: dobles | CC7: Otros | CD7: Patronal | CF7: Ordinario | CG7: Decreto | CH7: simples | CI7: simples | CJ7: dobles | CK7: dobles | CL7: Otros | CM7: Patronal | CP7: Empresa | CQ7: Ordinario | CR7: Decreto | CS7: simples | CT7: simples | CU7: dobles | CV7: dobles | CW7: Otros | CX7: Patronal | CZ7: Ordinario | DA7: Decreto | DB7: simples | DC7: simples | DD7: dobles | DE7: dobles | DF7: Otros | DG7: Patronal | DI7: Ordinario | DJ7: Decreto | DK7: simples | DL7: simples | DM7: dobles | DN7: dobles | DO7: Otros | DP7: Patronal | DR7: Ordinario | DS7: Decreto | DT7: simples | DU7: simples | DV7: dobles | DW7: dobles | DX7: Otros | DY7: Patronal | EA7: Ordinario | EB7: Decreto | EC7: simples | ED7: simples | EE7: dobles | EF7: dobles | EG7: Otros | EH7: Patronal | EK7: ISR | EL7: BANCOS | EM7: CELULAR | EN7: CAFETERIA | EO7: DESCUENTO producto | EP7: SEGURO/BOLETO ORNATO | EQ7: Otros Descuentos | ER7: CALZADO | ES7: UNIFORME | ET7: TOTAL EGRESOS Bol Ornato, Seguro, Otros | EV7: ISR | EW7: BANCOS | EX7: CELULAR | EY7: CAFETERIA | EZ7: DESCUENTO PRODUCTO | FA7: SEGURO | FB7: Otros Descuentos | FC7: CALZADO | FD7: UNIFORME | FE7: OTROS EGRESOS | FF7: % Proquima | FG7: % Unhesa | FH7: % Unhesa Liq. | FI7: % Econacional | FJ7: % Ecomezclas | FK7: Total % Distribución
B8: AREA ADMINISTRATIVA | FI8: cional
B9: PRESIDENCIA
A10: 1 | B10: Estrada Robles Victor Gerardo | C10: Presidente | D10: UNHESA | E10: 19750 | F10: 250 | G10: =+E10+F10 -> 20000 | H10: 30 | I10: 0 | J10: 1 | K10: 0 | L10: 0 | M10: 0 | N10: =SUM(I10:M10) -> 1 | Q10: =($E10/30/8*1.5)*P10 -> 0 | S10: 0 | U10: =($E10/30/8*1.5)*T10 -> 0 | W10: =($E10/30/8*2)*V10 -> 0 | Y10: =(($E10/30/8)*1.5)*X10 -> 0 | AA10: =(($E10/30/8)*2)*Z10 -> 0 | AC10: =(($E10/30/8)*1.5)*AB10 -> 0 | AE10: =(($E10/30/8)*2)*AD10 -> 0 | AG10: =(($E10/30/8)*1.5)*AF10 -> 0 | AI10: =(($E10/30/8)*2)*AH10 -> 0 | AV10: =(($E10/30)*$H10)*$I10 -> 0 | AW10: =(($F10/30)*$H10)*$I10 -> 0 | AX10: =P10 -> 0 | AY10: =Q10 -> 0 | AZ10: =R10 -> 0 | BA10: =S10 -> 0 | BB10: =AJ10+AO10 -> 0 | BC10: =(AV10+AY10+BA10)*0.1267 -> 0 | BD10: =SUM(AV10:BC10)-AX10-AZ10 -> 0 | BE10: =(($E10/30)*$H10)*$J10 -> 19750 | BF10: =(($F10/30)*$H10)*$J10 -> 250 | BG10: =T10 -> 0 | BH10: =U10 -> 0 | BI10: =V10 -> 0 | BJ10: =W10 -> 0 | BK10: =AK10+AP10 -> 0 | BL10: 0 | BM10: =SUM(BE10:BL10)-BG10-BI10 -> 20000 | BN10: =(($E10/30)*$H10)*$K10 -> 0 | BO10: =(($F10/30)*$H10)*$K10 -> 0 | BP10: =X10 -> 0 | BQ10: =Y10 -> 0 | BR10: =Z10 -> 0 | BS10: =AA10 -> 0 | BT10: =AL10+AQ10 -> 0 | BU10: 0 | BV10: =SUM(BN10:BU10)-BP10-BR10 -> 0 | BW10: =(($E10/30)*$H10)*$L10 -> 0 | BX10: =(($F10/30)*$H10)*$L10 -> 0 | BY10: =AB10 -> 0 | BZ10: =AC10 -> 0 | CA10: =AD10 -> 0 | CB10: =AE10 -> 0 | CC10: =AM10+AR10 -> 0 | CD10: =(BW10+BZ10+CB10)*0.1267 -> 0 | CE10: =SUM(BW10:CD10)-BY10-CA10 -> 0 | CF10: =(($E10/30)*$H10)*M10 -> 0 | CG10: =(($F10/30)*$H10)*$M10 -> 0 | CH10: =+AF10 -> 0 | CI10: =AG10 -> 0 | CJ10: =AH10 -> 0 | CK10: =AI10 -> 0 | CL10: =AN10+AS10 -> 0 | CM10: =(CF10+CI10+CK10)*0.1267 -> 0 | CN10: =SUM(CF10:CM10)-CH10-CJ10 -> 0 | CP10: UNHESA | CQ10: =IF($CP10="PROQUIMA",$AV10+$BE10+$BN10+$BW10+$CF10,0) -> 0 | CR10: =IF($CP10="PROQUIMA",$AW10+$BF10+$BO10+$BX10+$CG10,0) -> 0 | CS10: =IF($CP10="PROQUIMA",$AX10+$BG10+$BP10+$BY10+$CH10,0) -> 0 | CT10: =IF($CP10="PROQUIMA",$AY10+$BH10+$BQ10+$BZ10+$CI10,0) -> 0 | CU10: =IF($CP10="PROQUIMA",$AZ10+$BI10+$BR10+$CA10+$CJ10,0) -> 0 | CV10: =IF($CP10="PROQUIMA",$BA10+$BJ10+$BS10+$CB10+$CK10,0) -> 0 | CW10: =IF($CP10="PROQUIMA",$BB10+$BK10+$BT10+$CC10+$CL10,0) -> 0 | CX10: =IF($CP10="PROQUIMA",$BC10+$BL10+$BU10+$CD10+CM10,0) -> 0 | CY10: =SUM(CQ10:CX10)-CS10-CU10 -> 0 | CZ10: =IF($CP10="UNHESA",$AV10+$BE10+$BN10+$BW10+$CF10,0) -> 19750 | DA10: =IF($CP10="UNHESA",$AW10+$BF10+$BO10+$BX10+$CG10,0) -> 250 | DB10: =IF($CP10="UNHESA",$AX10+$BG10+$BP10+$BY10+$CH10,0) -> 0 | DC10: =IF($CP10="UNHESA",$AY10+$BH10+$BQ10+$BZ10+$CI10,0) -> 0 | DD10: =IF($CP10="UNHESA",$AZ10+$BI10+$BR10+$CA10+$CJ10,0) -> 0 | DE10: =IF($CP10="UNHESA",$BA10+$BJ10+$BS10+$CB10+$CK10,0) -> 0 | DF10: =IF($CP10="UNHESA",$BB10+$BK10+$BT10+$CC10+$CL10,0) -> 0 | DG10: =IF($CP10="UNHESA",$BC10+$BL10+$BU10+$CD10+$CM10,0) -> 0 | DH10: =SUM(CZ10:DG10)-DB10-DD10 -> 20000 | DI10: =IF($CP10="UNHESA LIQUIDOS",$AV10+$BE10+$BN10+$BW10+$CF10,0) -> 0 | DJ10: =IF($CP10="CALIDUL",$AW10+$BF10+$BO10+$BX10+$CG10,0) -> 0 | DK10: =IF($CP10="CALIDUL",$AX10+$BG10+$BP10+$BY10+$CH10,0) -> 0 | DL10: =IF($CP10="CALIDUL",$AY10+$BH10+$BQ10+$BZ10+$CI10,0) -> 0 | DM10: =IF($CP10="CALIDUL",$AZ10+$BI10+$BR10+$CA10+$CJ10,0) -> 0 | DN10: =IF($CP10="CALIDUL",$BA10+$BJ10+$BS10+$CB10+$CK10,0) -> 0 | DO10: =IF($CP10="CALIDUL",$BB10+$BK10+$BT10+$CC10+$CL10,0) -> 0 | DP10: =IF($CP10="CALIDUL",$BC10+$BL10+$BU10+$CD10+$CM10,0) -> 0 | DQ10: =SUM(DI10:DP10)-DK10-DM10 -> 0 | DR10: =IF($CP10="ECONACIONAL",$AV10+$BE10+$BN10+$BW10+$CF10,0) -> 0 | DS10: =IF($CP10="ECONACIONAL",$AW10+$BF10+$BO10+$BX10+$CG10,0) -> 0 | DT10: =IF($CP10="ECONACIONAL",$AX10+$BG10+$BP10+$BY10+$CH10,0) -> 0 | DU10: =IF($CP10="ECONACIONAL",$AY10+$BH10+$BQ10+$BZ10+$CI10,0) -> 0 | DV10: =IF($CP10="ECONACIONAL",$AZ10+$BI10+$BR10+$CA10+$CJ10,0) -> 0 | DW10: =IF($CP10="ECONACIONAL",$BA10+$BJ10+$BS10+$CB10+$CK10,0) -> 0 | DX10: =IF($CP10="ECONACIONAL",$BB10+$BK10+$BT10+$CC10+$CL10,0) -> 0 | DY10: =IF($CP10="ECONACIONAL",$BC10+$BL10+$BU10+$CD10+$CM10,0) -> 0 | DZ10: =SUM(DR10:DY10)-DT10-DV10 -> 0 | EA10: =IF($CP10="CLEARTEC",$AV10+$BE10+$BN10+$BW10+$CF10,0) -> 0 | EB10: =IF($CP10="CLEARTEC",$AW10+$BF10+$BO10+$BX10+$CG10,0) -> 0 | EC10: =IF($CP10="CLEARTEC",$AX10+$BG10+$BP10+$BY10+$CH10,0) -> 0 | ED10: =IF($CP10="CLEARTEC",$AY10+$BH10+$BQ10+$BZ10+$CI10,0) -> 0 | EE10: =IF($CP10="CLEARTEC",$AZ10+$BI10+$BR10+$CA10+$CJ10,0) -> 0 | EF10: =IF($CP10="CLEARTEC",$BA10+$BJ10+$BS10+$CB10+$CK10,0) -> 0 | EG10: =IF($CP10="CLEARTEC",$BB10+$BK10+$BT10+$CC10+$CL10,0) -> 0 | EH10: =IF($CP10="CLEARTEC",$BC10+$BL10+$BU10+$CD10+$CM10,0) -> 0 | EI10: =SUM(EA10:EH10)-EC10-EE10 -> 0 | ET10: =+EO10+EP10+EQ10 -> 0 | EV10: =IF($H10<=15,EK10/2,EK10) -> 0 | EW10: =IF($H10<=15,EL10/2,EL10) -> 0 | EX10: =IF($H10<=15,EM10/2,EM10) -> 0 | EY10: =IF($H10<=15,EN10/2,EN10) -> 0 | EZ10: =IF($H10<=15,EO10/2,EO10) -> 0 | FA10: =IF($H10<=15,EP10/2,EP10) -> 0 | FB10: =IF($H10<=15,EQ10/2,EQ10) -> 0 | FC10: =IF($H10<=15,ER10/2,ER10) -> 0 | ... FE10: =IF($H10<=15,ET10/2,ET10) -> 0 | FF10: 0 | FG10: 1 | FH10: 0 | FI10: 0 | FJ10: 0 | FK10: 1 | FL10: =+EP10-FA10 -> 0
A11: =+A10+1 -> 2 | B11: Estrada Robles Victor Gerardo1 | C11: Gerente General | D11: PROQUIMA | E11: 61000 | F11: 250 | G11: =+E11+F11 -> 61250 | H11: 30 | I11: 1 | J11: 0 | K11: 0 | L11: 0 | M11: 0 | N11: =SUM(I11:M11) -> 1 | Q11: =($E11/30/8*1.5)*P11 -> 0 | S11: =($E11/30/8*2)*R11 -> 0 | U11: =($E11/30/8*1.5)*T11 -> 0 | W11: =($E11/30/8*2)*V11 -> 0 | Y11: =(($E11/30/8)*1.5)*X11 -> 0 | AA11: =(($E11/30/8)*2)*Z11 -> 0 | AC11: =(($E11/30/8)*1.5)*AB11 -> 0 | AE11: =(($E11/30/8)*2)*AD11 -> 0 | AG11: =(($E11/30/8)*1.5)*AF11 -> 0 | AI11: =(($E11/30/8)*2)*AH11 -> 0 | AV11: =(($E11/30)*$H11)*$I11 -> 61000 | AW11: =(($F11/30)*$H11)*$I11 -> 250 | AX11: =P11 -> 0 | AY11: =Q11 -> 0 | AZ11: =R11 -> 0 | BA11: =S11 -> 0 | BB11: =AJ11+AO11 -> 0 | BC11: =(AV11+AY11+BA11)*0.1267 -> 7728.7 | BD11: =SUM(AV11:BC11)-AX11-AZ11 -> 68978.7 | BE11: =(($E11/30)*$H11)*$J11 -> 0 | BF11: =(($F11/30)*$H11)*$J11 -> 0 | BG11: =T11 -> 0 | BH11: =U11 -> 0 | BI11: =V11 -> 0 | BJ11: =W11 -> 0 | BK11: =AK11+AP11 -> 0 | BL11: 0 | BM11: =SUM(BE11:BL11)-BG11-BI11 -> 0 | BN11: =(($E11/30)*$H11)*$K11 -> 0 | BO11: =(($F11/30)*$H11)*$K11 -> 0 | BP11: =X11 -> 0 | BQ11: =Y11 -> 0 | BR11: =Z11 -> 0 | BS11: =AA11 -> 0 | BT11: =AL11+AQ11 -> 0 | BU11: 0 | BV11: =SUM(BN11:BU11)-BP11-BR11 -> 0 | BW11: =(($E11/30)*$H11)*$L11 -> 0 | BX11: =(($F11/30)*$H11)*$L11 -> 0 | BY11: =AB11 -> 0 | BZ11: =AC11 -> 0 | CA11: =AD11 -> 0 | CB11: =AE11 -> 0 | CC11: =AM11+AR11 -> 0 | CD11: =(BW11+BZ11+CB11)*0.1267 -> 0 | CE11: =SUM(BW11:CD11)-BY11-CA11 -> 0 | CF11: =(($E11/30)*$H11)*M11 -> 0 | CG11: =(($F11/30)*$H11)*$M11 -> 0 | CH11: =+AF11 -> 0 | CI11: =AG11 -> 0 | CJ11: =AH11 -> 0 | CK11: =AI11 -> 0 | CL11: =AN11+AS11 -> 0 | CM11: =(CF11+CI11+CK11)*0.1267 -> 0 | CN11: =SUM(CF11:CM11)-CH11-CJ11 -> 0 | CP11: PROQUIMA | CQ11: =IF($CP11="PROQUIMA",$AV11+$BE11+$BN11+$BW11+$CF11,0) -> 61000 | CR11: =IF($CP11="PROQUIMA",$AW11+$BF11+$BO11+$BX11+$CG11,0) -> 250 | CS11: =IF($CP11="PROQUIMA",$AX11+$BG11+$BP11+$BY11+$CH11,0) -> 0 | CT11: =IF($CP11="PROQUIMA",$AY11+$BH11+$BQ11+$BZ11+$CI11,0) -> 0 | CU11: =IF($CP11="PROQUIMA",$AZ11+$BI11+$BR11+$CA11+$CJ11,0) -> 0 | CV11: =IF($CP11="PROQUIMA",$BA11+$BJ11+$BS11+$CB11+$CK11,0) -> 0 | CW11: =IF($CP11="PROQUIMA",$BB11+$BK11+$BT11+$CC11+$CL11,0) -> 0 | CX11: =IF($CP11="PROQUIMA",$BC11+$BL11+$BU11+$CD11+CM11,0) -> 7728.7 | CY11: =SUM(CQ11:CX11)-CS11-CU11 -> 68978.7 | CZ11: =IF($CP11="UNHESA",$AV11+$BE11+$BN11+$BW11+$CF11,0) -> 0 | DA11: =IF($CP11="UNHESA",$AW11+$BF11+$BO11+$BX11+$CG11,0) -> 0 | DB11: =IF($CP11="UNHESA",$AX11+$BG11+$BP11+$BY11+$CH11,0) -> 0 | DC11: =IF($CP11="UNHESA",$AY11+$BH11+$BQ11+$BZ11+$CI11,0) -> 0 | DD11: =IF($CP11="UNHESA",$AZ11+$BI11+$BR11+$CA11+$CJ11,0) -> 0 | DE11: =IF($CP11="UNHESA",$BA11+$BJ11+$BS11+$CB11+$CK11,0) -> 0 | DF11: =IF($CP11="UNHESA",$BB11+$BK11+$BT11+$CC11+$CL11,0) -> 0 | DG11: =IF($CP11="UNHESA",$BC11+$BL11+$BU11+$CD11+$CM11,0) -> 0 | DH11: =SUM(CZ11:DG11)-DB11-DD11 -> 0 | EK11: 3507.5 | ET11: =+EO11+EP11+EQ11 -> 0 | EV11: =IF($H11<=15,EK11/2,EK11) -> 3507.5 | EW11: =IF($H11<=15,EL11/2,EL11) -> 0 | EX11: =IF($H11<=15,EM11/2,EM11) -> 0 | EY11: =IF($H11<=15,EN11/2,EN11) -> 0 | EZ11: =IF($H11<=15,EO11/2,EO11) -> 0 | FA11: =IF($H11<=15,EP11/2,EP11) -> 0 | FB11: =IF($H11<=15,EQ11/2,EQ11) -> 0 | FC11: =IF($H11<=15,ER11/2,ER11) -> 0 | ... FE11: =IF($H11<=15,ET11/2,ET11) -> 0
A12: =+A11+1 -> 3 | B12: Estrada Robles Juan Pablo | C12: Asesor | D12: PROQUIMA | E12: 15000 | F12: 155000 | G12: =+E12+F12 -> 170000 | H12: 30 | I12: 1 | J12: 0 | K12: 0 | L12: 0 | M12: 0 | N12: =SUM(I12:M12) -> 1 | Q12: =($E12/30/8*1.5)*P12 -> 0 | S12: =($E12/30/8*2)*R12 -> 0 | U12: =($E12/30/8*1.5)*T12 -> 0 | W12: =($E12/30/8*2)*V12 -> 0 | Y12: =(($E12/30/8)*1.5)*X12 -> 0 | AA12: =(($E12/30/8)*2)*Z12 -> 0 | AC12: =(($E12/30/8)*1.5)*AB12 -> 0 | AE12: =(($E12/30/8)*2)*AD12 -> 0 | AG12: =(($E12/30/8)*1.5)*AF12 -> 0 | AI12: =(($E12/30/8)*2)*AH12 -> 0 | AV12: =(($E12/30)*$H12)*$I12 -> 15000 | AW12: =(($F12/30)*$H12)*$I12+10923.87+3645 -> 169568.87 | AX12: =P12 -> 0 | AY12: =Q12 -> 0 | AZ12: =R12 -> 0 | BA12: =S12 -> 0 | BB12: =AJ12+AO12 -> 0 | BC12: =(AV12+AY12+BA12)*0.1267 -> 1900.5 | BD12: =SUM(AV12:BC12)-AX12-AZ12 -> 186469.37 | BE12: =(($E12/30)*$H12)*$J12 -> 0 | BF12: =(($F12/30)*$H12)*$J12 -> 0 | BG12: =T12 -> 0 | BH12: =U12 -> 0 | BI12: =V12 -> 0 | BJ12: =W12 -> 0 | BK12: =AK12+AP12 -> 0 | BL12: 0 | BM12: =SUM(BE12:BL12)-BG12-BI12 -> 0 | BN12: =(($E12/30)*$H12)*$K12 -> 0 | BO12: =(($F12/30)*$H12)*$K12 -> 0 | BP12: =X12 -> 0 | BQ12: =Y12 -> 0 | BR12: =Z12 -> 0 | BS12: =AA12 -> 0 | BT12: =AL12+AQ12 -> 0 | BU12: 0 | BV12: =SUM(BN12:BU12)-BP12-BR12 -> 0 | BW12: =(($E12/30)*$H12)*$L12 -> 0 | BX12: =(($F12/30)*$H12)*$L12 -> 0 | BY12: =AB12 -> 0 | BZ12: =AC12 -> 0 | CA12: =AD12 -> 0 | CB12: =AE12 -> 0 | CC12: =AM12+AR12 -> 0 | CD12: =(BW12+BZ12+CB12)*0.1267 -> 0 | CE12: =SUM(BW12:CD12)-BY12-CA12 -> 0 | CF12: =(($E12/30)*$H12)*M12 -> 0 | CG12: =(($F12/30)*$H12)*$M12 -> 0 | CH12: =+AF12 -> 0 | CI12: =AG12 -> 0 | CJ12: =AH12 -> 0 | CK12: =AI12 -> 0 | CL12: =AN12+AS12 -> 0 | CM12: =(CF12+CI12+CK12)*0.1267 -> 0 | CN12: =SUM(CF12:CM12)-CH12-CJ12 -> 0 | CP12: PROQUIMA | CQ12: =IF($CP12="PROQUIMA",$AV12+$BE12+$BN12+$BW12+$CF12,0) -> 15000 | CR12: =IF($CP12="PROQUIMA",$AW12+$BF12+$BO12+$BX12+$CG12,0) -> 169568.87 | CS12: =IF($CP12="PROQUIMA",$AX12+$BG12+$BP12+$BY12+$CH12,0) -> 0 | CT12: =IF($CP12="PROQUIMA",$AY12+$BH12+$BQ12+$BZ12+$CI12,0) -> 0 | CU12: =IF($CP12="PROQUIMA",$AZ12+$BI12+$BR12+$CA12+$CJ12,0) -> 0 | CV12: =IF($CP12="PROQUIMA",$BA12+$BJ12+$BS12+$CB12+$CK12,0) -> 0 | CW12: =IF($CP12="PROQUIMA",$BB12+$BK12+$BT12+$CC12+$CL12,0) -> 0 | CX12: =IF($CP12="PROQUIMA",$BC12+$BL12+$BU12+$CD12+CM12,0) -> 1900.5 | CY12: =SUM(CQ12:CX12)-CS12-CU12 -> 186469.37 | CZ12: =IF($CP12="UNHESA",$AV12+$BE12+$BN12+$BW12+$CF12,0) -> 0 | DA12: =IF($CP12="UNHESA",$AW12+$BF12+$BO12+$BX12+$CG12,0) -> 0 | DB12: =IF($CP12="UNHESA",$AX12+$BG12+$BP12+$BY12+$CH12,0) -> 0 | DC12: =IF($CP12="UNHESA",$AY12+$BH12+$BQ12+$BZ12+$CI12,0) -> 0 | DD12: =IF($CP12="UNHESA",$AZ12+$BI12+$BR12+$CA12+$CJ12,0) -> 0 | DE12: =IF($CP12="UNHESA",$BA12+$BJ12+$BS12+$CB12+$CK12,0) -> 0 | DF12: =IF($CP12="UNHESA",$BB12+$BK12+$BT12+$CC12+$CL12,0) -> 0 | DG12: =IF($CP12="UNHESA",$BC12+$BL12+$BU12+$CD12+$CM12,0) -> 0 | DH12: =SUM(CZ12:DG12)-DB12-DD12 -> 0 | EK12: 15719.44 | ET12: =+EO12+EP12+EQ12 -> 0 | EV12: =IF($H12<=15,EK12/2,EK12) -> 15719.44 | EW12: =IF($H12<=15,EL12/2,EL12) -> 0 | EX12: =IF($H12<=15,EM12/2,EM12) -> 0 | EY12: =IF($H12<=15,EN12/2,EN12) -> 0 | EZ12: =IF($H12<=15,EO12/2,EO12) -> 0 | FA12: =IF($H12<=15,EP12/2,EP12) -> 0 | FB12: =IF($H12<=15,EQ12/2,EQ12) -> 0 | FC12: =IF($H12<=15,ER12/2,ER12) -> 0 | ... FE12: =IF($H12<=15,ET12/2,ET12) -> 0
A13: =+A12+1 -> 4 | B13: Alvarez Caceros Genesis Arleth | C13: Asistente de Gerencia | D13: PROQUIMA | E13: 3500 | F13: 1500 | G13: =+E13+F13 -> 5000 | H13: 30 | I13: 0.5 | J13: 0.5 | K13: 0 | L13: 0 | M13: 0 | N13: =SUM(I13:M13) -> 1 | Q13: =($E13/30/8*1.5)*P13 -> 0 | S13: =($E13/30/8*2)*R13 -> 0 | U13: =($E13/30/8*1.5)*T13 -> 0 | W13: =($E13/30/8*2)*V13 -> 0 | Y13: =(($E13/30/8)*1.5)*X13 -> 0 | AA13: =(($E13/30/8)*2)*Z13 -> 0 | AC13: =(($E13/30/8)*1.5)*AB13 -> 0 | AD13: 0 | AE13: =(($E13/30/8)*2)*AD13 -> 0 | AG13: =(($E13/30/8)*1.5)*AF13 -> 0 | AI13: =(($E13/30/8)*2)*AH13 -> 0 | AV13: =(($E13/30)*$H13)*$I13 -> 1750 | AW13: =(($F13/30)*$H13)*$I13 -> 750 | AX13: =P13 -> 0 | AY13: =Q13 -> 0 | AZ13: =R13 -> 0 | BA13: =S13 -> 0 | BB13: =AJ13+AO13 -> 0 | BC13: =(AV13+AY13+BA13)*0.1267 -> 221.725 | BD13: =SUM(AV13:BC13)-AX13-AZ13 -> 2721.725 | BE13: =(($E13/30)*$H13)*$J13 -> 1750 | BF13: =(($F13/30)*$H13)*$J13 -> 750 | BG13: =T13 -> 0 | BH13: =U13 -> 0 | BI13: =V13 -> 0 | BJ13: =W13 -> 0 | BK13: =AK13+AP13 -> 0 | BL13: 0 | BM13: =SUM(BE13:BL13)-BG13-BI13 -> 2500 | BN13: =(($E13/30)*$H13)*$K13 -> 0 | BO13: =(($F13/30)*$H13)*$K13 -> 0 | BP13: =X13 -> 0 | BQ13: =Y13 -> 0 | BR13: =Z13 -> 0 | BS13: =AA13 -> 0 | BT13: =AL13+AQ13 -> 0 | BU13: 0 | BV13: =SUM(BN13:BU13)-BP13-BR13 -> 0 | BW13: =(($E13/30)*$H13)*$L13 -> 0 | BX13: =(($F13/30)*$H13)*$L13 -> 0 | BY13: =AB13 -> 0 | BZ13: =AC13 -> 0 | CA13: =AD13 -> 0 | CB13: =AE13 -> 0 | CC13: =AM13+AR13 -> 0 | CD13: =(BW13+BZ13+CB13)*0.1267 -> 0 | CE13: =SUM(BW13:CD13)-BY13-CA13 -> 0 | CF13: =(($E13/30)*$H13)*M13 -> 0 | CG13: =(($F13/30)*$H13)*$M13 -> 0 | CH13: =+AF13 -> 0 | CI13: =AG13 -> 0 | CJ13: =AH13 -> 0 | CK13: =AI13 -> 0 | CL13: =AN13+AS13 -> 0 | CM13: =(CF13+CI13+CK13)*0.1267 -> 0 | CN13: =SUM(CF13:CM13)-CH13-CJ13 -> 0 | CP13: PROQUIMA | CQ13: =IF($CP13="PROQUIMA",$AV13+$BE13+$BN13+$BW13+$CF13,0) -> 3500 | CR13: =IF($CP13="PROQUIMA",$AW13+$BF13+$BO13+$BX13+$CG13,0) -> 1500 | CS13: =IF($CP13="PROQUIMA",$AX13+$BG13+$BP13+$BY13+$CH13,0) -> 0 | CT13: =IF($CP13="PROQUIMA",$AY13+$BH13+$BQ13+$BZ13+$CI13,0) -> 0 | CU13: =IF($CP13="PROQUIMA",$AZ13+$BI13+$BR13+$CA13+$CJ13,0) -> 0 | CV13: =IF($CP13="PROQUIMA",$BA13+$BJ13+$BS13+$CB13+$CK13,0) -> 0 | CW13: =IF($CP13="PROQUIMA",$BB13+$BK13+$BT13+$CC13+$CL13,0) -> 0 | CX13: =IF($CP13="PROQUIMA",$BC13+$BL13+$BU13+$CD13+CM13,0) -> 221.725 | CY13: =SUM(CQ13:CX13)-CS13-CU13 -> 5221.725 | CZ13: =IF($CP13="UNHESA",$AV13+$BE13+$BN13+$BW13+$CF13,0) -> 0 | DA13: =IF($CP13="UNHESA",$AW13+$BF13+$BO13+$BX13+$CG13,0) -> 0 | DB13: =IF($CP13="UNHESA",$AX13+$BG13+$BP13+$BY13+$CH13,0) -> 0 | DC13: =IF($CP13="UNHESA",$AY13+$BH13+$BQ13+$BZ13+$CI13,0) -> 0 | DD13: =IF($CP13="UNHESA",$AZ13+$BI13+$BR13+$CA13+$CJ13,0) -> 0 | DE13: =IF($CP13="UNHESA",$BA13+$BJ13+$BS13+$CB13+$CK13,0) -> 0 | DF13: =IF($CP13="UNHESA",$BB13+$BK13+$BT13+$CC13+$CL13,0) -> 0 | DG13: =IF($CP13="UNHESA",$BC13+$BL13+$BU13+$CD13+$CM13,0) -> 0 | DH13: =SUM(CZ13:DG13)-DB13-DD13 -> 0 | EK13: 41.55 | EN13: 17 | EO13: 165 | EP13: 50 | ET13: =+EO13+EP13+EQ13 -> 215 | EV13: =IF($H13<=15,EK13/2,EK13) -> 41.55 | EW13: =IF($H13<=15,EL13/2,EL13) -> 0 | EX13: =IF($H13<=15,EM13/2,EM13) -> 0 | EY13: =IF($H13<=15,EN13/2,EN13) -> 17 | EZ13: =IF($H13<=15,EO13/2,EO13) -> 165 | FA13: =IF($H13<=15,EP13/2,EP13) -> 50 | FB13: =IF($H13<=15,EQ13/2,EQ13) -> 0 | FC13: =IF($H13<=15,ER13/2,ER13) -> 0 | ... FE13: =IF($H13<=15,ET13/2,ET13) -> 215
A14: =+A13+1 -> 5 | B14: Muñoz Laparra Orly Gabriela | D14: UNHESA | E14: 5000 | F14: 4000 | G14: =+E14+F14 -> 9000 | H14: 30 | I14: 0.35 | J14: 0.35 | K14: 0 | L14: 0.3 | M14: 0 | N14: =SUM(I14:M14) -> 1 | Q14: =($E14/30/8*1.5)*P14 -> 0 | S14: =($E14/30/8*2)*R14 -> 0 | U14: =($E14/30/8*1.5)*T14 -> 0 | W14: =($E14/30/8*2)*V14 -> 0 | Y14: =(($E14/30/8)*1.5)*X14 -> 0 | AA14: =(($E14/30/8)*2)*Z14 -> 0 | AC14: =(($E14/30/8)*1.5)*AB14 -> 0 | AD14: 0 | AE14: =(($E14/30/8)*2)*AD14 -> 0 | AG14: =(($E14/30/8)*1.5)*AF14 -> 0 | AI14: =(($E14/30/8)*2)*AH14 -> 0 | AV14: =(($E14/30)*$H14)*$I14 -> 1750 | AW14: =(($F14/30)*$H14)*$I14 -> 1400 | AX14: =P14 -> 0 | AY14: =Q14 -> 0 | AZ14: =R14 -> 0 | BA14: =S14 -> 0 | BB14: =AJ14+AO14 -> 0 | BC14: =(AV14+AY14+BA14)*0.1267 -> 221.725 | BD14: =SUM(AV14:BC14)-AX14-AZ14 -> 3371.725 | BE14: =(($E14/30)*$H14)*$J14 -> 1750 | BF14: =(($F14/30)*$H14)*$J14 -> 1400 | BG14: =T14 -> 0 | BH14: =U14 -> 0 | BI14: =V14 -> 0 | BJ14: =W14 -> 0 | BK14: =AK14+AP14 -> 0 | BL14: 0 | BM14: =SUM(BE14:BL14)-BG14-BI14 -> 3150 | BN14: =(($E14/30)*$H14)*$K14 -> 0 | BO14: =(($F14/30)*$H14)*$K14 -> 0 | BP14: =X14 -> 0 | BQ14: =Y14 -> 0 | BR14: =Z14 -> 0 | BS14: =AA14 -> 0 | BT14: =AL14+AQ14 -> 0 | BU14: 0 | BV14: =SUM(BN14:BU14)-BP14-BR14 -> 0 | BW14: =(($E14/30)*$H14)*$L14 -> 1500 | BX14: =(($F14/30)*$H14)*$L14 -> 1200 | BY14: =AB14 -> 0 | BZ14: =AC14 -> 0 | CA14: =AD14 -> 0 | CB14: =AE14 -> 0 | CC14: =AM14+AR14 -> 0 | CD14: =(BW14+BZ14+CB14)*0.1267 -> 190.05 | CE14: =SUM(BW14:CD14)-BY14-CA14 -> 2890.05 | CF14: =(($E14/30)*$H14)*M14 -> 0 | CG14: =(($F14/30)*$H14)*$M14 -> 0 | CH14: =+AF14 -> 0 | CI14: =AG14 -> 0 | CJ14: =AH14 -> 0 | CK14: =AI14 -> 0 | CL14: =AN14+AS14 -> 0 | CM14: =(CF14+CI14+CK14)*0.1267 -> 0 | CN14: =SUM(CF14:CM14)-CH14-CJ14 -> 0 | CP14: UNHESA | CQ14: =IF($CP14="PROQUIMA",$AV14+$BE14+$BN14+$BW14+$CF14,0) -> 0 | CR14: =IF($CP14="PROQUIMA",$AW14+$BF14+$BO14+$BX14+$CG14,0) -> 0 | CS14: =IF($CP14="PROQUIMA",$AX14+$BG14+$BP14+$BY14+$CH14,0) -> 0 | CT14: =IF($CP14="PROQUIMA",$AY14+$BH14+$BQ14+$BZ14+$CI14,0) -> 0 | CU14: =IF($CP14="PROQUIMA",$AZ14+$BI14+$BR14+$CA14+$CJ14,0) -> 0 | CV14: =IF($CP14="PROQUIMA",$BA14+$BJ14+$BS14+$CB14+$CK14,0) -> 0 | CW14: =IF($CP14="PROQUIMA",$BB14+$BK14+$BT14+$CC14+$CL14,0) -> 0 | CX14: =IF($CP14="PROQUIMA",$BC14+$BL14+$BU14+$CD14+CM14,0) -> 0 | CY14: =SUM(CQ14:CX14)-CS14-CU14 -> 0 | CZ14: =IF($CP14="UNHESA",$AV14+$BE14+$BN14+$BW14+$CF14,0) -> 5000 | DA14: =IF($CP14="UNHESA",$AW14+$BF14+$BO14+$BX14+$CG14,0) -> 4000 | DB14: =IF($CP14="UNHESA",$AX14+$BG14+$BP14+$BY14+$CH14,0) -> 0 | DC14: =IF($CP14="UNHESA",$AY14+$BH14+$BQ14+$BZ14+$CI14,0) -> 0 | DD14: =IF($CP14="UNHESA",$AZ14+$BI14+$BR14+$CA14+$CJ14,0) -> 0 | DE14: =IF($CP14="UNHESA",$BA14+$BJ14+$BS14+$CB14+$CK14,0) -> 0 | DF14: =IF($CP14="UNHESA",$BB14+$BK14+$BT14+$CC14+$CL14,0) -> 0 | DG14: =IF($CP14="UNHESA",$BC14+$BL14+$BU14+$CD14+$CM14,0) -> 411.775 | DH14: =SUM(CZ14:DG14)-DB14-DD14 -> 9411.775 | EK14: 237.93 | EN14: =27+53 -> 80 | EP14: 75 | EQ14: =240 -> 240 | ET14: =+EO14+EP14+EQ14 -> 315 | EV14: =IF($H14<=15,EK14/2,EK14) -> 237.93 | EW14: =IF($H14<=15,EL14/2,EL14) -> 0 | EX14: =IF($H14<=15,EM14/2,EM14) -> 0 | EY14: =IF($H14<=15,EN14/2,EN14) -> 80 | EZ14: =IF($H14<=15,EO14/2,EO14) -> 0 | FA14: =IF($H14<=15,EP14/2,EP14) -> 75 | FB14: =IF($H14<=15,EQ14/2,EQ14) -> 240 | FC14: =IF($H14<=15,ER14/2,ER14) -> 0 | ... FE14: =IF($H14<=15,ET14/2,ET14) -> 315
A15: =+A14+1 -> 6 | B15: Quevedo Lopez Ingrid Aracely | C15: Conserje | D15: UNHESA | E15: 3166.38 | F15: 250 | G15: =+E15+F15 -> 3416.38 | H15: 30 | I15: 0 | J15: 1 | K15: 0 | L15: 0 | M15: 0 | N15: =SUM(I15:M15) -> 1 | Q15: =($E15/30/8*1.5)*P15 -> 0 | S15: =($E15/30/8*2)*R15 -> 0 | U15: =($E15/30/8*1.5)*T15 -> 0 | W15: =($E15/30/8*2)*V15 -> 0 | Y15: =(($E15/30/8)*1.5)*X15 -> 0 | AA15: =(($E15/30/8)*2)*Z15 -> 0 | AC15: =(($E15/30/8)*1.5)*AB15 -> 0 | AE15: =(($E15/30/8)*2)*AD15 -> 0 | AG15: =(($E15/30/8)*1.5)*AF15 -> 0 | AI15: =(($E15/30/8)*2)*AH15 -> 0 | AV15: =((E15/30)*H15)*$I15 -> 0 | AW15: =((F15/30)*H15)*$I15 -> 0 | AX15: =P15 -> 0 | AY15: =Q15 -> 0 | AZ15: =R15 -> 0 | BA15: =S15 -> 0 | BB15: =AJ15+AO15 -> 0 | BC15: =(AV15+AY15+BA15)*0.1267 -> 0 | BD15: =SUM(AV15:BC15)-AX15-AZ15 -> 0 | BE15: =(($E15/30)*$H15)*$J15 -> 3166.38 | BF15: =(($F15/30)*$H15)*$J15 -> 250 | BG15: =T15 -> 0 | BH15: =U15 -> 0 | BI15: =V15 -> 0 | BJ15: =W15 -> 0 | BK15: =AK15+AP15 -> 0 | BL15: =(+BE15+BH15+BJ15+BK15)*0.1267 -> 401.18035 | BM15: =SUM(BE15:BL15)-BG15-BI15 -> 3817.5603 | BN15: =(($E15/30)*$H15)*$K15 -> 0 | BO15: =(($F15/30)*$H15)*$K15 -> 0 | BP15: =X15 -> 0 | BQ15: =Y15 -> 0 | BR15: =Z15 -> 0 | BS15: =AA15 -> 0 | BT15: =AL15+AQ15 -> 0 | BU15: =(BN15+BQ15+BS15)*0.1267 -> 0 | BV15: =SUM(BN15:BU15)-BP15-BR15 -> 0 | BW15: =(($E15/30)*$H15)*$L15 -> 0 | BX15: =(($F15/30)*$H15)*$L15 -> 0 | BY15: =AB15 -> 0 | BZ15: =AC15 -> 0 | CA15: =AD15 -> 0 | CB15: =AE15 -> 0 | CC15: =AM15+AR15 -> 0 | CD15: =(BW15+BZ15+CB15)*0.1267 -> 0 | CE15: =SUM(BW15:CD15)-BY15-CA15 -> 0 | CF15: =(($E15/30)*$H15)*M15 -> 0 | CG15: =(($F15/30)*$H15)*$M15 -> 0 | CH15: =+AF15 -> 0 | CI15: =AG15 -> 0 | CJ15: =AH15 -> 0 | CK15: =AI15 -> 0 | CL15: =AN15+AS15 -> 0 | CM15: =(CF15+CI15+CK15)*0.1267 -> 0 | CN15: =SUM(CF15:CM15)-CH15-CJ15 -> 0 | CP15: UNHESA | CQ15: =IF($CP15="PROQUIMA",$AV15+$BE15+$BN15+$BW15+$CF15,0) -> 0 | CR15: =IF($CP15="PROQUIMA",$AW15+$BF15+$BO15+$BX15+$CG15,0) -> 0 | CS15: =IF($CP15="PROQUIMA",$AX15+$BG15+$BP15+$BY15+$CH15,0) -> 0 | CT15: =IF($CP15="PROQUIMA",$AY15+$BH15+$BQ15+$BZ15+$CI15,0) -> 0 | CU15: =IF($CP15="PROQUIMA",$AZ15+$BI15+$BR15+$CA15+$CJ15,0) -> 0 | CV15: =IF($CP15="PROQUIMA",$BA15+$BJ15+$BS15+$CB15+$CK15,0) -> 0 | CW15: =IF($CP15="PROQUIMA",$BB15+$BK15+$BT15+$CC15+$CL15,0) -> 0 | CX15: =IF($CP15="PROQUIMA",$BC15+$BL15+$BU15+$CD15+CM15,0) -> 0 | CY15: =SUM(CQ15:CX15)-CS15-CU15 -> 0 | CZ15: =IF($CP15="UNHESA",$AV15+$BE15+$BN15+$BW15+$CF15,0) -> 3166.38 | DA15: =IF($CP15="UNHESA",$AW15+$BF15+$BO15+$BX15+$CG15,0) -> 250 | DB15: =IF($CP15="UNHESA",$AX15+$BG15+$BP15+$BY15+$CH15,0) -> 0 | DC15: =IF($CP15="UNHESA",$AY15+$BH15+$BQ15+$BZ15+$CI15,0) -> 0 | DD15: =IF($CP15="UNHESA",$AZ15+$BI15+$BR15+$CA15+$CJ15,0) -> 0 | DE15: =IF($CP15="UNHESA",$BA15+$BJ15+$BS15+$CB15+$CK15,0) -> 0 | DF15: =IF($CP15="UNHESA",$BB15+$BK15+$BT15+$CC15+$CL15,0) -> 0 | DG15: =IF($CP15="UNHESA",$BC15+$BL15+$BU15+$CD15+$CM15,0) -> 401.18035 | DH15: =SUM(CZ15:DG15)-DB15-DD15 -> 3817.5603 | DI15: =IF($CP15="UNHESA LIQUIDOS",$AV15+$BE15+$BN15+$BW15+$CF15,0) -> 0 | DJ15: =IF($CP15="CALIDUL",$AW15+$BF15+$BO15+$BX15+$CG15,0) -> 0 | DK15: =IF($CP15="CALIDUL",$AX15+$BG15+$BP15+$BY15+$CH15,0) -> 0 | DL15: =IF($CP15="CALIDUL",$AY15+$BH15+$BQ15+$BZ15+$CI15,0) -> 0 | DM15: =IF($CP15="CALIDUL",$AZ15+$BI15+$BR15+$CA15+$CJ15,0) -> 0 | DN15: =IF($CP15="CALIDUL",$BA15+$BJ15+$BS15+$CB15+$CK15,0) -> 0 | DO15: =IF($CP15="CALIDUL",$BB15+$BK15+$BT15+$CC15+$CL15,0) -> 0 | DP15: =IF($CP15="CALIDUL",$BC15+$BL15+$BU15+$CD15+$CM15,0) -> 0 | DQ15: =SUM(DI15:DP15)-DK15-DM15 -> 0 | DR15: =IF($CP15="ECONACIONAL",$AV15+$BE15+$BN15+$BW15+$CF15,0) -> 0 | DS15: =IF($CP15="ECONACIONAL",$AW15+$BF15+$BO15+$BX15+$CG15,0) -> 0 | DT15: =IF($CP15="ECONACIONAL",$AX15+$BG15+$BP15+$BY15+$CH15,0) -> 0 | DU15: =IF($CP15="ECONACIONAL",$AY15+$BH15+$BQ15+$BZ15+$CI15,0) -> 0 | DV15: =IF($CP15="ECONACIONAL",$AZ15+$BI15+$BR15+$CA15+$CJ15,0) -> 0 | DW15: =IF($CP15="ECONACIONAL",$BA15+$BJ15+$BS15+$CB15+$CK15,0) -> 0 | DX15: =IF($CP15="ECONACIONAL",$BB15+$BK15+$BT15+$CC15+$CL15,0) -> 0 | DY15: =IF($CP15="ECONACIONAL",$BC15+$BL15+$BU15+$CD15+$CM15,0) -> 0 | DZ15: =SUM(DR15:DY15)-DT15-DV15 -> 0 | EA15: =IF($CP15="CLEARTEC",$AV15+$BE15+$BN15+$BW15+$CF15,0) -> 0 | EB15: =IF($CP15="CLEARTEC",$AW15+$BF15+$BO15+$BX15+$CG15,0) -> 0 | EC15: =IF($CP15="CLEARTEC",$AX15+$BG15+$BP15+$BY15+$CH15,0) -> 0 | ED15: =IF($CP15="CLEARTEC",$AY15+$BH15+$BQ15+$BZ15+$CI15,0) -> 0 | EE15: =IF($CP15="CLEARTEC",$AZ15+$BI15+$BR15+$CA15+$CJ15,0) -> 0 | EF15: =IF($CP15="CLEARTEC",$BA15+$BJ15+$BS15+$CB15+$CK15,0) -> 0 | EG15: =IF($CP15="CLEARTEC",$BB15+$BK15+$BT15+$CC15+$CL15,0) -> 0 | EH15: =IF($CP15="CLEARTEC",$BC15+$BL15+$BU15+$CD15+$CM15,0) -> 0 | EI15: =SUM(EA15:EH15)-EC15-EE15 -> 0 | EP15: 50 | ET15: =+EO15+EP15+EQ15 -> 50 | EV15: =IF($H15<=15,EK15/2,EK15) -> 0 | EW15: =IF($H15<=15,EL15/2,EL15) -> 0 | EX15: =IF($H15<=15,EM15/2,EM15) -> 0 | EY15: =IF($H15<=15,EN15/2,EN15) -> 0 | EZ15: =IF($H15<=15,EO15/2,EO15) -> 0 | FA15: =IF($H15<=15,EP15/2,EP15) -> 50 | FB15: =IF($H15<=15,EQ15/2,EQ15) -> 0 | FC15: =IF($H15<=15,ER15/2,ER15) -> 0 | ... FE15: =IF($H15<=15,ET15/2,ET15) -> 50
A16: =+A15+1 -> 7 | B16: Morales Alvarez Yony | C16: Conserje | D16: UNHESA | E16: 3166.38 | F16: 250 | G16: =+E16+F16 -> 3416.38 | H16: 30 | I16: 0 | J16: 1 | K16: 0 | L16: 0 | M16: 0 | N16: =SUM(I16:M16) -> 1 | Q16: =($E16/30/8*1.5)*P16 -> 0 | S16: =($E16/30/8*2)*R16 -> 0 | U16: =($E16/30/8*1.5)*T16 -> 0 | W16: =($E16/30/8*2)*V16 -> 0 | Y16: =(($E16/30/8)*1.5)*X16 -> 0 | AA16: =(($E16/30/8)*2)*Z16 -> 0 | AC16: =(($E16/30/8)*1.5)*AB16 -> 0 | AE16: =(($E16/30/8)*2)*AD16 -> 0 | AG16: =(($E16/30/8)*1.5)*AF16 -> 0 | AI16: =(($E16/30/8)*2)*AH16 -> 0 | AV16: =((E16/30)*H16)*$I16 -> 0 | AW16: =((F16/30)*H16)*$I16 -> 0 | AX16: =P16 -> 0 | AY16: =Q16 -> 0 | AZ16: =R16 -> 0 | BA16: =S16 -> 0 | BB16: =AJ16+AO16 -> 0 | BC16: =(AV16+AY16+BA16)*0.1267 -> 0 | BD16: =SUM(AV16:BC16)-AX16-AZ16 -> 0 | BE16: =(($E16/30)*$H16)*$J16 -> 3166.38 | BF16: =(($F16/30)*$H16)*$J16 -> 250 | BG16: =T16 -> 0 | BH16: =U16 -> 0 | BI16: =V16 -> 0 | BJ16: =W16 -> 0 | BK16: =AK16+AP16 -> 0 | BL16: =(+BE16+BH16+BJ16+BK16)*0.1267 -> 401.18035 | BM16: =SUM(BE16:BL16)-BG16-BI16 -> 3817.5603 | BN16: =(($E16/30)*$H16)*$K16 -> 0 | BO16: =(($F16/30)*$H16)*$K16 -> 0 | BP16: =X16 -> 0 | BQ16: =Y16 -> 0 | BR16: =Z16 -> 0 | BS16: =AA16 -> 0 | BT16: =AL16+AQ16 -> 0 | BU16: =(BN16+BQ16+BS16)*0.1267 -> 0 | BV16: =SUM(BN16:BU16)-BP16-BR16 -> 0 | BW16: =(($E16/30)*$H16)*$L16 -> 0 | BX16: =(($F16/30)*$H16)*$L16 -> 0 | BY16: =AB16 -> 0 | BZ16: =AC16 -> 0 | CA16: =AD16 -> 0 | CB16: =AE16 -> 0 | CC16: =AM16+AR16 -> 0 | CD16: =(BW16+BZ16+CB16)*0.1267 -> 0 | CE16: =SUM(BW16:CD16)-BY16-CA16 -> 0 | CF16: =(($E16/30)*$H16)*M16 -> 0 | CG16: =(($F16/30)*$H16)*$M16 -> 0 | CH16: =+AF16 -> 0 | CI16: =AG16 -> 0 | CJ16: =AH16 -> 0 | CK16: =AI16 -> 0 | CL16: =AN16+AS16 -> 0 | CM16: =(CF16+CI16+CK16)*0.1267 -> 0 | CN16: =SUM(CF16:CM16)-CH16-CJ16 -> 0 | CP16: UNHESA | CQ16: =IF($CP16="PROQUIMA",$AV16+$BE16+$BN16+$BW16+$CF16,0) -> 0 | CR16: =IF($CP16="PROQUIMA",$AW16+$BF16+$BO16+$BX16+$CG16,0) -> 0 | CS16: =IF($CP16="PROQUIMA",$AX16+$BG16+$BP16+$BY16+$CH16,0) -> 0 | CT16: =IF($CP16="PROQUIMA",$AY16+$BH16+$BQ16+$BZ16+$CI16,0) -> 0 | CU16: =IF($CP16="PROQUIMA",$AZ16+$BI16+$BR16+$CA16+$CJ16,0) -> 0 | CV16: =IF($CP16="PROQUIMA",$BA16+$BJ16+$BS16+$CB16+$CK16,0) -> 0 | CW16: =IF($CP16="PROQUIMA",$BB16+$BK16+$BT16+$CC16+$CL16,0) -> 0 | CX16: =IF($CP16="PROQUIMA",$BC16+$BL16+$BU16+$CD16+CM16,0) -> 0 | CY16: =SUM(CQ16:CX16)-CS16-CU16 -> 0 | CZ16: =IF($CP16="UNHESA",$AV16+$BE16+$BN16+$BW16+$CF16,0) -> 3166.38 | DA16: =IF($CP16="UNHESA",$AW16+$BF16+$BO16+$BX16+$CG16,0) -> 250 | DB16: =IF($CP16="UNHESA",$AX16+$BG16+$BP16+$BY16+$CH16,0) -> 0 | DC16: =IF($CP16="UNHESA",$AY16+$BH16+$BQ16+$BZ16+$CI16,0) -> 0 | DD16: =IF($CP16="UNHESA",$AZ16+$BI16+$BR16+$CA16+$CJ16,0) -> 0 | DE16: =IF($CP16="UNHESA",$BA16+$BJ16+$BS16+$CB16+$CK16,0) -> 0 | DF16: =IF($CP16="UNHESA",$BB16+$BK16+$BT16+$CC16+$CL16,0) -> 0 | DG16: =IF($CP16="UNHESA",$BC16+$BL16+$BU16+$CD16+$CM16,0) -> 401.18035 | DH16: =SUM(CZ16:DG16)-DB16-DD16 -> 3817.5603 | DI16: =IF($CP16="UNHESA LIQUIDOS",$AV16+$BE16+$BN16+$BW16+$CF16,0) -> 0 | DJ16: =IF($CP16="CALIDUL",$AW16+$BF16+$BO16+$BX16+$CG16,0) -> 0 | DK16: =IF($CP16="CALIDUL",$AX16+$BG16+$BP16+$BY16+$CH16,0) -> 0 | DL16: =IF($CP16="CALIDUL",$AY16+$BH16+$BQ16+$BZ16+$CI16,0) -> 0 | DM16: =IF($CP16="CALIDUL",$AZ16+$BI16+$BR16+$CA16+$CJ16,0) -> 0 | DN16: =IF($CP16="CALIDUL",$BA16+$BJ16+$BS16+$CB16+$CK16,0) -> 0 | DO16: =IF($CP16="CALIDUL",$BB16+$BK16+$BT16+$CC16+$CL16,0) -> 0 | DP16: =IF($CP16="CALIDUL",$BC16+$BL16+$BU16+$CD16+$CM16,0) -> 0 | DQ16: =SUM(DI16:DP16)-DK16-DM16 -> 0 | DR16: =IF($CP16="ECONACIONAL",$AV16+$BE16+$BN16+$BW16+$CF16,0) -> 0 | DS16: =IF($CP16="ECONACIONAL",$AW16+$BF16+$BO16+$BX16+$CG16,0) -> 0 | DT16: =IF($CP16="ECONACIONAL",$AX16+$BG16+$BP16+$BY16+$CH16,0) -> 0 | DU16: =IF($CP16="ECONACIONAL",$AY16+$BH16+$BQ16+$BZ16+$CI16,0) -> 0 | DV16: =IF($CP16="ECONACIONAL",$AZ16+$BI16+$BR16+$CA16+$CJ16,0) -> 0 | DW16: =IF($CP16="ECONACIONAL",$BA16+$BJ16+$BS16+$CB16+$CK16,0) -> 0 | DX16: =IF($CP16="ECONACIONAL",$BB16+$BK16+$BT16+$CC16+$CL16,0) -> 0 | DY16: =IF($CP16="ECONACIONAL",$BC16+$BL16+$BU16+$CD16+$CM16,0) -> 0 | DZ16: =SUM(DR16:DY16)-DT16-DV16 -> 0 | EA16: =IF($CP16="CLEARTEC",$AV16+$BE16+$BN16+$BW16+$CF16,0) -> 0 | EB16: =IF($CP16="CLEARTEC",$AW16+$BF16+$BO16+$BX16+$CG16,0) -> 0 | EC16: =IF($CP16="CLEARTEC",$AX16+$BG16+$BP16+$BY16+$CH16,0) -> 0 | ED16: =IF($CP16="CLEARTEC",$AY16+$BH16+$BQ16+$BZ16+$CI16,0) -> 0 | EE16: =IF($CP16="CLEARTEC",$AZ16+$BI16+$BR16+$CA16+$CJ16,0) -> 0 | EF16: =IF($CP16="CLEARTEC",$BA16+$BJ16+$BS16+$CB16+$CK16,0) -> 0 | EG16: =IF($CP16="CLEARTEC",$BB16+$BK16+$BT16+$CC16+$CL16,0) -> 0 | EH16: =IF($CP16="CLEARTEC",$BC16+$BL16+$BU16+$CD16+$CM16,0) -> 0 | EI16: =SUM(EA16:EH16)-EC16-EE16 -> 0 | EP16: 50 | ET16: =+EO16+EP16+EQ16 -> 50 | EV16: =IF($H16<=15,EK16/2,EK16) -> 0 | EW16: =IF($H16<=15,EL16/2,EL16) -> 0 | EX16: =IF($H16<=15,EM16/2,EM16) -> 0 | EY16: =IF($H16<=15,EN16/2,EN16) -> 0 | EZ16: =IF($H16<=15,EO16/2,EO16) -> 0 | FA16: =IF($H16<=15,EP16/2,EP16) -> 50 | FB16: =IF($H16<=15,EQ16/2,EQ16) -> 0 | FC16: =IF($H16<=15,ER16/2,ER16) -> 0 | ... FE16: =IF($H16<=15,ET16/2,ET16) -> 50
A17: =+A16+1 -> 8 | B17: Veliz Carias Elder Danilo | C17: Piloto | D17: UNHESA | E17: 3166.38 | F17: 250 | G17: =+E17+F17 -> 3416.38 | H17: 30 | I17: 0 | J17: 1 | K17: 0 | L17: 0 | M17: 0 | N17: =SUM(I17:M17) -> 1 | Q17: =($E17/30/8*1.5)*P17 -> 0 | S17: =($E17/30/8*2)*R17 -> 0 | U17: =($E17/30/8*1.5)*T17 -> 0 | W17: =($E17/30/8*2)*V17 -> 0 | Y17: =(($E17/30/8)*1.5)*X17 -> 0 | AA17: =(($E17/30/8)*2)*Z17 -> 0 | AC17: =(($E17/30/8)*1.5)*AB17 -> 0 | AE17: =(($E17/30/8)*2)*AD17 -> 0 | AG17: =(($E17/30/8)*1.5)*AF17 -> 0 | AI17: =(($E17/30/8)*2)*AH17 -> 0 | AV17: =((E17/30)*H17)*$I17 -> 0 | AW17: =((F17/30)*H17)*$I17 -> 0 | AX17: =P17 -> 0 | AY17: =Q17 -> 0 | AZ17: =R17 -> 0 | BA17: =S17 -> 0 | BB17: =AJ17+AO17 -> 0 | BC17: =(AV17+AY17+BA17)*0.1267 -> 0 | BD17: =SUM(AV17:BC17)-AX17-AZ17 -> 0 | BE17: =(($E17/30)*$H17)*$J17 -> 3166.38 | BF17: =(($F17/30)*$H17)*$J17 -> 250 | BG17: =T17 -> 0 | BH17: =U17 -> 0 | BI17: =V17 -> 0 | BJ17: =W17 -> 0 | BK17: =AK17+AP17 -> 0 | BL17: =(+BE17+BH17+BJ17+BK17)*0.1267 -> 401.18035 | BM17: =SUM(BE17:BL17)-BG17-BI17 -> 3817.5603 | BN17: =(($E17/30)*$H17)*$K17 -> 0 | BO17: =(($F17/30)*$H17)*$K17 -> 0 | BP17: =X17 -> 0 | BQ17: =Y17 -> 0 | BR17: =Z17 -> 0 | BS17: =AA17 -> 0 | BT17: =AL17+AQ17 -> 0 | BU17: =(BN17+BQ17+BS17)*0.1267 -> 0 | BV17: =SUM(BN17:BU17)-BP17-BR17 -> 0 | BW17: =(($E17/30)*$H17)*$L17 -> 0 | BX17: =(($F17/30)*$H17)*$L17 -> 0 | BY17: =AB17 -> 0 | BZ17: =AC17 -> 0 | CA17: =AD17 -> 0 | CB17: =AE17 -> 0 | CC17: =AM17+AR17 -> 0 | CD17: =(BW17+BZ17+CB17)*0.1267 -> 0 | CE17: =SUM(BW17:CD17)-BY17-CA17 -> 0 | CF17: =(($E17/30)*$H17)*M17 -> 0 | CG17: =(($F17/30)*$H17)*$M17 -> 0 | CH17: =+AF17 -> 0 | CI17: =AG17 -> 0 | CJ17: =AH17 -> 0 | CK17: =AI17 -> 0 | CL17: =AN17+AS17 -> 0 | CM17: =(CF17+CI17+CK17)*0.1267 -> 0 | CN17: =SUM(CF17:CM17)-CH17-CJ17 -> 0 | CP17: UNHESA | CQ17: =IF($CP17="PROQUIMA",$AV17+$BE17+$BN17+$BW17+$CF17,0) -> 0 | CR17: =IF($CP17="PROQUIMA",$AW17+$BF17+$BO17+$BX17+$CG17,0) -> 0 | CS17: =IF($CP17="PROQUIMA",$AX17+$BG17+$BP17+$BY17+$CH17,0) -> 0 | CT17: =IF($CP17="PROQUIMA",$AY17+$BH17+$BQ17+$BZ17+$CI17,0) -> 0 | CU17: =IF($CP17="PROQUIMA",$AZ17+$BI17+$BR17+$CA17+$CJ17,0) -> 0 | CV17: =IF($CP17="PROQUIMA",$BA17+$BJ17+$BS17+$CB17+$CK17,0) -> 0 | CW17: =IF($CP17="PROQUIMA",$BB17+$BK17+$BT17+$CC17+$CL17,0) -> 0 | CX17: =IF($CP17="PROQUIMA",$BC17+$BL17+$BU17+$CD17+CM17,0) -> 0 | CY17: =SUM(CQ17:CX17)-CS17-CU17 -> 0 | CZ17: =IF($CP17="UNHESA",$AV17+$BE17+$BN17+$BW17+$CF17,0) -> 3166.38 | DA17: =IF($CP17="UNHESA",$AW17+$BF17+$BO17+$BX17+$CG17,0) -> 250 | DB17: =IF($CP17="UNHESA",$AX17+$BG17+$BP17+$BY17+$CH17,0) -> 0 | DC17: =IF($CP17="UNHESA",$AY17+$BH17+$BQ17+$BZ17+$CI17,0) -> 0 | DD17: =IF($CP17="UNHESA",$AZ17+$BI17+$BR17+$CA17+$CJ17,0) -> 0 | DE17: =IF($CP17="UNHESA",$BA17+$BJ17+$BS17+$CB17+$CK17,0) -> 0 | DF17: =IF($CP17="UNHESA",$BB17+$BK17+$BT17+$CC17+$CL17,0) -> 0 | DG17: =IF($CP17="UNHESA",$BC17+$BL17+$BU17+$CD17+$CM17,0) -> 401.18035 | DH17: =SUM(CZ17:DG17)-DB17-DD17 -> 3817.5603 | DI17: =IF($CP17="UNHESA LIQUIDOS",$AV17+$BE17+$BN17+$BW17+$CF17,0) -> 0 | DJ17: =IF($CP17="CALIDUL",$AW17+$BF17+$BO17+$BX17+$CG17,0) -> 0 | DK17: =IF($CP17="CALIDUL",$AX17+$BG17+$BP17+$BY17+$CH17,0) -> 0 | DL17: =IF($CP17="CALIDUL",$AY17+$BH17+$BQ17+$BZ17+$CI17,0) -> 0 | DM17: =IF($CP17="CALIDUL",$AZ17+$BI17+$BR17+$CA17+$CJ17,0) -> 0 | DN17: =IF($CP17="CALIDUL",$BA17+$BJ17+$BS17+$CB17+$CK17,0) -> 0 | DO17: =IF($CP17="CALIDUL",$BB17+$BK17+$BT17+$CC17+$CL17,0) -> 0 | DP17: =IF($CP17="CALIDUL",$BC17+$BL17+$BU17+$CD17+$CM17,0) -> 0 | DQ17: =SUM(DI17:DP17)-DK17-DM17 -> 0 | DR17: =IF($CP17="ECONACIONAL",$AV17+$BE17+$BN17+$BW17+$CF17,0) -> 0 | DS17: =IF($CP17="ECONACIONAL",$AW17+$BF17+$BO17+$BX17+$CG17,0) -> 0 | DT17: =IF($CP17="ECONACIONAL",$AX17+$BG17+$BP17+$BY17+$CH17,0) -> 0 | DU17: =IF($CP17="ECONACIONAL",$AY17+$BH17+$BQ17+$BZ17+$CI17,0) -> 0 | DV17: =IF($CP17="ECONACIONAL",$AZ17+$BI17+$BR17+$CA17+$CJ17,0) -> 0 | DW17: =IF($CP17="ECONACIONAL",$BA17+$BJ17+$BS17+$CB17+$CK17,0) -> 0 | DX17: =IF($CP17="ECONACIONAL",$BB17+$BK17+$BT17+$CC17+$CL17,0) -> 0 | DY17: =IF($CP17="ECONACIONAL",$BC17+$BL17+$BU17+$CD17+$CM17,0) -> 0 | DZ17: =SUM(DR17:DY17)-DT17-DV17 -> 0 | EA17: =IF($CP17="CLEARTEC",$AV17+$BE17+$BN17+$BW17+$CF17,0) -> 0 | EB17: =IF($CP17="CLEARTEC",$AW17+$BF17+$BO17+$BX17+$CG17,0) -> 0 | EC17: =IF($CP17="CLEARTEC",$AX17+$BG17+$BP17+$BY17+$CH17,0) -> 0 | ED17: =IF($CP17="CLEARTEC",$AY17+$BH17+$BQ17+$BZ17+$CI17,0) -> 0 | EE17: =IF($CP17="CLEARTEC",$AZ17+$BI17+$BR17+$CA17+$CJ17,0) -> 0 | EF17: =IF($CP17="CLEARTEC",$BA17+$BJ17+$BS17+$CB17+$CK17,0) -> 0 | EG17: =IF($CP17="CLEARTEC",$BB17+$BK17+$BT17+$CC17+$CL17,0) -> 0 | EH17: =IF($CP17="CLEARTEC",$BC17+$BL17+$BU17+$CD17+$CM17,0) -> 0 | EI17: =SUM(EA17:EH17)-EC17-EE17 -> 0 | EP17: 50 | ET17: =+EO17+EP17+EQ17 -> 50 | EV17: =IF($H17<=15,EK17/2,EK17) -> 0 | EW17: =IF($H17<=15,EL17/2,EL17) -> 0 | EX17: =IF($H17<=15,EM17/2,EM17) -> 0 | EY17: =IF($H17<=15,EN17/2,EN17) -> 0 | EZ17: =IF($H17<=15,EO17/2,EO17) -> 0 | FA17: =IF($H17<=15,EP17/2,EP17) -> 50 | FB17: =IF($H17<=15,EQ17/2,EQ17) -> 0 | FC17: =IF($H17<=15,ER17/2,ER17) -> 0 | ... FE17: =IF($H17<=15,ET17/2,ET17) -> 50 | FF17: 0 | FG17: 1 | FH17: 0 | FI17: 0 | FJ17: 0 | FK17: 1 | FL17: =+EP17-FA17 -> 0
A18: =+A17+1 -> 9 | B18: Alvarez Fajardo Erick Geovanni | C18: Piloto | D18: PROQUIMA | E18: 3166.38 | F18: 1540.76 | G18: =+E18+F18 -> 4707.14 | H18: 9 | I18: 1 | J18: 0 | K18: 0 | L18: 0 | M18: 0 | N18: =SUM(I18:M18) -> 1 | O18: B.9.1.23 | Q18: =($E18/30/8*1.5)*P18 -> 0 | S18: =($E18/30/8*2)*R18 -> 0 | U18: =($E18/30/8*1.5)*T18 -> 0 | W18: =($E18/30/8*2)*V18 -> 0 | Y18: =(($E18/30/8)*1.5)*X18 -> 0 | AA18: =(($E18/30/8)*2)*Z18 -> 0 | AC18: =(($E18/30/8)*1.5)*AB18 -> 0 | AE18: =(($E18/30/8)*2)*AD18 -> 0 | AG18: =(($E18/30/8)*1.5)*AF18 -> 0 | AI18: =(($E18/30/8)*2)*AH18 -> 0 | AV18: =((E18/30)*H18)*$I18 -> 949.914 | AW18: =((F18/30)*H18)*$I18 -> 462.228 | AX18: =P18 -> 0 | AY18: =Q18 -> 0 | AZ18: =R18 -> 0 | BA18: =S18 -> 0 | BB18: =AJ18+AO18 -> 0 | BC18: =(AV18+AY18+BA18)*0.1267 -> 120.3541 | BD18: =SUM(AV18:BC18)-AX18-AZ18 -> 1532.4961 | BE18: =(($E18/30)*$H18)*$J18 -> 0 | BF18: =(($F18/30)*$H18)*$J18 -> 0 | BG18: =T18 -> 0 | BH18: =U18 -> 0 | BI18: =V18 -> 0 | BJ18: =W18 -> 0 | BK18: =AK18+AP18 -> 0 | BL18: =(+BE18+BH18+BJ18+BK18)*0.1267 -> 0 | BM18: =SUM(BE18:BL18)-BG18-BI18 -> 0 | BN18: =(($E18/30)*$H18)*$K18 -> 0 | BO18: =(($F18/30)*$H18)*$K18 -> 0 | BP18: =X18 -> 0 | BQ18: =Y18 -> 0 | BR18: =Z18 -> 0 | BS18: =AA18 -> 0 | BT18: =AL18+AQ18 -> 0 | BU18: =(BN18+BQ18+BS18)*0.1267 -> 0 | BV18: =SUM(BN18:BU18)-BP18-BR18 -> 0 | BW18: =(($E18/30)*$H18)*$L18 -> 0 | BX18: =(($F18/30)*$H18)*$L18 -> 0 | BY18: =AB18 -> 0 | BZ18: =AC18 -> 0 | CA18: =AD18 -> 0 | CB18: =AE18 -> 0 | CC18: =AM18+AR18 -> 0 | CD18: =(BW18+BZ18+CB18)*0.1267 -> 0 | CE18: =SUM(BW18:CD18)-BY18-CA18 -> 0 | CF18: =(($E18/30)*$H18)*M18 -> 0 | CG18: =(($F18/30)*$H18)*$M18 -> 0 | CH18: =+AF18 -> 0 | CI18: =AG18 -> 0 | CJ18: =AH18 -> 0 | CK18: =AI18 -> 0 | CL18: =AN18+AS18 -> 0 | CM18: =(CF18+CI18+CK18)*0.1267 -> 0 | CN18: =SUM(CF18:CM18)-CH18-CJ18 -> 0 | CP18: PROQUIMA | CQ18: =IF($CP18="PROQUIMA",$AV18+$BE18+$BN18+$BW18+$CF18,0) -> 949.914 | CR18: =IF($CP18="PROQUIMA",$AW18+$BF18+$BO18+$BX18+$CG18,0) -> 462.228 | CS18: =IF($CP18="PROQUIMA",$AX18+$BG18+$BP18+$BY18+$CH18,0) -> 0 | CT18: =IF($CP18="PROQUIMA",$AY18+$BH18+$BQ18+$BZ18+$CI18,0) -> 0 | CU18: =IF($CP18="PROQUIMA",$AZ18+$BI18+$BR18+$CA18+$CJ18,0) -> 0 | CV18: =IF($CP18="PROQUIMA",$BA18+$BJ18+$BS18+$CB18+$CK18,0) -> 0 | CW18: =IF($CP18="PROQUIMA",$BB18+$BK18+$BT18+$CC18+$CL18,0) -> 0 | CX18: =IF($CP18="PROQUIMA",$BC18+$BL18+$BU18+$CD18+CM18,0) -> 120.3541 | CY18: =SUM(CQ18:CX18)-CS18-CU18 -> 1532.4961 | CZ18: =IF($CP18="UNHESA",$AV18+$BE18+$BN18+$BW18+$CF18,0) -> 0 | DA18: =IF($CP18="UNHESA",$AW18+$BF18+$BO18+$BX18+$CG18,0) -> 0 | DB18: =IF($CP18="UNHESA",$AX18+$BG18+$BP18+$BY18+$CH18,0) -> 0 | DC18: =IF($CP18="UNHESA",$AY18+$BH18+$BQ18+$BZ18+$CI18,0) -> 0 | DD18: =IF($CP18="UNHESA",$AZ18+$BI18+$BR18+$CA18+$CJ18,0) -> 0 | DE18: =IF($CP18="UNHESA",$BA18+$BJ18+$BS18+$CB18+$CK18,0) -> 0 | DF18: =IF($CP18="UNHESA",$BB18+$BK18+$BT18+$CC18+$CL18,0) -> 0 | DG18: =IF($CP18="UNHESA",$BC18+$BL18+$BU18+$CD18+$CM18,0) -> 0 | DH18: =SUM(CZ18:DG18)-DB18-DD18 -> 0 | DI18: =IF($CP18="UNHESA LIQUIDOS",$AV18+$BE18+$BN18+$BW18+$CF18,0) -> 0 | DJ18: =IF($CP18="CALIDUL",$AW18+$BF18+$BO18+$BX18+$CG18,0) -> 0 | DK18: =IF($CP18="CALIDUL",$AX18+$BG18+$BP18+$BY18+$CH18,0) -> 0 | DL18: =IF($CP18="CALIDUL",$AY18+$BH18+$BQ18+$BZ18+$CI18,0) -> 0 | DM18: =IF($CP18="CALIDUL",$AZ18+$BI18+$BR18+$CA18+$CJ18,0) -> 0 | DN18: =IF($CP18="CALIDUL",$BA18+$BJ18+$BS18+$CB18+$CK18,0) -> 0 | DO18: =IF($CP18="CALIDUL",$BB18+$BK18+$BT18+$CC18+$CL18,0) -> 0 | DP18: =IF($CP18="CALIDUL",$BC18+$BL18+$BU18+$CD18+$CM18,0) -> 0 | DQ18: =SUM(DI18:DP18)-DK18-DM18 -> 0 | DR18: =IF($CP18="ECONACIONAL",$AV18+$BE18+$BN18+$BW18+$CF18,0) -> 0 | DS18: =IF($CP18="ECONACIONAL",$AW18+$BF18+$BO18+$BX18+$CG18,0) -> 0 | DT18: =IF($CP18="ECONACIONAL",$AX18+$BG18+$BP18+$BY18+$CH18,0) -> 0 | DU18: =IF($CP18="ECONACIONAL",$AY18+$BH18+$BQ18+$BZ18+$CI18,0) -> 0 | DV18: =IF($CP18="ECONACIONAL",$AZ18+$BI18+$BR18+$CA18+$CJ18,0) -> 0 | DW18: =IF($CP18="ECONACIONAL",$BA18+$BJ18+$BS18+$CB18+$CK18,0) -> 0 | DX18: =IF($CP18="ECONACIONAL",$BB18+$BK18+$BT18+$CC18+$CL18,0) -> 0 | DY18: =IF($CP18="ECONACIONAL",$BC18+$BL18+$BU18+$CD18+$CM18,0) -> 0 | DZ18: =SUM(DR18:DY18)-DT18-DV18 -> 0 | EA18: =IF($CP18="CLEARTEC",$AV18+$BE18+$BN18+$BW18+$CF18,0) -> 0 | EB18: =IF($CP18="CLEARTEC",$AW18+$BF18+$BO18+$BX18+$CG18,0) -> 0 | EC18: =IF($CP18="CLEARTEC",$AX18+$BG18+$BP18+$BY18+$CH18,0) -> 0 | ED18: =IF($CP18="CLEARTEC",$AY18+$BH18+$BQ18+$BZ18+$CI18,0) -> 0 | EE18: =IF($CP18="CLEARTEC",$AZ18+$BI18+$BR18+$CA18+$CJ18,0) -> 0 | EF18: =IF($CP18="CLEARTEC",$BA18+$BJ18+$BS18+$CB18+$CK18,0) -> 0 | EG18: =IF($CP18="CLEARTEC",$BB18+$BK18+$BT18+$CC18+$CL18,0) -> 0 | EH18: =IF($CP18="CLEARTEC",$BC18+$BL18+$BU18+$CD18+$CM18,0) -> 0 | EI18: =SUM(EA18:EH18)-EC18-EE18 -> 0 | ET18: =+EO18+EP18+EQ18 -> 0 | EV18: =IF($H18<=15,EK18/2,EK18) -> 0 | EW18: =IF($H18<=15,EL18/2,EL18) -> 0 | EX18: =IF($H18<=15,EM18/2,EM18) -> 0 | EY18: =IF($H18<=15,EN18/2,EN18) -> 0 | EZ18: =IF($H18<=15,EO18/2,EO18) -> 0 | FA18: =IF($H18<=15,EP18/2,EP18) -> 0 | FB18: =IF($H18<=15,EQ18/2,EQ18) -> 0 | FC18: =IF($H18<=15,ER18/2,ER18) -> 0 | ... FE18: =IF($H18<=15,ET18/2,ET18) -> 0
C19: Total Presidencia | E19: =SUM(E10:E18) -> 116915.52 | F19: =SUM(F10:F18) -> 163290.76 | G19: =SUM(G10:G18) -> 280206.28 | P19: =SUM(P10:P18) -> 0 | Q19: =SUM(Q10:Q18) -> 0 | R19: =SUM(R10:R18) -> 0 | S19: =SUM(S10:S18) -> 0 | T19: =SUM(T10:T18) -> 0 | U19: =SUM(U10:U18) -> 0 | V19: =SUM(V10:V18) -> 0 | W19: =SUM(W10:W18) -> 0 | ... AA19: =SUM(AA10:AA18) -> 0 | AB19: =SUM(AB10:AB17) -> 0 | AC19: =SUM(AC10:AC17) -> 0 | AD19: =SUM(AD10:AD17) -> 0 | AE19: =SUM(AE10:AE17) -> 0 | AF19: =SUM(AF10:AF17) -> 0 | AG19: =SUM(AG10:AG17) -> 0 | AH19: =SUM(AH10:AH17) -> 0 | AI19: =SUM(AI10:AI17) -> 0 | ... AT19: =SUM(AT10:AT17) -> 0 | AV19: =SUM(AV10:AV18) -> 80449.914 | AW19: =SUM(AW10:AW18) -> 172431.1 | AX19: =SUM(AX10:AX18) -> 0 | AY19: =SUM(AY10:AY18) -> 0 | AZ19: =SUM(AZ10:AZ18) -> 0 | BA19: =SUM(BA10:BA18) -> 0 | BB19: =SUM(BB10:BB18) -> 0 | BC19: =SUM(BC10:BC18) -> 10193.004 | ... BV19: =SUM(BV10:BV18) -> 0 | BW19: =SUM(BW10:BW17) -> 1500 | BX19: =SUM(BX10:BX17) -> 1200 | BY19: =SUM(BY10:BY17) -> 0 | BZ19: =SUM(BZ10:BZ17) -> 0 | CA19: =SUM(CA10:CA17) -> 0 | CB19: =SUM(CB10:CB17) -> 0 | CC19: =SUM(CC10:CC17) -> 0 | CD19: =SUM(CD10:CD18) -> 190.05 | CE19: =SUM(CE10:CE18) -> 2890.05 | CF19: =SUM(CF10:CF17) -> 0 | CG19: =SUM(CG10:CG17) -> 0 | CH19: =SUM(CH10:CH17) -> 0 | CI19: =SUM(CI10:CI17) -> 0 | CJ19: =SUM(CJ10:CJ17) -> 0 | CK19: =SUM(CK10:CK17) -> 0 | CL19: =SUM(CL10:CL17) -> 0 | CM19: =SUM(CM10:CM17) -> 0 | CN19: =SUM(CN10:CN17) -> 0 | CQ19: =SUM(CQ10:CQ18) -> 80449.914 | CR19: =SUM(CR10:CR18) -> 171781.1 | CS19: =SUM(CS10:CS18) -> 0 | CT19: =SUM(CT10:CT18) -> 0 | CU19: =SUM(CU10:CU18) -> 0 | CV19: =SUM(CV10:CV18) -> 0 | CW19: =SUM(CW10:CW18) -> 0 | CX19: =SUM(CX10:CX18) -> 9971.2791 | ... DQ19: =SUM(DQ10:DQ18) -> 0 | DR19: =SUM(DR10:DR17) -> 0 | DS19: =SUM(DS10:DS17) -> 0 | DT19: =SUM(DT10:DT17) -> 0 | DU19: =SUM(DU10:DU17) -> 0 | DV19: =SUM(DV10:DV17) -> 0 | DW19: =SUM(DW10:DW17) -> 0 | DX19: =SUM(DX10:DX17) -> 0 | DY19: =SUM(DY10:DY17) -> 0 | ... EI19: =SUM(EI10:EI17) -> 0 | EK19: =SUM(EK10:EK18) -> 19506.42 | EL19: =SUM(EL10:EL18) -> 0 | EM19: =SUM(EM10:EM18) -> 0 | EN19: =SUM(EN10:EN18) -> 97 | EO19: =SUM(EO10:EO18) -> 165 | EP19: =SUM(EP10:EP18) -> 275 | EQ19: =SUM(EQ10:EQ18) -> 240 | ER19: =SUM(ER10:ER18) -> 0 | ... ET19: =SUM(ET10:ET18) -> 680 | EV19: =SUM(EV10:EV18) -> 19506.42 | EW19: =SUM(EW10:EW18) -> 0 | EX19: =SUM(EX10:EX18) -> 0 | EY19: =SUM(EY10:EY18) -> 97 | EZ19: =SUM(EZ10:EZ18) -> 165 | FA19: =SUM(FA10:FA18) -> 275 | FB19: =SUM(FB10:FB18) -> 240 | FC19: =SUM(FC10:FC18) -> 0 | ... FE19: =SUM(FE10:FE18) -> 680 | FL19: =+EP19-FA19 -> 0
FL20: =+EP20-FA20 -> 0
B21: ADMINISTRATIVO | FL21: =+EP21-FA21 -> 0
A22: 10 | B22: Gaitan Hernandez Luis Daniel | C22: Piloto de Presidencia | D22: PROQUIMA | E22: 3262.5 | F22: 2250 | G22: =+E22+F22 -> 5512.5 | H22: 30 | I22: 1 | J22: 0 | K22: 0 | L22: 0 | M22: 0 | N22: =SUM(I22:M22) -> 1 | Q22: =($E22/30/8*1.5)*P22 -> 0 | S22: =($E22/30/8*2)*R22 -> 0 | U22: =($E22/30/8*1.5)*T22 -> 0 | W22: =($E22/30/8*2)*V22 -> 0 | Y22: =(($E22/30/8)*1.5)*X22 -> 0 | AA22: =(($E22/30/8)*2)*Z22 -> 0 | AC22: =(($E22/30/8)*1.5)*AB22 -> 0 | AE22: =(($E22/30/8)*2)*AD22 -> 0 | AG22: =(($E22/30/8)*1.5)*AF22 -> 0 | AI22: =(($E22/30/8)*2)*AH22 -> 0 | AV22: =((E22/30)*H22)*$I22 -> 3262.5 | AW22: =((F22/30)*H22)*$I22 -> 2250 | AX22: =P22 -> 0 | AY22: =Q22 -> 0 | AZ22: =R22 -> 0 | BA22: =S22 -> 0 | BB22: =AJ22+AO22 -> 0 | BC22: =(AV22+AY22+BA22)*0.1267 -> 413.35875 | BD22: =SUM(AV22:BC22)-AX22-AZ22 -> 5925.8588 | BE22: =(($E22/30)*$H22)*$J22 -> 0 | BF22: =(($F22/30)*$H22)*$J22 -> 0 | BG22: =T22 -> 0 | BH22: =U22 -> 0 | BI22: =V22 -> 0 | BJ22: =W22 -> 0 | BK22: =AK22+AP22 -> 0 | BL22: =(+BE22+BH22+BJ22+BK22)*0.1267 -> 0 | BM22: =SUM(BE22:BL22)-BG22-BI22 -> 0 | BN22: =(($E22/30)*$H22)*$K22 -> 0 | BO22: =(($F22/30)*$H22)*$K22 -> 0 | BP22: =X22 -> 0 | BQ22: =Y22 -> 0 | BR22: =Z22 -> 0 | BS22: =AA22 -> 0 | BT22: =AL22+AQ22 -> 0 | BU22: =(BN22+BQ22+BS22)*0.1267 -> 0 | BV22: =SUM(BN22:BU22)-BP22-BR22 -> 0 | BW22: =(($E22/30)*$H22)*$L22 -> 0 | BX22: =(($F22/30)*$H22)*$L22 -> 0 | BY22: =AB22 -> 0 | BZ22: =AC22 -> 0 | CA22: =AD22 -> 0 | CB22: =AE22 -> 0 | CC22: =AM22+AR22 -> 0 | CD22: =(BW22+BZ22+CB22)*0.1267 -> 0 | CE22: =SUM(BW22:CD22)-BY22-CA22 -> 0 | CF22: =(($E22/30)*$H22)*M22 -> 0 | CG22: =(($F22/30)*$H22)*$M22 -> 0 | CH22: =+AF22 -> 0 | CI22: =AG22 -> 0 | CJ22: =AH22 -> 0 | CK22: =AI22 -> 0 | CL22: =AN22+AS22 -> 0 | CM22: =(CF22+CI22+CK22)*0.1267 -> 0 | CN22: =SUM(CF22:CM22)-CH22-CJ22 -> 0 | CP22: PROQUIMA | CQ22: =IF($CP22="PROQUIMA",$AV22+$BE22+$BN22+$BW22+$CF22,0) -> 3262.5 | CR22: =IF($CP22="PROQUIMA",$AW22+$BF22+$BO22+$BX22+$CG22,0) -> 2250 | CS22: =IF($CP22="PROQUIMA",$AX22+$BG22+$BP22+$BY22+$CH22,0) -> 0 | CT22: =IF($CP22="PROQUIMA",$AY22+$BH22+$BQ22+$BZ22+$CI22,0) -> 0 | CU22: =IF($CP22="PROQUIMA",$AZ22+$BI22+$BR22+$CA22+$CJ22,0) -> 0 | CV22: =IF($CP22="PROQUIMA",$BA22+$BJ22+$BS22+$CB22+$CK22,0) -> 0 | CW22: =IF($CP22="PROQUIMA",$BB22+$BK22+$BT22+$CC22+$CL22,0) -> 0 | CX22: =IF($CP22="PROQUIMA",$BC22+$BL22+$BU22+$CD22+CM22,0) -> 413.35875 | CY22: =SUM(CQ22:CX22)-CS22-CU22 -> 5925.8588 | CZ22: =IF($CP22="UNHESA",$AV22+$BE22+$BN22+$BW22+$CF22,0) -> 0 | DA22: =IF($CP22="UNHESA",$AW22+$BF22+$BO22+$BX22+$CG22,0) -> 0 | DB22: =IF($CP22="UNHESA",$AX22+$BG22+$BP22+$BY22+$CH22,0) -> 0 | DC22: =IF($CP22="UNHESA",$AY22+$BH22+$BQ22+$BZ22+$CI22,0) -> 0 | DD22: =IF($CP22="UNHESA",$AZ22+$BI22+$BR22+$CA22+$CJ22,0) -> 0 | DE22: =IF($CP22="UNHESA",$BA22+$BJ22+$BS22+$CB22+$CK22,0) -> 0 | DF22: =IF($CP22="UNHESA",$BB22+$BK22+$BT22+$CC22+$CL22,0) -> 0 | DG22: =IF($CP22="UNHESA",$BC22+$BL22+$BU22+$CD22+$CM22,0) -> 0 | DH22: =SUM(CZ22:DG22)-DB22-DD22 -> 0 | DI22: =IF($CP22="UNHESA LIQUIDOS",$AV22+$BE22+$BN22+$BW22+$CF22,0) -> 0 | DJ22: =IF($CP22="CALIDUL",$AW22+$BF22+$BO22+$BX22+$CG22,0) -> 0 | DK22: =IF($CP22="CALIDUL",$AX22+$BG22+$BP22+$BY22+$CH22,0) -> 0 | DL22: =IF($CP22="CALIDUL",$AY22+$BH22+$BQ22+$BZ22+$CI22,0) -> 0 | DM22: =IF($CP22="CALIDUL",$AZ22+$BI22+$BR22+$CA22+$CJ22,0) -> 0 | DN22: =IF($CP22="CALIDUL",$BA22+$BJ22+$BS22+$CB22+$CK22,0) -> 0 | DO22: =IF($CP22="CALIDUL",$BB22+$BK22+$BT22+$CC22+$CL22,0) -> 0 | DP22: =IF($CP22="CALIDUL",$BC22+$BL22+$BU22+$CD22+$CM22,0) -> 0 | DQ22: =SUM(DI22:DP22)-DK22-DM22 -> 0 | DR22: =IF($CP22="ECONACIONAL",$AV22+$BE22+$BN22+$BW22+$CF22,0) -> 0 | DS22: =IF($CP22="ECONACIONAL",$AW22+$BF22+$BO22+$BX22+$CG22,0) -> 0 | DT22: =IF($CP22="ECONACIONAL",$AX22+$BG22+$BP22+$BY22+$CH22,0) -> 0 | DU22: =IF($CP22="ECONACIONAL",$AY22+$BH22+$BQ22+$BZ22+$CI22,0) -> 0 | DV22: =IF($CP22="ECONACIONAL",$AZ22+$BI22+$BR22+$CA22+$CJ22,0) -> 0 | DW22: =IF($CP22="ECONACIONAL",$BA22+$BJ22+$BS22+$CB22+$CK22,0) -> 0 | DX22: =IF($CP22="ECONACIONAL",$BB22+$BK22+$BT22+$CC22+$CL22,0) -> 0 | DY22: =IF($CP22="ECONACIONAL",$BC22+$BL22+$BU22+$CD22+$CM22,0) -> 0 | DZ22: =SUM(DR22:DY22)-DT22-DV22 -> 0 | EA22: =IF($CP22="CLEARTEC",$AV22+$BE22+$BN22+$BW22+$CF22,0) -> 0 | EB22: =IF($CP22="CLEARTEC",$AW22+$BF22+$BO22+$BX22+$CG22,0) -> 0 | EC22: =IF($CP22="CLEARTEC",$AX22+$BG22+$BP22+$BY22+$CH22,0) -> 0 | ED22: =IF($CP22="CLEARTEC",$AY22+$BH22+$BQ22+$BZ22+$CI22,0) -> 0 | EE22: =IF($CP22="CLEARTEC",$AZ22+$BI22+$BR22+$CA22+$CJ22,0) -> 0 | EF22: =IF($CP22="CLEARTEC",$BA22+$BJ22+$BS22+$CB22+$CK22,0) -> 0 | EG22: =IF($CP22="CLEARTEC",$BB22+$BK22+$BT22+$CC22+$CL22,0) -> 0 | EH22: =IF($CP22="CLEARTEC",$BC22+$BL22+$BU22+$CD22+$CM22,0) -> 0 | EI22: =SUM(EA22:EH22)-EC22-EE22 -> 0 | EK22: 67.75 | EP22: 50 | ET22: =+EO22+EP22+EQ22 -> 50 | EV22: =IF($H22<=15,EK22/2,EK22) -> 67.75 | EW22: =IF($H22<=15,EL22/2,EL22) -> 0 | EX22: =IF($H22<=15,EM22/2,EM22) -> 0 | EY22: =IF($H22<=15,EN22/2,EN22) -> 0 | EZ22: =IF($H22<=15,EO22/2,EO22) -> 0 | FA22: =IF($H22<=15,EP22/2,EP22) -> 50 | FB22: =IF($H22<=15,EQ22/2,EQ22) -> 0 | FC22: =IF($H22<=15,ER22/2,ER22) -> 0 | ... FE22: =IF($H22<=15,ET22/2,ET22) -> 50 | FF22: 1 | FG22: 0 | FH22: 0 | FI22: 0 | FJ22: 0 | FK22: 1 | FL22: =+EP22-FA22 -> 0
A23: =+A22+1 -> 11 | B23: Saenz Lemus Dulce Maria | C23: Recepcionista | D23: PROQUIMA | E23: 3166.38 | F23: 250 | G23: =+E23+F23 -> 3416.38 | H23: 30 | I23: 0.5 | J23: 0.5 | K23: 0 | L23: 0 | M23: 0 | N23: =SUM(I23:M23) -> 1 | Q23: =($E23/30/8*1.5)*P23 -> 0 | S23: =($E23/30/8*2)*R23 -> 0 | U23: =($E23/30/8*1.5)*T23 -> 0 | W23: =($E23/30/8*2)*V23 -> 0 | Y23: =(($E23/30/8)*1.5)*X23 -> 0 | AA23: =(($E23/30/8)*2)*Z23 -> 0 | AC23: =(($E23/30/8)*1.5)*AB23 -> 0 | AE23: =(($E23/30/8)*2)*AD23 -> 0 | AV23: =((E23/30)*H23)*$I23 -> 1583.19 | AW23: =((F23/30)*H23)*$I23 -> 125 | AX23: =P23 -> 0 | AY23: =Q23 -> 0 | AZ23: =R23 -> 0 | BA23: =S23 -> 0 | BB23: =AJ23+AO23 -> 0 | BC23: =(AV23+AY23+BA23)*0.1267 -> 200.59017 | BD23: =SUM(AV23:BC23)-AX23-AZ23 -> 1908.7802 | BE23: =(($E23/30)*$H23)*$J23 -> 1583.19 | BF23: =(($F23/30)*$H23)*$J23 -> 125 | BG23: =T23 -> 0 | BH23: =U23 -> 0 | BI23: =V23 -> 0 | BJ23: =W23 -> 0 | BK23: =AK23+AP23 -> 0 | BL23: =(+BE23+BH23+BJ23+BK23)*0.1267 -> 200.59017 | BM23: =SUM(BE23:BL23)-BG23-BI23 -> 1908.7802 | BN23: =(($E23/30)*$H23)*$K23 -> 0 | BO23: =(($F23/30)*$H23)*$K23 -> 0 | BP23: =X23 -> 0 | BQ23: =Y23 -> 0 | BR23: =Z23 -> 0 | BS23: =AA23 -> 0 | BT23: =AL23+AQ23 -> 0 | BU23: =(BN23+BQ23+BS23)*0.1267 -> 0 | BV23: =SUM(BN23:BU23)-BP23-BR23 -> 0 | BW23: =(($E23/30)*$H23)*$L23 -> 0 | BX23: =(($F23/30)*$H23)*$L23 -> 0 | BY23: =AB23 -> 0 | BZ23: =AC23 -> 0 | CA23: =AD23 -> 0 | CB23: =AE23 -> 0 | CC23: =AM23+AR23 -> 0 | CD23: =(BW23+BZ23+CB23)*0.1267 -> 0 | CE23: =SUM(BW23:CD23)-BY23-CA23 -> 0 | CP23: PROQUIMA | CQ23: =IF($CP23="PROQUIMA",$AV23+$BE23+$BN23+$BW23+$CF23,0) -> 3166.38 | CR23: =IF($CP23="PROQUIMA",$AW23+$BF23+$BO23+$BX23+$CG23,0) -> 250 | CS23: =IF($CP23="PROQUIMA",$AX23+$BG23+$BP23+$BY23+$CH23,0) -> 0 | CT23: =IF($CP23="PROQUIMA",$AY23+$BH23+$BQ23+$BZ23+$CI23,0) -> 0 | CU23: =IF($CP23="PROQUIMA",$AZ23+$BI23+$BR23+$CA23+$CJ23,0) -> 0 | CV23: =IF($CP23="PROQUIMA",$BA23+$BJ23+$BS23+$CB23+$CK23,0) -> 0 | CW23: =IF($CP23="PROQUIMA",$BB23+$BK23+$BT23+$CC23+$CL23,0) -> 0 | CX23: =IF($CP23="PROQUIMA",$BC23+$BL23+$BU23+$CD23+CM23,0) -> 401.18035 | CY23: =SUM(CQ23:CX23)-CS23-CU23 -> 3817.5603 | CZ23: =IF($CP23="UNHESA",$AV23+$BE23+$BN23+$BW23+$CF23,0) -> 0 | DA23: =IF($CP23="UNHESA",$AW23+$BF23+$BO23+$BX23+$CG23,0) -> 0 | DB23: =IF($CP23="UNHESA",$AX23+$BG23+$BP23+$BY23+$CH23,0) -> 0 | DC23: =IF($CP23="UNHESA",$AY23+$BH23+$BQ23+$BZ23+$CI23,0) -> 0 | DD23: =IF($CP23="UNHESA",$AZ23+$BI23+$BR23+$CA23+$CJ23,0) -> 0 | DE23: =IF($CP23="UNHESA",$BA23+$BJ23+$BS23+$CB23+$CK23,0) -> 0 | DF23: =IF($CP23="UNHESA",$BB23+$BK23+$BT23+$CC23+$CL23,0) -> 0 | DG23: =IF($CP23="UNHESA",$BC23+$BL23+$BU23+$CD23+$CM23,0) -> 0 | DH23: =SUM(CZ23:DG23)-DB23-DD23 -> 0 | DI23: =IF($CP23="UNHESA LIQUIDOS",$AV23+$BE23+$BN23+$BW23+$CF23,0) -> 0 | DJ23: =IF($CP23="CALIDUL",$AW23+$BF23+$BO23+$BX23+$CG23,0) -> 0 | DK23: =IF($CP23="CALIDUL",$AX23+$BG23+$BP23+$BY23+$CH23,0) -> 0 | DL23: =IF($CP23="CALIDUL",$AY23+$BH23+$BQ23+$BZ23+$CI23,0) -> 0 | DM23: =IF($CP23="CALIDUL",$AZ23+$BI23+$BR23+$CA23+$CJ23,0) -> 0 | DN23: =IF($CP23="CALIDUL",$BA23+$BJ23+$BS23+$CB23+$CK23,0) -> 0 | DO23: =IF($CP23="CALIDUL",$BB23+$BK23+$BT23+$CC23+$CL23,0) -> 0 | DP23: =IF($CP23="CALIDUL",$BC23+$BL23+$BU23+$CD23+$CM23,0) -> 0 | DQ23: =SUM(DI23:DP23)-DK23-DM23 -> 0 | EP23: 50 | ET23: =+EO23+EP23+EQ23 -> 50 | EV23: =IF($H23<=15,EK23/2,EK23) -> 0 | EW23: =IF($H23<=15,EL23/2,EL23) -> 0 | EX23: =IF($H23<=15,EM23/2,EM23) -> 0 | EY23: =IF($H23<=15,EN23/2,EN23) -> 0 | EZ23: =IF($H23<=15,EO23/2,EO23) -> 0 | FA23: =IF($H23<=15,EP23/2,EP23) -> 50 | FB23: =IF($H23<=15,EQ23/2,EQ23) -> 0 | FC23: =IF($H23<=15,ER23/2,ER23) -> 0 | ... FE23: =IF($H23<=15,ET23/2,ET23) -> 50
